Workbook

Sheet bio
A1: UID | B1: Last,First | C1: Team | D1: DOB | E1: 7/1 Age | F1: B | G1: T | H1: Pos | I1: ShortName
A2: 24614 | B2: Abbott,Jeff | D2: 26528 | E2: =YEARFRAC(D2,DATE(1999,7,1),1) -> 26.869268 | F2: R | G2: L | H2: lf | I2: Abbott,Je | K2: BBG | L2: =COUNTIF(C$2:C$1243,K2) -> 50
A3: 10011 | B3: Abbott,Jim | D3: 24734 | E3: =YEARFRAC(D3,DATE(1999,7,1),1) -> 31.781631 | F3: L | G3: L | H3: sp | I3: Abbott,Ji | K3: BAR | L3: =COUNTIF(C$2:C$1243,K3) -> 49
A4: 10013 | B4: Abbott,Kurt | D4: 25356 | E4: =YEARFRAC(D4,DATE(1999,7,1),1) -> 30.080021 | F4: R | G4: R | H4: 2b | I4: Abbott,K | K4: CEN | L4: =COUNTIF(C$2:C$1243,K4) -> 36
A5: 10015 | B5: Abbott,Paul | C5: GAR | D5: 24730 | E5: =YEARFRAC(D5,DATE(1999,7,1),1) -> 31.792583 | F5: R | G5: R | H5: mr | I5: Abbott,P | K5: CTW | L5: =COUNTIF(C$2:C$1243,K5) -> 43
A6: 24420 | B6: Abreu,Bob | C6: GAR | D6: 27099 | E6: =YEARFRAC(D6,DATE(1999,7,1),1) -> 25.307287 | F6: L | G6: R | H6: rf | I6: Abreu | K6: CIN | L6: =COUNTIF(C$2:C$1243,K6) -> 50
A7: 10030 | B7: Acevedo,Juan | C7: NEP | D7: 25693 | E7: =YEARFRAC(D7,DATE(1999,7,1),1) -> 29.156703 | F7: R | G7: R | H7: mr | I7: Acevedo | K7: DLM | L7: =COUNTIF(C$2:C$1243,K7) -> 48
A8: 10065 | B8: Adams,Terry | C8: BAR | D8: 26729 | E8: =YEARFRAC(D8,DATE(1999,7,1),1) -> 26.320961 | F8: R | G8: R | H8: cl | I8: Adams | K8: EVN | L8: =COUNTIF(C$2:C$1243,K8) -> 43
A9: 24794 | B9: Agbayani,Benny | C9: BBG | D9: 26295 | E9: =YEARFRAC(D9,DATE(1999,7,1),1) -> 27.507836 | F9: R | G9: R | H9: rf | I9: Agbayani | K9: FFR | L9: =COUNTIF(C$2:C$1243,K9) -> 50
A10: 10087 | B10: Aguilera,Rick | C10: DLM | D10: 22646 | E10: =YEARFRAC(D10,DATE(1999,7,1),1) -> 37.499579 | F10: R | G10: R | H10: cl | I10: Aguilera | K10: FDH | L10: =COUNTIF(C$2:C$1243,K10) -> 40
A11: 10116 | B11: Aldred,Scott | C11: DLM | D11: 25001 | E11: =YEARFRAC(D11,DATE(1999,7,1),1) -> 31.049966 | F11: L | G11: L | H11: mr | I11: Aldred | K11: FER | L11: =COUNTIF(C$2:C$1243,K11) -> 47
A12: 10126 | B12: Alexander,Manny | C12: CIN | D12: 26012 | E12: =YEARFRAC(D12,DATE(1999,7,1),1) -> 28.282666 | F12: R | G12: R | H12: ss | I12: Alexander | K12: FHK | L12: =COUNTIF(C$2:C$1243,K12) -> 45
A13: 24615 | B13: Alfonseca,Antonio | C13: FLL | D13: 26405 | E13: =YEARFRAC(D13,DATE(1999,7,1),1) -> 27.206023 | F13: R | G13: R | H13: cl | I13: Alfonseca | K13: FLL | L13: =COUNTIF(C$2:C$1243,K13) -> 43
A14: 10130 | B14: Alfonzo,Edgardo | C14: FHK | D14: 26887 | E14: =YEARFRAC(D14,DATE(1999,7,1),1) -> 25.888348 | F14: R | G14: R | H14: 2b | I14: Alfonzo | K14: GAR | L14: =COUNTIF(C$2:C$1243,K14) -> 50
A15: 10131 | B15: Alicea,Luis | C15: NEP | D15: 23952 | E15: =YEARFRAC(D15,DATE(1999,7,1),1) -> 33.923962 | F15: S | G15: R | H15: 2b | I15: Alicea | K15: MCL | L15: =COUNTIF(C$2:C$1243,K15) -> 41
A16: 25002 | B16: Allen,Chad | C16: TAR | D16: 27431 | E16: =YEARFRAC(D16,DATE(1999,7,1),1) -> 24.397656 | F16: R | G16: R | H16: lf | I16: Allen | K16: NEP | L16: =COUNTIF(C$2:C$1243,K16) -> 45
A17: 24423 | B17: Allensworth,Jermaine | D17: 26309 | E17: =YEARFRAC(D17,DATE(1999,7,1),1) -> 27.468857 | F17: R | G17: R | H17: rf | I17: Allensworth | K17: OKO | L17: =COUNTIF(C$2:C$1243,K17) -> 43
A18: 25003 | B18: Almanza,Armando | C18: GAR | D18: 26598 | E18: =YEARFRAC(D18,DATE(1999,7,1),1) -> 26.677618 | F18: L | G18: L | H18: mr | I18: Almanza | K18: RMO | L18: =COUNTIF(C$2:C$1243,K18) -> 46
A19: 24616 | B19: Almanzar,Carlos | C19: FFR | D19: 26974 | E19: =YEARFRAC(D19,DATE(1999,7,1),1) -> 25.650137 | F19: R | G19: R | H19: mr | I19: Almanzar | K19: TAR | L19: =COUNTIF(C$2:C$1243,K19) -> 44
A20: 25004 | B20: Almonte,Hector | D20: 27684 | E20: =YEARFRAC(D20,DATE(1999,7,1),1) -> 23.704961 | F20: R | G20: R | H20: mr | I20: Almonte | K20: TEW | L20: =COUNTIF(C$2:C$1243,K20) -> 41
A21: 10176 | B21: Alomar,Roberto | C21: MCL | D21: 24873 | E21: =YEARFRAC(D21,DATE(1999,7,1),1) -> 31.400411 | F21: S | G21: R | H21: 2b | I21: Alomar,R | K21: ZZY | L21: =COUNTIF(C$2:C$1243,K21) -> 43
A22: 10177 | B22: Alomar,Sandy | C22: NEP | D22: 24276 | E22: =YEARFRAC(D22,DATE(1999,7,1),1) -> 33.036238 | F22: R | G22: R | H22: c | I22: Alomar,S
A23: 10181 | B23: Alou,Moises | C23: TAR | D23: 24291 | E23: =YEARFRAC(D23,DATE(1999,7,1),1) -> 32.995168 | F23: R | G23: R | H23: of | I23: Alou
A24: 24795 | B24: Alvarez,Gabe | D24: 27094 | E24: =YEARFRAC(D24,DATE(1999,7,1),1) -> 25.320977 | F24: R | G24: R | H24: dh | I24: Alvarez,G
A25: 25005 | B25: Alvarez,Juan | D25: 26885 | E25: =YEARFRAC(D25,DATE(1999,7,1),1) -> 25.893824 | F25: L | G25: L | H25: mr | I25: Alvarez,J
A26: 10201 | B26: Alvarez,Wilson | C26: FER | D26: 25651 | E26: =YEARFRAC(D26,DATE(1999,7,1),1) -> 29.271698 | F26: L | G26: L | H26: sp | I26: Alvarez,W
A27: 10206 | B27: Amaral,Rich | C27: EVN | D27: 22737 | E27: =YEARFRAC(D27,DATE(1999,7,1),1) -> 37.249802 | F27: R | G27: R | H27: cf | I27: Amaral
A28: 10219 | B28: Anderson,Brady | C28: BAR | D28: 23394 | E28: =YEARFRAC(D28,DATE(1999,7,1),1) -> 35.449692 | F28: L | G28: L | H28: cf | I28: Anderson,Bra
A29: 10220 | B29: Anderson,Brian | C29: FHK | D29: 26415 | E29: =YEARFRAC(D29,DATE(1999,7,1),1) -> 27.178645 | F29: S | G29: L | H29: sp | I29: Anderson,Bri
A30: 10230 | B30: Anderson,Garret | C30: FFR | D30: 26480 | E30: =YEARFRAC(D30,DATE(1999,7,1),1) -> 27.000684 | F30: L | G30: L | H30: cf | I30: Anderson,G
A31: 25006 | B31: Anderson,Jimmy | C31: BAR | D31: 27781 | E31: =YEARFRAC(D31,DATE(1999,7,1),1) -> 23.438741 | F31: L | G31: L | H31: mr | I31: Anderson,J
A32: 24797 | B32: Anderson,Marlon | C32: CEN | D32: 27035 | E32: =YEARFRAC(D32,DATE(1999,7,1),1) -> 25.482519 | F32: L | G32: R | H32: 2b | I32: Anderson,Mar
A33: 24796 | B33: Anderson,Matt | C33: RMO | D33: 27989 | E33: =YEARFRAC(D33,DATE(1999,7,1),1) -> 22.869268 | F33: R | G33: R | H33: mr | I33: Anderson,Mat
A34: 10266 | B34: Andrews,Shane | D34: 26173 | E34: =YEARFRAC(D34,DATE(1999,7,1),1) -> 27.841862 | F34: R | G34: R | H34: 3b | I34: Andrews
A35: 25007 | B35: Ankiel,Rick | C35: BAR | D35: 29055 | E35: =YEARFRAC(D35,DATE(1999,7,1),1) -> 19.951369 | F35: L | G35: L | H35: sp | I35: Ankiel
A36: 10285 | B36: Appier,Kevin | C36: FDH | D36: 24812 | E36: =YEARFRAC(D36,DATE(1999,7,1),1) -> 31.568074 | F36: R | G36: R | H36: sp | I36: Appier
A37: 10304 | B37: Arias,Alex | C37: EVN | D37: 24796 | E37: =YEARFRAC(D37,DATE(1999,7,1),1) -> 31.611881 | F37: R | G37: R | H37: ss | I37: Arias,A
A38: 24425 | B38: Arias,George | D38: 26370 | E38: =YEARFRAC(D38,DATE(1999,7,1),1) -> 27.301848 | F38: R | G38: R | H38: 3b | I38: Arias,G
A39: 25008 | B39: Armas,Tony | C39: NEP | D39: 28609 | E39: =YEARFRAC(D39,DATE(1999,7,1),1) -> 21.173118 | F39: R | G39: R | H39: sp | I39: Armas
A40: 25009 | B40: Arnold,Jamie | D40: 27112 | E40: =YEARFRAC(D40,DATE(1999,7,1),1) -> 25.271693 | F40: R | G40: R | H40: mr | I40: Arnold
...

Sheet dnp99
A1: PLAYERS WHO DO NOT PLAY IN 1999
A2: uid | B2: Batter | C2: Pos | D2: uid | E2: Pitcher | F2: Pos
A3: 10181 | B3: =VLOOKUP(A3,bio!$A$2:$I$1243,2,0) -> Alou,Moises | C3: =VLOOKUP(A3,bio!$A$2:$H$1243,8,0) -> of | D3: 10429 | E3: =VLOOKUP(D3,bio!$A$2:$I$1243,2,0) -> Bailey,Cory | F3: =VLOOKUP(D3,bio!$A$2:$H$1243,8,0) -> rp
A4: 24620 | B4: =VLOOKUP(A4,bio!$A$2:$I$1243,2,0) -> Bellhorn,Mark | C4: =VLOOKUP(A4,bio!$A$2:$H$1243,8,0) -> 2b | D4: 11210 | E4: =VLOOKUP(D4,bio!$A$2:$I$1243,2,0) -> Borowski,Joe | F4: =VLOOKUP(D4,bio!$A$2:$H$1243,8,0) -> rp
A5: 24452 | B5: =VLOOKUP(A5,bio!$A$2:$I$1243,2,0) -> Casanova,Raul | C5: =VLOOKUP(A5,bio!$A$2:$H$1243,8,0) -> c | D5: 11989 | E5: =VLOOKUP(D5,bio!$A$2:$I$1243,2,0) -> Carrara,Giovanni | F5: =VLOOKUP(D5,bio!$A$2:$H$1243,8,0) -> rp
A6: 24460 | B6: =VLOOKUP(A6,bio!$A$2:$I$1243,2,0) -> Crespo, Felipe | C6: =VLOOKUP(A6,bio!$A$2:$H$1243,8,0) -> 0 | D6: 12050 | E6: =VLOOKUP(D6,bio!$A$2:$I$1243,2,0) -> Castillo,Frank | F6: =VLOOKUP(D6,bio!$A$2:$H$1243,8,0) -> sp
A7: 13350 | B7: =VLOOKUP(A7,bio!$A$2:$I$1243,2,0) -> Donnels,Chris | C7: =VLOOKUP(A7,bio!$A$2:$H$1243,8,0) -> 3b | D7: 24464 | E7: =VLOOKUP(D7,bio!$A$2:$I$1243,2,0) -> Delgado,Wilson | F7: =VLOOKUP(D7,bio!$A$2:$H$1243,8,0) -> ss
A8: 14400 | B8: =VLOOKUP(A8,bio!$A$2:$I$1243,2,0) -> Galarraga,Andres | C8: =VLOOKUP(A8,bio!$A$2:$H$1243,8,0) -> 1b | D8: 13681 | E8: =VLOOKUP(D8,bio!$A$2:$I$1243,2,0) -> Eischen,Joey | F8: =VLOOKUP(D8,bio!$A$2:$H$1243,8,0) -> rp
A9: 14641 | B9: =VLOOKUP(A9,bio!$A$2:$I$1243,2,0) -> Gil,Benji | C9: =VLOOKUP(A9,bio!$A$2:$H$1243,8,0) -> ss | D9: 24479 | E9: =VLOOKUP(D9,bio!$A$2:$I$1243,2,0) -> Fernandez,Osvaldo | F9: =VLOOKUP(D9,bio!$A$2:$H$1243,8,0) -> sp
A10: 24686 | B10: =VLOOKUP(A10,bio!$A$2:$I$1243,2,0) -> Halter,Shane | C10: =VLOOKUP(A10,bio!$A$2:$H$1243,8,0) -> ss | D10: 24679 | E10: =VLOOKUP(D10,bio!$A$2:$I$1243,2,0) -> Gonzalez,Geremi | F10: =VLOOKUP(D10,bio!$A$2:$H$1243,8,0) -> sp
A11: 24874 | B11: =VLOOKUP(A11,bio!$A$2:$I$1243,2,0) -> Helms,Wes | C11: =VLOOKUP(A11,bio!$A$2:$H$1243,8,0) -> 3b | D11: 15245 | E11: =VLOOKUP(D11,bio!$A$2:$I$1243,2,0) -> Hammond,Chris | F11: =VLOOKUP(D11,bio!$A$2:$H$1243,8,0) -> rp
A12: 24899 | B12: =VLOOKUP(A12,bio!$A$2:$I$1243,2,0) -> Little,Mark | C12: =VLOOKUP(A12,bio!$A$2:$H$1243,8,0) -> of | D12: 16314 | E12: =VLOOKUP(D12,bio!$A$2:$I$1243,2,0) -> James,Mike | F12: =VLOOKUP(D12,bio!$A$2:$H$1243,8,0) -> rp
A13: 18315 | B13: =VLOOKUP(A13,bio!$A$2:$I$1243,2,0) -> McCarty,David | C13: =VLOOKUP(A13,bio!$A$2:$H$1243,8,0) -> 1b | D13: 24519 | E13: =VLOOKUP(D13,bio!$A$2:$I$1243,2,0) -> Larkin,Andy | F13: =VLOOKUP(D13,bio!$A$2:$H$1243,8,0) -> rp
A14: 24930 | B14: =VLOOKUP(A14,bio!$A$2:$I$1243,2,0) -> Ortiz,Hector | C14: =VLOOKUP(A14,bio!$A$2:$H$1243,8,0) -> c | D14: 24712 | E14: =VLOOKUP(D14,bio!$A$2:$I$1243,2,0) -> Ligtenberg,Kerry | F14: =VLOOKUP(D14,bio!$A$2:$H$1243,8,0) -> rp
... A18: 25204 | B18: =VLOOKUP(A18,bio!$A$2:$I$1243,2,0) -> Wilson,Vance | C18: =VLOOKUP(A18,bio!$A$2:$H$1243,8,0) -> c | D18: 21870 | E18: =VLOOKUP(D18,bio!$A$2:$I$1243,2,0) -> Shouse,Brian | F18: =VLOOKUP(D18,bio!$A$2:$H$1243,8,0) -> rp
D19: 23306 | E19: =VLOOKUP(D19,bio!$A$2:$I$1243,2,0) -> VanPoppel,Todd | F19: =VLOOKUP(D19,bio!$A$2:$H$1243,8,0) -> rp
D20: 24784 | E20: =VLOOKUP(D20,bio!$A$2:$I$1243,2,0) -> Walker,Jamie | F20: =VLOOKUP(D20,bio!$A$2:$H$1243,8,0) -> rp
D21: 24608 | E21: =VLOOKUP(D21,bio!$A$2:$I$1243,2,0) -> Wilson,Paul | F21: =VLOOKUP(D21,bio!$A$2:$H$1243,8,0) -> sp
D22: 24999 | E22: =VLOOKUP(D22,bio!$A$2:$I$1243,2,0) -> Wood,Kerry | F22: =VLOOKUP(D22,bio!$A$2:$H$1243,8,0) -> sp
