Workbook
Name solver_adj: Standings!$R$47
Name solver_lhs1: Standings!$U$52
Name solver_lhs2: Standings!$U$52
Name solver_opt: Standings!$T$54

Sheet Standings
A1: 2003 CHUTES TOO NARROW LEAGUE | U1: MOCKING PYTHAGORAS
A2: Team | B2: W | C2: L | D2: Pct | E2: GB | F2: L10 | G2: Strk | H2: Recent | I2: RF | J2: RA | K2: Margin | L2: RF/g | M2: RA/g | N2: Dom | O2: pWin | P2: pLoss | Q2: Pyth% | R2: GB | S2: Luck | T2: Error | U2: TCI* | W2: DIVISION | X2: RANK | Y2: DIVISION | Z2: WILD
A3: =dump!$A4 -> EASTERN CONFERENCE
A4: =TRIM(MID(dump!$A5,1,28)) -> LIPLESS
A5: =TRIM(MID(dump!$A6,1,28)) -> Barcelona Brewers | B5: =VALUE(MID(dump!$A6,29,3)) -> 16 | C5: =VALUE(MID(dump!$A6,34,3)) -> 12 | D5: =B5/(B5+C5) -> 0.57142857 | E5: =((B5-B$5)+(C$5-C5))/-2 -> 0 | F5: =((10-LEN(SUBSTITUTE(H5,"w","")))&"-")&LEN(SUBSTITUTE(H5,"w","")) -> 4-6 | G5: =TRIM(MID(dump!$A6,61,3)) -> W1 | H5: =TRIM(MID(dump!$A6,65,10)) -> wlllllwwlw | I5: =VALUE(MID(dump!$A6,77,4)) -> 164 | J5: =VALUE(MID(dump!$A6,82,4)) -> 135 | K5: =I5-J5 -> 29 | L5: =I5/($B5+$C5) -> 5.8571429 | M5: =J5/($B5+$C5) -> 4.8214286 | N5: =L5-M5 -> 1.0357143 | O5: =Q5*(B5+C5) -> 16.527988 | P5: =(B5+C5)-O5 -> 11.472012 | Q5: =(L5^Q$54)/((L5^Q$54)+(M5^Q$54)) -> 0.5902853 | R5: =((O5-O$5)+(P$5-P5))/-2 -> 0 | S5: =B5-O5 -> -0.52798841 | T5: =(D5-Q5)^2 -> 0.00035557623 | U5: =((((B5-O5)+(25*D5))+(5*(((10-LEN(SUBSTITUTE(H5,"w","")))/10)-D5)))+(VALUE(MID(G5,2,2))/PI()))-12.5 -> 0.7188929 | W5: TRUE | X5: =RANK(D5+K5/1000000,Y$5:Y$32) -> 4 | Y5: =D5+K5/1000000 -> 0.57145757
A6: =TRIM(MID(dump!$A7,1,28)) -> Chinatrust Whales | B6: =VALUE(MID(dump!$A7,29,3)) -> 14 | C6: =VALUE(MID(dump!$A7,34,3)) -> 14 | D6: =B6/(B6+C6) -> 0.5 | E6: =((B6-B$5)+(C$5-C6))/-2 -> 2 | F6: =((10-LEN(SUBSTITUTE(H6,"w","")))&"-")&LEN(SUBSTITUTE(H6,"w","")) -> 6-4 | G6: =TRIM(MID(dump!$A7,61,3)) -> L1 | H6: =TRIM(MID(dump!$A7,65,10)) -> lwwlwwwwll | I6: =VALUE(MID(dump!$A7,77,4)) -> 122 | J6: =VALUE(MID(dump!$A7,82,4)) -> 128 | K6: =I6-J6 -> -6 | L6: =I6/($B6+$C6) -> 4.3571429 | M6: =J6/($B6+$C6) -> 4.5714286 | N6: =L6-M6 -> -0.21428571 | O6: =Q6*(B6+C6) -> 13.369812 | P6: =(B6+C6)-O6 -> 14.630188 | Q6: =(L6^Q$54)/((L6^Q$54)+(M6^Q$54)) -> 0.47749328 | R6: =((O6-O$5)+(P$5-P6))/-2 -> 3.1581765 | S6: =B6-O6 -> 0.63018805 | T6: =(D6-Q6)^2 -> 0.00050655226 | U6: =((((B6-O6)+(25*D6))+(5*(((10-LEN(SUBSTITUTE(H6,"w","")))/10)-D6)))+(VALUE(MID(G6,2,2))/PI()))-12.5 -> 1.4484979 | W6: FALSE | X6: =RANK(D6+K6/1000000,Z$5:Z$32)+4 -> 13 | Z6: =D6+K6/1000000 -> 0.499994
A7: =TRIM(MID(dump!$A8,1,28)) -> Chico's Bail Bonds | B7: =VALUE(MID(dump!$A8,29,3)) -> 13 | C7: =VALUE(MID(dump!$A8,34,3)) -> 15 | D7: =B7/(B7+C7) -> 0.46428571 | E7: =((B7-B$5)+(C$5-C7))/-2 -> 3 | F7: =((10-LEN(SUBSTITUTE(H7,"w","")))&"-")&LEN(SUBSTITUTE(H7,"w","")) -> 5-5 | G7: =TRIM(MID(dump!$A8,61,3)) -> L1 | H7: =TRIM(MID(dump!$A8,65,10)) -> lwlwwwwlll | I7: =VALUE(MID(dump!$A8,77,4)) -> 159 | J7: =VALUE(MID(dump!$A8,82,4)) -> 155 | K7: =I7-J7 -> 4 | L7: =I7/($B7+$C7) -> 5.6785714 | M7: =J7/($B7+$C7) -> 5.5357143 | N7: =L7-M7 -> 0.14285714 | O7: =Q7*(B7+C7) -> 14.334611 | P7: =(B7+C7)-O7 -> 13.665389 | Q7: =(L7^Q$54)/((L7^Q$54)+(M7^Q$54)) -> 0.51195039 | R7: =((O7-O$5)+(P$5-P7))/-2 -> 2.1933774 | S7: =B7-O7 -> -1.334611 | T7: =(D7-Q7)^2 -> 0.0022719216 | U7: =((((B7-O7)+(25*D7))+(5*(((10-LEN(SUBSTITUTE(H7,"w","")))/10)-D7)))+(VALUE(MID(G7,2,2))/PI()))-12.5 -> -1.7305868 | W7: FALSE | X7: =RANK(D7+K7/1000000,Z$5:Z$32)+4 -> 16 | Z7: =D7+K7/1000000 -> 0.46428971
A8: =TRIM(MID(dump!$A9,1,28)) -> Philly Halladaze | B8: =VALUE(MID(dump!$A9,29,3)) -> 13 | C8: =VALUE(MID(dump!$A9,34,3)) -> 15 | D8: =B8/(B8+C8) -> 0.46428571 | E8: =((B8-B$5)+(C$5-C8))/-2 -> 3 | F8: =((10-LEN(SUBSTITUTE(H8,"w","")))&"-")&LEN(SUBSTITUTE(H8,"w","")) -> 4-6 | G8: =TRIM(MID(dump!$A9,61,3)) -> W2 | H8: =TRIM(MID(dump!$A9,65,10)) -> wwlwlllllw | I8: =VALUE(MID(dump!$A9,77,4)) -> 119 | J8: =VALUE(MID(dump!$A9,82,4)) -> 138 | K8: =I8-J8 -> -19 | L8: =I8/($B8+$C8) -> 4.25 | M8: =J8/($B8+$C8) -> 4.9285714 | N8: =L8-M8 -> -0.67857143 | O8: =Q8*(B8+C8) -> 12.066701 | P8: =(B8+C8)-O8 -> 15.933299 | Q8: =(L8^Q$54)/((L8^Q$54)+(M8^Q$54)) -> 0.43095361 | R8: =((O8-O$5)+(P$5-P8))/-2 -> 4.4612873 | S8: =B8-O8 -> 0.93329886 | T8: =(D8-Q8)^2 -> 0.001111029 | U8: =((((B8-O8)+(25*D8))+(5*(((10-LEN(SUBSTITUTE(H8,"w","")))/10)-D8)))+(VALUE(MID(G8,2,2))/PI()))-12.5 -> 0.35563292 | W8: FALSE | X8: =RANK(D8+K8/1000000,Z$5:Z$32)+4 -> 17 | Z8: =D8+K8/1000000 -> 0.46426671
A9: =TRIM(MID(dump!$A10,1,28)) -> Garmisch-Parten Shebazzle! | B9: =VALUE(MID(dump!$A10,29,3)) -> 8 | C9: =VALUE(MID(dump!$A10,34,3)) -> 20 | D9: =B9/(B9+C9) -> 0.28571429 | E9: =((B9-B$5)+(C$5-C9))/-2 -> 8 | F9: =((10-LEN(SUBSTITUTE(H9,"w","")))&"-")&LEN(SUBSTITUTE(H9,"w","")) -> 4-6 | G9: =TRIM(MID(dump!$A10,61,3)) -> L2 | H9: =TRIM(MID(dump!$A10,65,10)) -> llwwllwwll | I9: =VALUE(MID(dump!$A10,77,4)) -> 136 | J9: =VALUE(MID(dump!$A10,82,4)) -> 197 | K9: =I9-J9 -> -61 | L9: =I9/($B9+$C9) -> 4.8571429 | M9: =J9/($B9+$C9) -> 7.0357143 | N9: =L9-M9 -> -2.1785714 | O9: =Q9*(B9+C9) -> 9.3198005 | P9: =(B9+C9)-O9 -> 18.680199 | Q9: =(L9^Q$54)/((L9^Q$54)+(M9^Q$54)) -> 0.33285002 | R9: =((O9-O$5)+(P$5-P9))/-2 -> 7.2081879 | S9: =B9-O9 -> -1.3198005 | T9: =(D9-Q9)^2 -> 0.0022217774 | U9: =((((B9-O9)+(25*D9))+(5*(((10-LEN(SUBSTITUTE(H9,"w","")))/10)-D9)))+(VALUE(MID(G9,2,2))/PI()))-12.5 -> -5.4688951 | W9: FALSE | X9: =RANK(D9+K9/1000000,Z$5:Z$32)+4 -> 20 | Z9: =D9+K9/1000000 -> 0.28565329
A10: =TRIM(MID(dump!$A11,1,28)) -> Rocky Mountain Oysters | B10: =VALUE(MID(dump!$A11,29,3)) -> 5 | C10: =VALUE(MID(dump!$A11,34,3)) -> 23 | D10: =B10/(B10+C10) -> 0.17857143 | E10: =((B10-B$5)+(C$5-C10))/-2 -> 11 | F10: =((10-LEN(SUBSTITUTE(H10,"w","")))&"-")&LEN(SUBSTITUTE(H10,"w","")) -> 1-9 | G10: =TRIM(MID(dump!$A11,61,3)) -> L8 | H10: =TRIM(MID(dump!$A11,65,10)) -> llllllllwl | I10: =VALUE(MID(dump!$A11,77,4)) -> 85 | J10: =VALUE(MID(dump!$A11,82,4)) -> 194 | K10: =I10-J10 -> -109 | L10: =I10/($B10+$C10) -> 3.0357143 | M10: =J10/($B10+$C10) -> 6.9285714 | N10: =L10-M10 -> -3.8928571 | O10: =Q10*(B10+C10) -> 4.9085899 | P10: =(B10+C10)-O10 -> 23.09141 | Q10: =(L10^Q$54)/((L10^Q$54)+(M10^Q$54)) -> 0.17530678 | R10: =((O10-O$5)+(P$5-P10))/-2 -> 11.619399 | S10: =B10-O10 -> 0.091410111 | T10: =(D10-Q10)^2 -> 1.0657919e-05 | U10: =((((B10-O10)+(25*D10))+(5*(((10-LEN(SUBSTITUTE(H10,"w","")))/10)-D10)))+(VALUE(MID(G10,2,2))/PI()))-12.5 -> -5.7906822 | W10: FALSE | X10: =RANK(D10+K10/1000000,Z$5:Z$32)+4 -> 24 | Z10: =D10+K10/1000000 -> 0.17846243
A11: =TRIM(MID(dump!$A13,1,28)) -> HIGH HORSE
A12: =TRIM(MID(dump!$A14,1,28)) -> Dinosaur Iguanodons | B12: =VALUE(MID(dump!$A14,29,3)) -> 22 | C12: =VALUE(MID(dump!$A14,34,3)) -> 6 | D12: =B12/(B12+C12) -> 0.78571429 | E12: =((B12-B$12)+(C$12-C12))/-2 -> 0 | F12: =((10-LEN(SUBSTITUTE(H12,"w","")))&"-")&LEN(SUBSTITUTE(H12,"w","")) -> 9-1 | G12: =TRIM(MID(dump!$A14,61,3)) -> W2 | H12: =TRIM(MID(dump!$A14,65,10)) -> wwlwwwwwww | I12: =VALUE(MID(dump!$A14,77,4)) -> 223 | J12: =VALUE(MID(dump!$A14,82,4)) -> 90 | K12: =I12-J12 -> 133 | L12: =I12/($B12+$C12) -> 7.9642857 | M12: =J12/($B12+$C12) -> 3.2142857 | N12: =L12-M12 -> 4.75 | O12: =Q12*(B12+C12) -> 23.684602 | P12: =(B12+C12)-O12 -> 4.3153981 | Q12: =(L12^Q$54)/((L12^Q$54)+(M12^Q$54)) -> 0.84587864 | R12: =((O12-O$12)+(P$12-P12))/-2 -> 0 | S12: =B12-O12 -> -1.6846019 | T12: =(D12-Q12)^2 -> 0.0036197494 | U12: =((((B12-O12)+(25*D12))+(5*(((10-LEN(SUBSTITUTE(H12,"w","")))/10)-D12)))+(VALUE(MID(G12,2,2))/PI()))-12.5 -> 6.6663036 | W12: TRUE | X12: =RANK(D12+K12/1000000,Y$5:Y$32) -> 2 | Y12: =D12+K12/1000000 -> 0.78584729
A13: =TRIM(MID(dump!$A15,1,28)) -> Cincinnati Reds | B13: =VALUE(MID(dump!$A15,29,3)) -> 21 | C13: =VALUE(MID(dump!$A15,34,3)) -> 7 | D13: =B13/(B13+C13) -> 0.75 | E13: =((B13-B$12)+(C$12-C13))/-2 -> 1 | F13: =((10-LEN(SUBSTITUTE(H13,"w","")))&"-")&LEN(SUBSTITUTE(H13,"w","")) -> 9-1 | G13: =TRIM(MID(dump!$A15,61,3)) -> W8 | H13: =TRIM(MID(dump!$A15,65,10)) -> wwwwwwwwlw | I13: =VALUE(MID(dump!$A15,77,4)) -> 174 | J13: =VALUE(MID(dump!$A15,82,4)) -> 138 | K13: =I13-J13 -> 36 | L13: =I13/($B13+$C13) -> 6.2142857 | M13: =J13/($B13+$C13) -> 4.9285714 | N13: =L13-M13 -> 1.2857143 | O13: =Q13*(B13+C13) -> 16.997663 | P13: =(B13+C13)-O13 -> 11.002337 | Q13: =(L13^Q$54)/((L13^Q$54)+(M13^Q$54)) -> 0.6070594 | R13: =((O13-O$12)+(P$12-P13))/-2 -> 6.6869386 | S13: =B13-O13 -> 4.0023367 | T13: =(D13-Q13)^2 -> 0.020432014 | U13: =((((B13-O13)+(25*D13))+(5*(((10-LEN(SUBSTITUTE(H13,"w","")))/10)-D13)))+(VALUE(MID(G13,2,2))/PI()))-12.5 -> 13.548816 | W13: FALSE | X13: =RANK(D13+K13/1000000,Z$5:Z$32)+4 -> 5 | Z13: =D13+K13/1000000 -> 0.750036
A14: =TRIM(MID(dump!$A16,1,28)) -> Okoboji Cropdusters | B14: =VALUE(MID(dump!$A16,29,3)) -> 19 | C14: =VALUE(MID(dump!$A16,34,3)) -> 9 | D14: =B14/(B14+C14) -> 0.67857143 | E14: =((B14-B$12)+(C$12-C14))/-2 -> 3 | F14: =((10-LEN(SUBSTITUTE(H14,"w","")))&"-")&LEN(SUBSTITUTE(H14,"w","")) -> 7-3 | G14: =TRIM(MID(dump!$A16,61,3)) -> W2 | H14: =TRIM(MID(dump!$A16,65,10)) -> wwlwwlwwlw | I14: =VALUE(MID(dump!$A16,77,4)) -> 170 | J14: =VALUE(MID(dump!$A16,82,4)) -> 115 | K14: =I14-J14 -> 55 | L14: =I14/($B14+$C14) -> 6.0714286 | M14: =J14/($B14+$C14) -> 4.1071429 | N14: =L14-M14 -> 1.9642857 | O14: =Q14*(B14+C14) -> 18.91572 | P14: =(B14+C14)-O14 -> 9.0842796 | Q14: =(L14^Q$54)/((L14^Q$54)+(M14^Q$54)) -> 0.67556144 | R14: =((O14-O$12)+(P$12-P14))/-2 -> 4.7688814 | S14: =B14-O14 -> 0.08427955 | T14: =(D14-Q14)^2 -> 9.0600033e-06 | U14: =((((B14-O14)+(25*D14))+(5*(((10-LEN(SUBSTITUTE(H14,"w","")))/10)-D14)))+(VALUE(MID(G14,2,2))/PI()))-12.5 -> 5.2923279 | W14: FALSE | X14: =RANK(D14+K14/1000000,Z$5:Z$32)+4 -> 6 | Z14: =D14+K14/1000000 -> 0.67862643
A15: =TRIM(MID(dump!$A17,1,28)) -> Tewksbury Bobs | B15: =VALUE(MID(dump!$A17,29,3)) -> 14 | C15: =VALUE(MID(dump!$A17,34,3)) -> 14 | D15: =B15/(B15+C15) -> 0.5 | E15: =((B15-B$12)+(C$12-C15))/-2 -> 8 | F15: =((10-LEN(SUBSTITUTE(H15,"w","")))&"-")&LEN(SUBSTITUTE(H15,"w","")) -> 4-6 | G15: =TRIM(MID(dump!$A17,61,3)) -> L6 | H15: =TRIM(MID(dump!$A17,65,10)) -> llllllwwww | I15: =VALUE(MID(dump!$A17,77,4)) -> 110 | J15: =VALUE(MID(dump!$A17,82,4)) -> 125 | K15: =I15-J15 -> -15 | L15: =I15/($B15+$C15) -> 3.9285714 | M15: =J15/($B15+$C15) -> 4.4642857 | N15: =L15-M15 -> -0.53571429 | O15: =Q15*(B15+C15) -> 12.328879 | P15: =(B15+C15)-O15 -> 15.671121 | Q15: =(L15^Q$54)/((L15^Q$54)+(M15^Q$54)) -> 0.44031711 | R15: =((O15-O$12)+(P$12-P15))/-2 -> 11.355723 | S15: =B15-O15 -> 1.6711209 | T15: =(D15-Q15)^2 -> 0.0035620471 | U15: =((((B15-O15)+(25*D15))+(5*(((10-LEN(SUBSTITUTE(H15,"w","")))/10)-D15)))+(VALUE(MID(G15,2,2))/PI()))-12.5 -> 3.0809802 | W15: FALSE | X15: =RANK(D15+K15/1000000,Z$5:Z$32)+4 -> 14 | Z15: =D15+K15/1000000 -> 0.499985
A16: =TRIM(MID(dump!$A18,1,28)) -> Ferlin Huskies | B16: =VALUE(MID(dump!$A18,29,3)) -> 13 | C16: =VALUE(MID(dump!$A18,34,3)) -> 15 | D16: =B16/(B16+C16) -> 0.46428571 | E16: =((B16-B$12)+(C$12-C16))/-2 -> 9 | F16: =((10-LEN(SUBSTITUTE(H16,"w","")))&"-")&LEN(SUBSTITUTE(H16,"w","")) -> 4-6 | G16: =TRIM(MID(dump!$A18,61,3)) -> W2 | H16: =TRIM(MID(dump!$A18,65,10)) -> wwlwllllwl | I16: =VALUE(MID(dump!$A18,77,4)) -> 153 | J16: =VALUE(MID(dump!$A18,82,4)) -> 143 | K16: =I16-J16 -> 10 | L16: =I16/($B16+$C16) -> 5.4642857 | M16: =J16/($B16+$C16) -> 5.1071429 | N16: =L16-M16 -> 0.35714286 | O16: =Q16*(B16+C16) -> 14.886668 | P16: =(B16+C16)-O16 -> 13.113332 | Q16: =(L16^Q$54)/((L16^Q$54)+(M16^Q$54)) -> 0.53166671 | R16: =((O16-O$12)+(P$12-P16))/-2 -> 8.7979339 | S16: =B16-O16 -> -1.886668 | T16: =(D16-Q16)^2 -> 0.0045401989 | U16: =((((B16-O16)+(25*D16))+(5*(((10-LEN(SUBSTITUTE(H16,"w","")))/10)-D16)))+(VALUE(MID(G16,2,2))/PI()))-12.5 -> -2.4643339 | W16: FALSE | X16: =RANK(D16+K16/1000000,Z$5:Z$32)+4 -> 15 | Z16: =D16+K16/1000000 -> 0.46429571
A17: =TRIM(MID(dump!$A19,1,28)) -> Century Atoms | B17: =VALUE(MID(dump!$A19,29,3)) -> 11 | C17: =VALUE(MID(dump!$A19,34,3)) -> 17 | D17: =B17/(B17+C17) -> 0.39285714 | E17: =((B17-B$12)+(C$12-C17))/-2 -> 11 | F17: =((10-LEN(SUBSTITUTE(H17,"w","")))&"-")&LEN(SUBSTITUTE(H17,"w","")) -> 4-6 | G17: =TRIM(MID(dump!$A19,61,3)) -> L2 | H17: =TRIM(MID(dump!$A19,65,10)) -> llwlwwwlll | I17: =VALUE(MID(dump!$A19,77,4)) -> 129 | J17: =VALUE(MID(dump!$A19,82,4)) -> 170 | K17: =I17-J17 -> -41 | L17: =I17/($B17+$C17) -> 4.6071429 | M17: =J17/($B17+$C17) -> 6.0714286 | N17: =L17-M17 -> -1.4642857 | O17: =Q17*(B17+C17) -> 10.453754 | P17: =(B17+C17)-O17 -> 17.546246 | Q17: =(L17^Q$54)/((L17^Q$54)+(M17^Q$54)) -> 0.37334837 | R17: =((O17-O$12)+(P$12-P17))/-2 -> 13.230848 | S17: =B17-O17 -> 0.54624575 | T17: =(D17-Q17)^2 -> 0.00038059237 | U17: =((((B17-O17)+(25*D17))+(5*(((10-LEN(SUBSTITUTE(H17,"w","")))/10)-D17)))+(VALUE(MID(G17,2,2))/PI()))-12.5 -> -1.4599916 | W17: FALSE | X17: =RANK(D17+K17/1000000,Z$5:Z$32)+4 -> 18 | Z17: =D17+K17/1000000 -> 0.39281614
A18: =TRIM(MID(dump!$A21,1,28)) -> WESTERN CONFERENCE
A19: =TRIM(MID(dump!$A22,1,28)) -> PILGRIMS
A20: =TRIM(MID(dump!$A23,1,28)) -> Evanston Endorphins | B20: =VALUE(MID(dump!$A23,29,3)) -> 18 | C20: =VALUE(MID(dump!$A23,34,3)) -> 10 | D20: =B20/(B20+C20) -> 0.64285714 | E20: =((B20-B$20)+(C$20-C20))/-2 -> 0 | F20: =((10-LEN(SUBSTITUTE(H20,"w","")))&"-")&LEN(SUBSTITUTE(H20,"w","")) -> 8-2 | G20: =TRIM(MID(dump!$A23,61,3)) -> W2 | H20: =TRIM(MID(dump!$A23,65,10)) -> wwlwwwwlww | I20: =VALUE(MID(dump!$A23,77,4)) -> 155 | J20: =VALUE(MID(dump!$A23,82,4)) -> 125 | K20: =I20-J20 -> 30 | L20: =I20/($B20+$C20) -> 5.5357143 | M20: =J20/($B20+$C20) -> 4.4642857 | N20: =L20-M20 -> 1.0714286 | O20: =Q20*(B20+C20) -> 16.787797 | P20: =(B20+C20)-O20 -> 11.212203 | Q20: =(L20^Q$54)/((L20^Q$54)+(M20^Q$54)) -> 0.59956418 | R20: =((O20-O$20)+(P$20-P20))/-2 -> 0 | S20: =B20-O20 -> 1.2122029 | T20: =(D20-Q20)^2 -> 0.0018742805 | U20: =((((B20-O20)+(25*D20))+(5*(((10-LEN(SUBSTITUTE(H20,"w","")))/10)-D20)))+(VALUE(MID(G20,2,2))/PI()))-12.5 -> 6.2059656 | W20: TRUE | X20: =RANK(D20+K20/1000000,Y$5:Y$32) -> 3 | Y20: =D20+K20/1000000 -> 0.64288714
A21: =TRIM(MID(dump!$A24,1,28)) -> Felldownhead Firsts | B21: =VALUE(MID(dump!$A24,29,3)) -> 18 | C21: =VALUE(MID(dump!$A24,34,3)) -> 10 | D21: =B21/(B21+C21) -> 0.64285714 | E21: =((B21-B$20)+(C$20-C21))/-2 -> 0 | F21: =((10-LEN(SUBSTITUTE(H21,"w","")))&"-")&LEN(SUBSTITUTE(H21,"w","")) -> 6-4 | G21: =TRIM(MID(dump!$A24,61,3)) -> L1 | H21: =TRIM(MID(dump!$A24,65,10)) -> lwwwwlllww | I21: =VALUE(MID(dump!$A24,77,4)) -> 183 | J21: =VALUE(MID(dump!$A24,82,4)) -> 102 | K21: =I21-J21 -> 81 | L21: =I21/($B21+$C21) -> 6.5357143 | M21: =J21/($B21+$C21) -> 3.6428571 | N21: =L21-M21 -> 2.8928571 | O21: =Q21*(B21+C21) -> 20.990588 | P21: =(B21+C21)-O21 -> 7.009412 | Q21: =(L21^Q$54)/((L21^Q$54)+(M21^Q$54)) -> 0.74966386 | R21: =((O21-O$20)+(P$20-P21))/-2 -> -4.2027909 | S21: =B21-O21 -> -2.990588 | T21: =(D21-Q21)^2 -> 0.011407674 | U21: =((((B21-O21)+(25*D21))+(5*(((10-LEN(SUBSTITUTE(H21,"w","")))/10)-D21)))+(VALUE(MID(G21,2,2))/PI()))-12.5 -> 0.68486479 | W21: FALSE | X21: =RANK(D21+K21/1000000,Z$5:Z$32)+4 -> 7 | Z21: =D21+K21/1000000 -> 0.64293814
A22: =TRIM(MID(dump!$A25,1,28)) -> Renfroe Hunters | B22: =VALUE(MID(dump!$A25,29,3)) -> 17 | C22: =VALUE(MID(dump!$A25,34,3)) -> 11 | D22: =B22/(B22+C22) -> 0.60714286 | E22: =((B22-B$20)+(C$20-C22))/-2 -> 1 | F22: =((10-LEN(SUBSTITUTE(H22,"w","")))&"-")&LEN(SUBSTITUTE(H22,"w","")) -> 6-4 | G22: =TRIM(MID(dump!$A25,61,3)) -> W1 | H22: =TRIM(MID(dump!$A25,65,10)) -> wlwwlwlwwl | I22: =VALUE(MID(dump!$A25,77,4)) -> 170 | J22: =VALUE(MID(dump!$A25,82,4)) -> 127 | K22: =I22-J22 -> 43 | L22: =I22/($B22+$C22) -> 6.0714286 | M22: =J22/($B22+$C22) -> 4.5357143 | N22: =L22-M22 -> 1.5357143 | O22: =Q22*(B22+C22) -> 17.737595 | P22: =(B22+C22)-O22 -> 10.262405 | Q22: =(L22^Q$54)/((L22^Q$54)+(M22^Q$54)) -> 0.63348555 | R22: =((O22-O$20)+(P$20-P22))/-2 -> -0.94979831 | S22: =B22-O22 -> -0.73759538 | T22: =(D22-Q22)^2 -> 0.00069393743 | U22: =((((B22-O22)+(25*D22))+(5*(((10-LEN(SUBSTITUTE(H22,"w","")))/10)-D22)))+(VALUE(MID(G22,2,2))/PI()))-12.5 -> 2.2235716 | W22: FALSE | X22: =RANK(D22+K22/1000000,Z$5:Z$32)+4 -> 8 | Z22: =D22+K22/1000000 -> 0.60718586
A23: =TRIM(MID(dump!$A26,1,28)) -> Inwood Landfills | B23: =VALUE(MID(dump!$A26,29,3)) -> 17 | C23: =VALUE(MID(dump!$A26,34,3)) -> 11 | D23: =B23/(B23+C23) -> 0.60714286 | E23: =((B23-B$20)+(C$20-C23))/-2 -> 1 | F23: =((10-LEN(SUBSTITUTE(H23,"w","")))&"-")&LEN(SUBSTITUTE(H23,"w","")) -> 5-5 | G23: =TRIM(MID(dump!$A26,61,3)) -> W3 | H23: =TRIM(MID(dump!$A26,65,10)) -> wwwlwlllwl | I23: =VALUE(MID(dump!$A26,77,4)) -> 161 | J23: =VALUE(MID(dump!$A26,82,4)) -> 162 | K23: =I23-J23 -> -1 | L23: =I23/($B23+$C23) -> 5.75 | M23: =J23/($B23+$C23) -> 5.7857143 | N23: =L23-M23 -> -0.035714286 | O23: =Q23*(B23+C23) -> 13.918668 | P23: =(B23+C23)-O23 -> 14.081332 | Q23: =(L23^Q$54)/((L23^Q$54)+(M23^Q$54)) -> 0.49709527 | R23: =((O23-O$20)+(P$20-P23))/-2 -> 2.8691294 | S23: =B23-O23 -> 3.0813323 | T23: =(D23-Q23)^2 -> 0.01211047 | U23: =((((B23-O23)+(25*D23))+(5*(((10-LEN(SUBSTITUTE(H23,"w","")))/10)-D23)))+(VALUE(MID(G23,2,2))/PI()))-12.5 -> 6.1791191 | W23: FALSE | X23: =RANK(D23+K23/1000000,Z$5:Z$32)+4 -> 9 | Z23: =D23+K23/1000000 -> 0.60714186
A24: =TRIM(MID(dump!$A27,1,28)) -> Baraboo GoiterMen | B24: =VALUE(MID(dump!$A27,29,3)) -> 15 | C24: =VALUE(MID(dump!$A27,34,3)) -> 13 | D24: =B24/(B24+C24) -> 0.53571429 | E24: =((B24-B$20)+(C$20-C24))/-2 -> 3 | F24: =((10-LEN(SUBSTITUTE(H24,"w","")))&"-")&LEN(SUBSTITUTE(H24,"w","")) -> 4-6 | G24: =TRIM(MID(dump!$A27,61,3)) -> L2 | H24: =TRIM(MID(dump!$A27,65,10)) -> llwllwlwlw | I24: =VALUE(MID(dump!$A27,77,4)) -> 138 | J24: =VALUE(MID(dump!$A27,82,4)) -> 146 | K24: =I24-J24 -> -8 | L24: =I24/($B24+$C24) -> 4.9285714 | M24: =J24/($B24+$C24) -> 5.2142857 | N24: =L24-M24 -> -0.28571429 | O24: =Q24*(B24+C24) -> 13.260478 | P24: =(B24+C24)-O24 -> 14.739522 | Q24: =(L24^Q$54)/((L24^Q$54)+(M24^Q$54)) -> 0.47358849 | R24: =((O24-O$20)+(P$20-P24))/-2 -> 3.5273193 | S24: =B24-O24 -> 1.7395222 | T24: =(D24-Q24)^2 -> 0.0038596142 | U24: =((((B24-O24)+(25*D24))+(5*(((10-LEN(SUBSTITUTE(H24,"w","")))/10)-D24)))+(VALUE(MID(G24,2,2))/PI()))-12.5 -> 2.5904277 | W24: FALSE | X24: =RANK(D24+K24/1000000,Z$5:Z$32)+4 -> 10 | Z24: =D24+K24/1000000 -> 0.53570629
A25: =TRIM(MID(dump!$A28,1,28)) -> Falkirk Frightened Rabbit | B25: =VALUE(MID(dump!$A28,29,3)) -> 14 | C25: =VALUE(MID(dump!$A28,34,3)) -> 14 | D25: =B25/(B25+C25) -> 0.5 | E25: =((B25-B$20)+(C$20-C25))/-2 -> 4 | F25: =((10-LEN(SUBSTITUTE(H25,"w","")))&"-")&LEN(SUBSTITUTE(H25,"w","")) -> 7-3 | G25: =TRIM(MID(dump!$A28,61,3)) -> W1 | H25: =TRIM(MID(dump!$A28,65,10)) -> wlllwwwwww | I25: =VALUE(MID(dump!$A28,77,4)) -> 140 | J25: =VALUE(MID(dump!$A28,82,4)) -> 123 | K25: =I25-J25 -> 17 | L25: =I25/($B25+$C25) -> 5 | M25: =J25/($B25+$C25) -> 4.3928571 | N25: =L25-M25 -> 0.60714286 | O25: =Q25*(B25+C25) -> 15.692154 | P25: =(B25+C25)-O25 -> 12.307846 | Q25: =(L25^Q$54)/((L25^Q$54)+(M25^Q$54)) -> 0.56043406 | R25: =((O25-O$20)+(P$20-P25))/-2 -> 1.0956433 | S25: =B25-O25 -> -1.6921538 | T25: =(D25-Q25)^2 -> 0.003652276 | U25: =((((B25-O25)+(25*D25))+(5*(((10-LEN(SUBSTITUTE(H25,"w","")))/10)-D25)))+(VALUE(MID(G25,2,2))/PI()))-12.5 -> -0.37384388 | W25: FALSE | X25: =RANK(D25+K25/1000000,Z$5:Z$32)+4 -> 11 | Z25: =D25+K25/1000000 -> 0.500017
A26: =TRIM(MID(dump!$A30,1,28)) -> PINK BULLETS
A27: =TRIM(MID(dump!$A31,1,28)) -> Newport Never Nudes | B27: =VALUE(MID(dump!$A31,29,3)) -> 23 | C27: =VALUE(MID(dump!$A31,34,3)) -> 5 | D27: =B27/(B27+C27) -> 0.82142857 | E27: =((B27-B$27)+(C$27-C27))/-2 -> 0 | F27: =((10-LEN(SUBSTITUTE(H27,"w","")))&"-")&LEN(SUBSTITUTE(H27,"w","")) -> 10-0 | G27: =TRIM(MID(dump!$A31,61,3)) -> W16 | H27: =TRIM(MID(dump!$A31,65,10)) -> wwwwwwwwww | I27: =VALUE(MID(dump!$A31,77,4)) -> 204 | J27: =VALUE(MID(dump!$A31,82,4)) -> 160 | K27: =I27-J27 -> 44 | L27: =I27/($B27+$C27) -> 7.2857143 | M27: =J27/($B27+$C27) -> 5.7142857 | N27: =L27-M27 -> 1.5714286 | O27: =Q27*(B27+C27) -> 17.137022 | P27: =(B27+C27)-O27 -> 10.862978 | Q27: =(L27^Q$54)/((L27^Q$54)+(M27^Q$54)) -> 0.61203649 | R27: =((O27-O$27)+(P$27-P27))/-2 -> 0 | S27: =B27-O27 -> 5.8629782 | T27: =(D27-Q27)^2 -> 0.043845043 | U27: =((((B27-O27)+(25*D27))+(5*(((10-LEN(SUBSTITUTE(H27,"w","")))/10)-D27)))+(VALUE(MID(G27,2,2))/PI()))-12.5 -> 19.884508 | W27: TRUE | X27: =RANK(D27+K27/1000000,Y$5:Y$32) -> 1 | Y27: =D27+K27/1000000 -> 0.82147257
A28: =TRIM(MID(dump!$A32,1,28)) -> Brooklyn Dodgers | B28: =VALUE(MID(dump!$A32,29,3)) -> 14 | C28: =VALUE(MID(dump!$A32,34,3)) -> 14 | D28: =B28/(B28+C28) -> 0.5 | E28: =((B28-B$27)+(C$27-C28))/-2 -> 9 | F28: =((10-LEN(SUBSTITUTE(H28,"w","")))&"-")&LEN(SUBSTITUTE(H28,"w","")) -> 3-7 | G28: =TRIM(MID(dump!$A32,61,3)) -> L2 | H28: =TRIM(MID(dump!$A32,65,10)) -> llwllllwlw | I28: =VALUE(MID(dump!$A32,77,4)) -> 151 | J28: =VALUE(MID(dump!$A32,82,4)) -> 140 | K28: =I28-J28 -> 11 | L28: =I28/($B28+$C28) -> 5.3928571 | M28: =J28/($B28+$C28) -> 5 | N28: =L28-M28 -> 0.39285714 | O28: =Q28*(B28+C28) -> 14.991854 | P28: =(B28+C28)-O28 -> 13.008146 | Q28: =(L28^Q$54)/((L28^Q$54)+(M28^Q$54)) -> 0.53542334 | R28: =((O28-O$27)+(P$27-P28))/-2 -> 2.1451682 | S28: =B28-O28 -> -0.99185361 | T28: =(D28-Q28)^2 -> 0.0012548132 | U28: =((((B28-O28)+(25*D28))+(5*(((10-LEN(SUBSTITUTE(H28,"w","")))/10)-D28)))+(VALUE(MID(G28,2,2))/PI()))-12.5 -> -1.3552338 | W28: FALSE | X28: =RANK(D28+K28/1000000,Z$5:Z$32)+4 -> 12 | Z28: =D28+K28/1000000 -> 0.500011
A29: =TRIM(MID(dump!$A33,1,28)) -> Newfoundland Perfectos | B29: =VALUE(MID(dump!$A33,29,3)) -> 10 | C29: =VALUE(MID(dump!$A33,34,3)) -> 18 | D29: =B29/(B29+C29) -> 0.35714286 | E29: =((B29-B$27)+(C$27-C29))/-2 -> 13 | F29: =((10-LEN(SUBSTITUTE(H29,"w","")))&"-")&LEN(SUBSTITUTE(H29,"w","")) -> 5-5 | G29: =TRIM(MID(dump!$A33,61,3)) -> W2 | H29: =TRIM(MID(dump!$A33,65,10)) -> wwlwwwllll | I29: =VALUE(MID(dump!$A33,77,4)) -> 106 | J29: =VALUE(MID(dump!$A33,82,4)) -> 152 | K29: =I29-J29 -> -46 | L29: =I29/($B29+$C29) -> 3.7857143 | M29: =J29/($B29+$C29) -> 5.4285714 | N29: =L29-M29 -> -1.6428571 | O29: =Q29*(B29+C29) -> 9.4380985 | P29: =(B29+C29)-O29 -> 18.561902 | Q29: =(L29^Q$54)/((L29^Q$54)+(M29^Q$54)) -> 0.33707495 | R29: =((O29-O$27)+(P$27-P29))/-2 -> 7.6989233 | S29: =B29-O29 -> 0.5619015 | T29: =(D29-Q29)^2 -> 0.00040272105 | U29: =((((B29-O29)+(25*D29))+(5*(((10-LEN(SUBSTITUTE(H29,"w","")))/10)-D29)))+(VALUE(MID(G29,2,2))/PI()))-12.5 -> -1.6586216 | W29: FALSE | X29: =RANK(D29+K29/1000000,Z$5:Z$32)+4 -> 19 | Z29: =D29+K29/1000000 -> 0.35709686
A30: =TRIM(MID(dump!$A34,1,28)) -> New York Dolls | B30: =VALUE(MID(dump!$A34,29,3)) -> 8 | C30: =VALUE(MID(dump!$A34,34,3)) -> 20 | D30: =B30/(B30+C30) -> 0.28571429 | E30: =((B30-B$27)+(C$27-C30))/-2 -> 15 | F30: =((10-LEN(SUBSTITUTE(H30,"w","")))&"-")&LEN(SUBSTITUTE(H30,"w","")) -> 2-8 | G30: =TRIM(MID(dump!$A34,61,3)) -> L2 | H30: =TRIM(MID(dump!$A34,65,10)) -> llwllwllll | I30: =VALUE(MID(dump!$A34,77,4)) -> 99 | J30: =VALUE(MID(dump!$A34,82,4)) -> 166 | K30: =I30-J30 -> -67 | L30: =I30/($B30+$C30) -> 3.5357143 | M30: =J30/($B30+$C30) -> 5.9285714 | N30: =L30-M30 -> -2.3928571 | O30: =Q30*(B30+C30) -> 7.6972908 | P30: =(B30+C30)-O30 -> 20.302709 | Q30: =(L30^Q$54)/((L30^Q$54)+(M30^Q$54)) -> 0.27490324 | R30: =((O30-O$27)+(P$27-P30))/-2 -> 9.439731 | S30: =B30-O30 -> 0.30270924 | T30: =(D30-Q30)^2 -> 0.00011687867 | U30: =((((B30-O30)+(25*D30))+(5*(((10-LEN(SUBSTITUTE(H30,"w","")))/10)-D30)))+(VALUE(MID(G30,2,2))/PI()))-12.5 -> -4.8463853 | W30: FALSE | X30: =RANK(D30+K30/1000000,Z$5:Z$32)+4 -> 21 | Z30: =D30+K30/1000000 -> 0.28564729
A31: =TRIM(MID(dump!$A35,1,28)) -> Hartford Dark Blues | B31: =VALUE(MID(dump!$A35,29,3)) -> 7 | C31: =VALUE(MID(dump!$A35,34,3)) -> 21 | D31: =B31/(B31+C31) -> 0.25 | E31: =((B31-B$27)+(C$27-C31))/-2 -> 16 | F31: =((10-LEN(SUBSTITUTE(H31,"w","")))&"-")&LEN(SUBSTITUTE(H31,"w","")) -> 1-9 | G31: =TRIM(MID(dump!$A35,61,3)) -> L8 | H31: =TRIM(MID(dump!$A35,65,10)) -> llllllllwl | I31: =VALUE(MID(dump!$A35,77,4)) -> 144 | J31: =VALUE(MID(dump!$A35,82,4)) -> 187 | K31: =I31-J31 -> -43 | L31: =I31/($B31+$C31) -> 5.1428571 | M31: =J31/($B31+$C31) -> 6.6785714 | N31: =L31-M31 -> -1.5357143 | O31: =Q31*(B31+C31) -> 10.634961 | P31: =(B31+C31)-O31 -> 17.365039 | Q31: =(L31^Q$54)/((L31^Q$54)+(M31^Q$54)) -> 0.37982003 | R31: =((O31-O$27)+(P$27-P31))/-2 -> 6.502061 | S31: =B31-O31 -> -3.6349608 | T31: =(D31-Q31)^2 -> 0.016853239 | U31: =((((B31-O31)+(25*D31))+(5*(((10-LEN(SUBSTITUTE(H31,"w","")))/10)-D31)))+(VALUE(MID(G31,2,2))/PI()))-12.5 -> -8.0884817 | W31: FALSE | X31: =RANK(D31+K31/1000000,Z$5:Z$32)+4 -> 22 | Z31: =D31+K31/1000000 -> 0.249957
A32: =TRIM(MID(dump!$A36,1,28)) -> Dún Laoghaire Messiahs | B32: =VALUE(MID(dump!$A36,29,3)) -> 6 | C32: =VALUE(MID(dump!$A36,34,3)) -> 22 | D32: =B32/(B32+C32) -> 0.21428571 | E32: =((B32-B$27)+(C$27-C32))/-2 -> 17 | F32: =((10-LEN(SUBSTITUTE(H32,"w","")))&"-")&LEN(SUBSTITUTE(H32,"w","")) -> 2-8 | G32: =TRIM(MID(dump!$A36,61,3)) -> L2 | H32: =TRIM(MID(dump!$A36,65,10)) -> llwlllllwl | I32: =VALUE(MID(dump!$A36,77,4)) -> 77 | J32: =VALUE(MID(dump!$A36,82,4)) -> 154 | K32: =I32-J32 -> -77 | L32: =I32/($B32+$C32) -> 2.75 | M32: =J32/($B32+$C32) -> 5.5 | N32: =L32-M32 -> -2.75 | O32: =Q32*(B32+C32) -> 5.9934723 | P32: =(B32+C32)-O32 -> 22.006528 | Q32: =(L32^Q$54)/((L32^Q$54)+(M32^Q$54)) -> 0.21405258 | R32: =((O32-O$27)+(P$27-P32))/-2 -> 11.143549 | S32: =B32-O32 -> 0.0065277116 | T32: =(D32-Q32)^2 -> 5.4350788e-08 | U32: =((((B32-O32)+(25*D32))+(5*(((10-LEN(SUBSTITUTE(H32,"w","")))/10)-D32)))+(VALUE(MID(G32,2,2))/PI()))-12.5 -> -6.5711382 | W32: FALSE | X32: =RANK(D32+K32/1000000,Z$5:Z$32)+4 -> 23 | Z32: =D32+K32/1000000 -> 0.21420871
A34: POSTSEASON STANDINGS
A35: Team | B35: W | C35: L | D35: Pct | E35: GB | K35: Margin | Q35: Pyth%
A36: =INDEX(A$5:A$32,MATCH($V36,$X$5:$X$32,0)) -> Newport Never Nudes | B36: =INDEX(B$5:B$32,MATCH($V36,$X$5:$X$32,0)) -> 23 | C36: =INDEX(C$5:C$32,MATCH($V36,$X$5:$X$32,0)) -> 5 | D36: =INDEX(D$5:D$32,MATCH($V36,$X$5:$X$32,0)) -> 0.82142857 | H36: BYE | K36: =INDEX(K$5:K$32,MATCH($V36,$X$5:$X$32,0)) -> 44 | Q36: =INDEX(Q$5:Q$32,MATCH($V36,$X$5:$X$32,0)) -> 0.61203649 | V36: 1
A37: =INDEX(A$5:A$32,MATCH($V37,$X$5:$X$32,0)) -> Dinosaur Iguanodons | B37: =INDEX(B$5:B$32,MATCH($V37,$X$5:$X$32,0)) -> 22 | C37: =INDEX(C$5:C$32,MATCH($V37,$X$5:$X$32,0)) -> 6 | D37: =INDEX(D$5:D$32,MATCH($V37,$X$5:$X$32,0)) -> 0.78571429 | H37: BYE | K37: =INDEX(K$5:K$32,MATCH($V37,$X$5:$X$32,0)) -> 133 | Q37: =INDEX(Q$5:Q$32,MATCH($V37,$X$5:$X$32,0)) -> 0.84587864 | V37: 2
A38: =INDEX(A$5:A$32,MATCH($V38,$X$5:$X$32,0)) -> Evanston Endorphins | B38: =INDEX(B$5:B$32,MATCH($V38,$X$5:$X$32,0)) -> 18 | C38: =INDEX(C$5:C$32,MATCH($V38,$X$5:$X$32,0)) -> 10 | D38: =INDEX(D$5:D$32,MATCH($V38,$X$5:$X$32,0)) -> 0.64285714 | H38: DIVISION | K38: =INDEX(K$5:K$32,MATCH($V38,$X$5:$X$32,0)) -> 30 | Q38: =INDEX(Q$5:Q$32,MATCH($V38,$X$5:$X$32,0)) -> 0.59956418 | V38: 3
A39: =INDEX(A$5:A$32,MATCH($V39,$X$5:$X$32,0)) -> Barcelona Brewers | B39: =INDEX(B$5:B$32,MATCH($V39,$X$5:$X$32,0)) -> 16 | C39: =INDEX(C$5:C$32,MATCH($V39,$X$5:$X$32,0)) -> 12 | D39: =INDEX(D$5:D$32,MATCH($V39,$X$5:$X$32,0)) -> 0.57142857 | H39: DIVISION | K39: =INDEX(K$5:K$32,MATCH($V39,$X$5:$X$32,0)) -> 29 | Q39: =INDEX(Q$5:Q$32,MATCH($V39,$X$5:$X$32,0)) -> 0.5902853 | V39: 4
A40: =INDEX(A$5:A$32,MATCH($V40,$X$5:$X$32,0)) -> Cincinnati Reds | B40: =INDEX(B$5:B$32,MATCH($V40,$X$5:$X$32,0)) -> 21 | C40: =INDEX(C$5:C$32,MATCH($V40,$X$5:$X$32,0)) -> 7 | D40: =INDEX(D$5:D$32,MATCH($V40,$X$5:$X$32,0)) -> 0.75 | H40: WILD CARD | K40: =INDEX(K$5:K$32,MATCH($V40,$X$5:$X$32,0)) -> 36 | Q40: =INDEX(Q$5:Q$32,MATCH($V40,$X$5:$X$32,0)) -> 0.6070594 | V40: 5
A41: =INDEX(A$5:A$32,MATCH($V41,$X$5:$X$32,0)) -> Okoboji Cropdusters | B41: =INDEX(B$5:B$32,MATCH($V41,$X$5:$X$32,0)) -> 19 | C41: =INDEX(C$5:C$32,MATCH($V41,$X$5:$X$32,0)) -> 9 | D41: =INDEX(D$5:D$32,MATCH($V41,$X$5:$X$32,0)) -> 0.67857143 | H41: WILD CARD | K41: =INDEX(K$5:K$32,MATCH($V41,$X$5:$X$32,0)) -> 55 | Q41: =INDEX(Q$5:Q$32,MATCH($V41,$X$5:$X$32,0)) -> 0.67556144 | V41: 6
...

Sheet dump
A1: 1 2 3 4 5 6 7 8 9 0
A3: Team W L Pct GB L10 Strk Recent RF RA Mgn Mgc pW pPct
A4: EASTERN CONFERENCE
A5: LIPLESS
A6: Barcelona Brewers 16 12 .571 - 4-6 W1 wlllllwwlw 164 135 29 133 17 .596
A7: Chinatrust Whales 14 14 .500 2 6-4 L1 lwwlwwwwll 122 128 -6 137 13 .476
A8: Chico's Bail Bonds 13 15 .464 3 5-5 L1 lwlwwwwlll 159 155 4 138 14 .513
A9: Philly Halladaze 13 15 .464 3 4-6 W2 wwlwlllllw 119 138 -19 138 12 .426
A10: Garmisch-Parten Shebazzle! 8 20 .286 8 4-6 L2 llwwllwwll 136 197 -61 143 9 .323
A11: Rocky Mountain Oysters 5 23 .179 11 1-9 L8 llllllllwl 85 194 -109 146 5 .161
A13: HIGH HORSE
A14: Dinosaur Iguanodons 22 6 .786 - 9-1 W2 wwlwwwwwww 223 90 133 134 24 .860
... A36: Dún Laoghaire Messiahs 6 22 .214 17 2-8 L2 llwlllllwl 77 154 -77 152 6 .200
