Workbook
Name Sched: Output!#REF!
Name Sched: '2004'!$D$1:$I$1588
Name Sort: '2004'!$D$1:$G$1621

Sheet Output
B1: INCHES - 2004 - Les Savy Fav
A2: Team# | B2: 13 | C2: 7 | D2: 8 | E2: 9 | F2: 17 | G2: 14 | H2: 20 | I2: 2 | J2: 10 | K2: 3 | L2: 16 | M2: 1 | N2: 4 | O2: 5 | P2: 12 | Q2: 23 | R2: 22 | S2: 11 | T2: 21 | U2: 24
A3: Division | B3: J U M P I N G | G3: C R U I S E | L3: B A R C E L O N A | Q3: G O O D B Y E
A4: Team | B4: BBG | C4: BAR | D4: CTW | E4: CIN | F4: GAR | G4: CEN | H4: FDH | I4: NEP | J4: REN | K4: TEW | L4: DIG | M4: FFR | N4: NNN | O4: OKO | P4: RMO | Q4: BRK | R4: CBB | S4: HAR | T4: NYD | U4: PHI
A5: 38082 | B5: =IF(ISNA(VLOOKUP($A5&B$2,'2004'!$B$2:$K$1621,10,0)),VLOOKUP($A5&B$2,'2004'!$A$2:$K$1621,10,0),VLOOKUP($A5&B$2,'2004'!$B$2:$K$1621,10,0)) -> CBB | C5: =IF(ISNA(VLOOKUP($A5&C$2,'2004'!$B$2:$K$1621,10,0)),VLOOKUP($A5&C$2,'2004'!$A$2:$K$1621,10,0),VLOOKUP($A5&C$2,'2004'!$B$2:$K$1621,10,0)) -> PHI | D5: =IF(ISNA(VLOOKUP($A5&D$2,'2004'!$B$2:$K$1621,10,0)),VLOOKUP($A5&D$2,'2004'!$A$2:$K$1621,10,0),VLOOKUP($A5&D$2,'2004'!$B$2:$K$1621,10,0)) -> NYD | E5: =IF(ISNA(VLOOKUP($A5&E$2,'2004'!$B$2:$K$1621,10,0)),VLOOKUP($A5&E$2,'2004'!$A$2:$K$1621,10,0),VLOOKUP($A5&E$2,'2004'!$B$2:$K$1621,10,0)) -> HAR | F5: =IF(ISNA(VLOOKUP($A5&F$2,'2004'!$B$2:$K$1621,10,0)),VLOOKUP($A5&F$2,'2004'!$A$2:$K$1621,10,0),VLOOKUP($A5&F$2,'2004'!$B$2:$K$1621,10,0)) -> BRK | G5: =IF(ISNA(VLOOKUP($A5&G$2,'2004'!$B$2:$K$1621,10,0)),VLOOKUP($A5&G$2,'2004'!$A$2:$K$1621,10,0),VLOOKUP($A5&G$2,'2004'!$B$2:$K$1621,10,0)) -> RMO | H5: =IF(ISNA(VLOOKUP($A5&H$2,'2004'!$B$2:$K$1621,10,0)),VLOOKUP($A5&H$2,'2004'!$A$2:$K$1621,10,0),VLOOKUP($A5&H$2,'2004'!$B$2:$K$1621,10,0)) -> FFR | I5: =IF(ISNA(VLOOKUP($A5&I$2,'2004'!$B$2:$K$1621,10,0)),VLOOKUP($A5&I$2,'2004'!$A$2:$K$1621,10,0),VLOOKUP($A5&I$2,'2004'!$B$2:$K$1621,10,0)) -> NNN | ... U5: =IF(ISNA(VLOOKUP($A5&U$2,'2004'!$B$2:$K$1621,10,0)),VLOOKUP($A5&U$2,'2004'!$A$2:$K$1621,10,0),VLOOKUP($A5&U$2,'2004'!$B$2:$K$1621,10,0)) -> @BAR
A6: =A5+1 -> 38083 | B6: =IF(ISNA(VLOOKUP($A6&B$2,'2004'!$B$2:$K$1621,10,0)),VLOOKUP($A6&B$2,'2004'!$A$2:$K$1621,10,0),VLOOKUP($A6&B$2,'2004'!$B$2:$K$1621,10,0)) -> CBB | C6: =IF(ISNA(VLOOKUP($A6&C$2,'2004'!$B$2:$K$1621,10,0)),VLOOKUP($A6&C$2,'2004'!$A$2:$K$1621,10,0),VLOOKUP($A6&C$2,'2004'!$B$2:$K$1621,10,0)) -> PHI | D6: =IF(ISNA(VLOOKUP($A6&D$2,'2004'!$B$2:$K$1621,10,0)),VLOOKUP($A6&D$2,'2004'!$A$2:$K$1621,10,0),VLOOKUP($A6&D$2,'2004'!$B$2:$K$1621,10,0)) -> NYD | E6: =IF(ISNA(VLOOKUP($A6&E$2,'2004'!$B$2:$K$1621,10,0)),VLOOKUP($A6&E$2,'2004'!$A$2:$K$1621,10,0),VLOOKUP($A6&E$2,'2004'!$B$2:$K$1621,10,0)) -> HAR | F6: =IF(ISNA(VLOOKUP($A6&F$2,'2004'!$B$2:$K$1621,10,0)),VLOOKUP($A6&F$2,'2004'!$A$2:$K$1621,10,0),VLOOKUP($A6&F$2,'2004'!$B$2:$K$1621,10,0)) -> BRK | G6: =IF(ISNA(VLOOKUP($A6&G$2,'2004'!$B$2:$K$1621,10,0)),VLOOKUP($A6&G$2,'2004'!$A$2:$K$1621,10,0),VLOOKUP($A6&G$2,'2004'!$B$2:$K$1621,10,0)) -> RMO | H6: =IF(ISNA(VLOOKUP($A6&H$2,'2004'!$B$2:$K$1621,10,0)),VLOOKUP($A6&H$2,'2004'!$A$2:$K$1621,10,0),VLOOKUP($A6&H$2,'2004'!$B$2:$K$1621,10,0)) -> FFR | I6: =IF(ISNA(VLOOKUP($A6&I$2,'2004'!$B$2:$K$1621,10,0)),VLOOKUP($A6&I$2,'2004'!$A$2:$K$1621,10,0),VLOOKUP($A6&I$2,'2004'!$B$2:$K$1621,10,0)) -> NNN | ... U6: =IF(ISNA(VLOOKUP($A6&U$2,'2004'!$B$2:$K$1621,10,0)),VLOOKUP($A6&U$2,'2004'!$A$2:$K$1621,10,0),VLOOKUP($A6&U$2,'2004'!$B$2:$K$1621,10,0)) -> @BAR
A7: =A6+1 -> 38084 | B7: =IF(ISNA(VLOOKUP($A7&B$2,'2004'!$B$2:$K$1621,10,0)),VLOOKUP($A7&B$2,'2004'!$A$2:$K$1621,10,0),VLOOKUP($A7&B$2,'2004'!$B$2:$K$1621,10,0)) -> CBB | C7: =IF(ISNA(VLOOKUP($A7&C$2,'2004'!$B$2:$K$1621,10,0)),VLOOKUP($A7&C$2,'2004'!$A$2:$K$1621,10,0),VLOOKUP($A7&C$2,'2004'!$B$2:$K$1621,10,0)) -> PHI | D7: =IF(ISNA(VLOOKUP($A7&D$2,'2004'!$B$2:$K$1621,10,0)),VLOOKUP($A7&D$2,'2004'!$A$2:$K$1621,10,0),VLOOKUP($A7&D$2,'2004'!$B$2:$K$1621,10,0)) -> NYD | E7: =IF(ISNA(VLOOKUP($A7&E$2,'2004'!$B$2:$K$1621,10,0)),VLOOKUP($A7&E$2,'2004'!$A$2:$K$1621,10,0),VLOOKUP($A7&E$2,'2004'!$B$2:$K$1621,10,0)) -> HAR | F7: =IF(ISNA(VLOOKUP($A7&F$2,'2004'!$B$2:$K$1621,10,0)),VLOOKUP($A7&F$2,'2004'!$A$2:$K$1621,10,0),VLOOKUP($A7&F$2,'2004'!$B$2:$K$1621,10,0)) -> BRK | G7: =IF(ISNA(VLOOKUP($A7&G$2,'2004'!$B$2:$K$1621,10,0)),VLOOKUP($A7&G$2,'2004'!$A$2:$K$1621,10,0),VLOOKUP($A7&G$2,'2004'!$B$2:$K$1621,10,0)) -> RMO | H7: =IF(ISNA(VLOOKUP($A7&H$2,'2004'!$B$2:$K$1621,10,0)),VLOOKUP($A7&H$2,'2004'!$A$2:$K$1621,10,0),VLOOKUP($A7&H$2,'2004'!$B$2:$K$1621,10,0)) -> FFR | I7: =IF(ISNA(VLOOKUP($A7&I$2,'2004'!$B$2:$K$1621,10,0)),VLOOKUP($A7&I$2,'2004'!$A$2:$K$1621,10,0),VLOOKUP($A7&I$2,'2004'!$B$2:$K$1621,10,0)) -> NNN | ... U7: =IF(ISNA(VLOOKUP($A7&U$2,'2004'!$B$2:$K$1621,10,0)),VLOOKUP($A7&U$2,'2004'!$A$2:$K$1621,10,0),VLOOKUP($A7&U$2,'2004'!$B$2:$K$1621,10,0)) -> @BAR
A8: =A7+1 -> 38085 | B8: =IF(ISNA(VLOOKUP($A8&B$2,'2004'!$B$2:$K$1621,10,0)),VLOOKUP($A8&B$2,'2004'!$A$2:$K$1621,10,0),VLOOKUP($A8&B$2,'2004'!$B$2:$K$1621,10,0)) -> CBB | C8: =IF(ISNA(VLOOKUP($A8&C$2,'2004'!$B$2:$K$1621,10,0)),VLOOKUP($A8&C$2,'2004'!$A$2:$K$1621,10,0),VLOOKUP($A8&C$2,'2004'!$B$2:$K$1621,10,0)) -> PHI | D8: =IF(ISNA(VLOOKUP($A8&D$2,'2004'!$B$2:$K$1621,10,0)),VLOOKUP($A8&D$2,'2004'!$A$2:$K$1621,10,0),VLOOKUP($A8&D$2,'2004'!$B$2:$K$1621,10,0)) -> NYD | E8: =IF(ISNA(VLOOKUP($A8&E$2,'2004'!$B$2:$K$1621,10,0)),VLOOKUP($A8&E$2,'2004'!$A$2:$K$1621,10,0),VLOOKUP($A8&E$2,'2004'!$B$2:$K$1621,10,0)) -> HAR | F8: =IF(ISNA(VLOOKUP($A8&F$2,'2004'!$B$2:$K$1621,10,0)),VLOOKUP($A8&F$2,'2004'!$A$2:$K$1621,10,0),VLOOKUP($A8&F$2,'2004'!$B$2:$K$1621,10,0)) -> BRK | G8: =IF(ISNA(VLOOKUP($A8&G$2,'2004'!$B$2:$K$1621,10,0)),VLOOKUP($A8&G$2,'2004'!$A$2:$K$1621,10,0),VLOOKUP($A8&G$2,'2004'!$B$2:$K$1621,10,0)) -> RMO | H8: =IF(ISNA(VLOOKUP($A8&H$2,'2004'!$B$2:$K$1621,10,0)),VLOOKUP($A8&H$2,'2004'!$A$2:$K$1621,10,0),VLOOKUP($A8&H$2,'2004'!$B$2:$K$1621,10,0)) -> FFR | I8: =IF(ISNA(VLOOKUP($A8&I$2,'2004'!$B$2:$K$1621,10,0)),VLOOKUP($A8&I$2,'2004'!$A$2:$K$1621,10,0),VLOOKUP($A8&I$2,'2004'!$B$2:$K$1621,10,0)) -> NNN | ... U8: =IF(ISNA(VLOOKUP($A8&U$2,'2004'!$B$2:$K$1621,10,0)),VLOOKUP($A8&U$2,'2004'!$A$2:$K$1621,10,0),VLOOKUP($A8&U$2,'2004'!$B$2:$K$1621,10,0)) -> @BAR
A9: =A8+1 -> 38086 | B9: =IF(ISNA(VLOOKUP($A9&B$2,'2004'!$B$2:$K$1621,10,0)),VLOOKUP($A9&B$2,'2004'!$A$2:$K$1621,10,0),VLOOKUP($A9&B$2,'2004'!$B$2:$K$1621,10,0)) -> @TEW | C9: =IF(ISNA(VLOOKUP($A9&C$2,'2004'!$B$2:$K$1621,10,0)),VLOOKUP($A9&C$2,'2004'!$A$2:$K$1621,10,0),VLOOKUP($A9&C$2,'2004'!$B$2:$K$1621,10,0)) -> CTW | D9: =IF(ISNA(VLOOKUP($A9&D$2,'2004'!$B$2:$K$1621,10,0)),VLOOKUP($A9&D$2,'2004'!$A$2:$K$1621,10,0),VLOOKUP($A9&D$2,'2004'!$B$2:$K$1621,10,0)) -> @BAR | E9: =IF(ISNA(VLOOKUP($A9&E$2,'2004'!$B$2:$K$1621,10,0)),VLOOKUP($A9&E$2,'2004'!$A$2:$K$1621,10,0),VLOOKUP($A9&E$2,'2004'!$B$2:$K$1621,10,0)) -> GAR | F9: =IF(ISNA(VLOOKUP($A9&F$2,'2004'!$B$2:$K$1621,10,0)),VLOOKUP($A9&F$2,'2004'!$A$2:$K$1621,10,0),VLOOKUP($A9&F$2,'2004'!$B$2:$K$1621,10,0)) -> @CIN | G9: =IF(ISNA(VLOOKUP($A9&G$2,'2004'!$B$2:$K$1621,10,0)),VLOOKUP($A9&G$2,'2004'!$A$2:$K$1621,10,0),VLOOKUP($A9&G$2,'2004'!$B$2:$K$1621,10,0)) -> NEP | H9: =IF(ISNA(VLOOKUP($A9&H$2,'2004'!$B$2:$K$1621,10,0)),VLOOKUP($A9&H$2,'2004'!$A$2:$K$1621,10,0),VLOOKUP($A9&H$2,'2004'!$B$2:$K$1621,10,0)) -> REN | I9: =IF(ISNA(VLOOKUP($A9&I$2,'2004'!$B$2:$K$1621,10,0)),VLOOKUP($A9&I$2,'2004'!$A$2:$K$1621,10,0),VLOOKUP($A9&I$2,'2004'!$B$2:$K$1621,10,0)) -> @CEN | ... U9: =IF(ISNA(VLOOKUP($A9&U$2,'2004'!$B$2:$K$1621,10,0)),VLOOKUP($A9&U$2,'2004'!$A$2:$K$1621,10,0),VLOOKUP($A9&U$2,'2004'!$B$2:$K$1621,10,0)) -> @CBB
A10: =A9+1 -> 38087 | B10: =IF(ISNA(VLOOKUP($A10&B$2,'2004'!$B$2:$K$1621,10,0)),VLOOKUP($A10&B$2,'2004'!$A$2:$K$1621,10,0),VLOOKUP($A10&B$2,'2004'!$B$2:$K$1621,10,0)) -> @TEW | C10: =IF(ISNA(VLOOKUP($A10&C$2,'2004'!$B$2:$K$1621,10,0)),VLOOKUP($A10&C$2,'2004'!$A$2:$K$1621,10,0),VLOOKUP($A10&C$2,'2004'!$B$2:$K$1621,10,0)) -> CTW | D10: =IF(ISNA(VLOOKUP($A10&D$2,'2004'!$B$2:$K$1621,10,0)),VLOOKUP($A10&D$2,'2004'!$A$2:$K$1621,10,0),VLOOKUP($A10&D$2,'2004'!$B$2:$K$1621,10,0)) -> @BAR | E10: =IF(ISNA(VLOOKUP($A10&E$2,'2004'!$B$2:$K$1621,10,0)),VLOOKUP($A10&E$2,'2004'!$A$2:$K$1621,10,0),VLOOKUP($A10&E$2,'2004'!$B$2:$K$1621,10,0)) -> GAR | F10: =IF(ISNA(VLOOKUP($A10&F$2,'2004'!$B$2:$K$1621,10,0)),VLOOKUP($A10&F$2,'2004'!$A$2:$K$1621,10,0),VLOOKUP($A10&F$2,'2004'!$B$2:$K$1621,10,0)) -> @CIN | G10: =IF(ISNA(VLOOKUP($A10&G$2,'2004'!$B$2:$K$1621,10,0)),VLOOKUP($A10&G$2,'2004'!$A$2:$K$1621,10,0),VLOOKUP($A10&G$2,'2004'!$B$2:$K$1621,10,0)) -> NEP | H10: =IF(ISNA(VLOOKUP($A10&H$2,'2004'!$B$2:$K$1621,10,0)),VLOOKUP($A10&H$2,'2004'!$A$2:$K$1621,10,0),VLOOKUP($A10&H$2,'2004'!$B$2:$K$1621,10,0)) -> REN | I10: =IF(ISNA(VLOOKUP($A10&I$2,'2004'!$B$2:$K$1621,10,0)),VLOOKUP($A10&I$2,'2004'!$A$2:$K$1621,10,0),VLOOKUP($A10&I$2,'2004'!$B$2:$K$1621,10,0)) -> @CEN | ... U10: =IF(ISNA(VLOOKUP($A10&U$2,'2004'!$B$2:$K$1621,10,0)),VLOOKUP($A10&U$2,'2004'!$A$2:$K$1621,10,0),VLOOKUP($A10&U$2,'2004'!$B$2:$K$1621,10,0)) -> @CBB
A11: =A10+1 -> 38088 | B11: =IF(ISNA(VLOOKUP($A11&B$2,'2004'!$B$2:$K$1621,10,0)),VLOOKUP($A11&B$2,'2004'!$A$2:$K$1621,10,0),VLOOKUP($A11&B$2,'2004'!$B$2:$K$1621,10,0)) -> @TEW | C11: =IF(ISNA(VLOOKUP($A11&C$2,'2004'!$B$2:$K$1621,10,0)),VLOOKUP($A11&C$2,'2004'!$A$2:$K$1621,10,0),VLOOKUP($A11&C$2,'2004'!$B$2:$K$1621,10,0)) -> CTW | D11: =IF(ISNA(VLOOKUP($A11&D$2,'2004'!$B$2:$K$1621,10,0)),VLOOKUP($A11&D$2,'2004'!$A$2:$K$1621,10,0),VLOOKUP($A11&D$2,'2004'!$B$2:$K$1621,10,0)) -> @BAR | E11: =IF(ISNA(VLOOKUP($A11&E$2,'2004'!$B$2:$K$1621,10,0)),VLOOKUP($A11&E$2,'2004'!$A$2:$K$1621,10,0),VLOOKUP($A11&E$2,'2004'!$B$2:$K$1621,10,0)) -> GAR | F11: =IF(ISNA(VLOOKUP($A11&F$2,'2004'!$B$2:$K$1621,10,0)),VLOOKUP($A11&F$2,'2004'!$A$2:$K$1621,10,0),VLOOKUP($A11&F$2,'2004'!$B$2:$K$1621,10,0)) -> @CIN | G11: =IF(ISNA(VLOOKUP($A11&G$2,'2004'!$B$2:$K$1621,10,0)),VLOOKUP($A11&G$2,'2004'!$A$2:$K$1621,10,0),VLOOKUP($A11&G$2,'2004'!$B$2:$K$1621,10,0)) -> NEP | H11: =IF(ISNA(VLOOKUP($A11&H$2,'2004'!$B$2:$K$1621,10,0)),VLOOKUP($A11&H$2,'2004'!$A$2:$K$1621,10,0),VLOOKUP($A11&H$2,'2004'!$B$2:$K$1621,10,0)) -> REN | I11: =IF(ISNA(VLOOKUP($A11&I$2,'2004'!$B$2:$K$1621,10,0)),VLOOKUP($A11&I$2,'2004'!$A$2:$K$1621,10,0),VLOOKUP($A11&I$2,'2004'!$B$2:$K$1621,10,0)) -> @CEN | ... U11: =IF(ISNA(VLOOKUP($A11&U$2,'2004'!$B$2:$K$1621,10,0)),VLOOKUP($A11&U$2,'2004'!$A$2:$K$1621,10,0),VLOOKUP($A11&U$2,'2004'!$B$2:$K$1621,10,0)) -> @CBB
A12: =A11+1 -> 38089 | B12: =IF(ISNA(VLOOKUP($A12&B$2,'2004'!$B$2:$K$1621,10,0)),VLOOKUP($A12&B$2,'2004'!$A$2:$K$1621,10,0),VLOOKUP($A12&B$2,'2004'!$B$2:$K$1621,10,0)) -> @TEW | C12: =IF(ISNA(VLOOKUP($A12&C$2,'2004'!$B$2:$K$1621,10,0)),VLOOKUP($A12&C$2,'2004'!$A$2:$K$1621,10,0),VLOOKUP($A12&C$2,'2004'!$B$2:$K$1621,10,0)) -> #N/A | D12: =IF(ISNA(VLOOKUP($A12&D$2,'2004'!$B$2:$K$1621,10,0)),VLOOKUP($A12&D$2,'2004'!$A$2:$K$1621,10,0),VLOOKUP($A12&D$2,'2004'!$B$2:$K$1621,10,0)) -> #N/A | E12: =IF(ISNA(VLOOKUP($A12&E$2,'2004'!$B$2:$K$1621,10,0)),VLOOKUP($A12&E$2,'2004'!$A$2:$K$1621,10,0),VLOOKUP($A12&E$2,'2004'!$B$2:$K$1621,10,0)) -> #N/A | F12: =IF(ISNA(VLOOKUP($A12&F$2,'2004'!$B$2:$K$1621,10,0)),VLOOKUP($A12&F$2,'2004'!$A$2:$K$1621,10,0),VLOOKUP($A12&F$2,'2004'!$B$2:$K$1621,10,0)) -> #N/A | G12: =IF(ISNA(VLOOKUP($A12&G$2,'2004'!$B$2:$K$1621,10,0)),VLOOKUP($A12&G$2,'2004'!$A$2:$K$1621,10,0),VLOOKUP($A12&G$2,'2004'!$B$2:$K$1621,10,0)) -> #N/A | H12: =IF(ISNA(VLOOKUP($A12&H$2,'2004'!$B$2:$K$1621,10,0)),VLOOKUP($A12&H$2,'2004'!$A$2:$K$1621,10,0),VLOOKUP($A12&H$2,'2004'!$B$2:$K$1621,10,0)) -> #N/A | I12: =IF(ISNA(VLOOKUP($A12&I$2,'2004'!$B$2:$K$1621,10,0)),VLOOKUP($A12&I$2,'2004'!$A$2:$K$1621,10,0),VLOOKUP($A12&I$2,'2004'!$B$2:$K$1621,10,0)) -> #N/A | ... U12: =IF(ISNA(VLOOKUP($A12&U$2,'2004'!$B$2:$K$1621,10,0)),VLOOKUP($A12&U$2,'2004'!$A$2:$K$1621,10,0),VLOOKUP($A12&U$2,'2004'!$B$2:$K$1621,10,0)) -> #N/A
A13: =A12+1 -> 38090 | B13: =IF(ISNA(VLOOKUP($A13&B$2,'2004'!$B$2:$K$1621,10,0)),VLOOKUP($A13&B$2,'2004'!$A$2:$K$1621,10,0),VLOOKUP($A13&B$2,'2004'!$B$2:$K$1621,10,0)) -> HAR | C13: =IF(ISNA(VLOOKUP($A13&C$2,'2004'!$B$2:$K$1621,10,0)),VLOOKUP($A13&C$2,'2004'!$A$2:$K$1621,10,0),VLOOKUP($A13&C$2,'2004'!$B$2:$K$1621,10,0)) -> CBB | D13: =IF(ISNA(VLOOKUP($A13&D$2,'2004'!$B$2:$K$1621,10,0)),VLOOKUP($A13&D$2,'2004'!$A$2:$K$1621,10,0),VLOOKUP($A13&D$2,'2004'!$B$2:$K$1621,10,0)) -> PHI | E13: =IF(ISNA(VLOOKUP($A13&E$2,'2004'!$B$2:$K$1621,10,0)),VLOOKUP($A13&E$2,'2004'!$A$2:$K$1621,10,0),VLOOKUP($A13&E$2,'2004'!$B$2:$K$1621,10,0)) -> BRK | F13: =IF(ISNA(VLOOKUP($A13&F$2,'2004'!$B$2:$K$1621,10,0)),VLOOKUP($A13&F$2,'2004'!$A$2:$K$1621,10,0),VLOOKUP($A13&F$2,'2004'!$B$2:$K$1621,10,0)) -> NYD | G13: =IF(ISNA(VLOOKUP($A13&G$2,'2004'!$B$2:$K$1621,10,0)),VLOOKUP($A13&G$2,'2004'!$A$2:$K$1621,10,0),VLOOKUP($A13&G$2,'2004'!$B$2:$K$1621,10,0)) -> OKO | H13: =IF(ISNA(VLOOKUP($A13&H$2,'2004'!$B$2:$K$1621,10,0)),VLOOKUP($A13&H$2,'2004'!$A$2:$K$1621,10,0),VLOOKUP($A13&H$2,'2004'!$B$2:$K$1621,10,0)) -> DIG | I13: =IF(ISNA(VLOOKUP($A13&I$2,'2004'!$B$2:$K$1621,10,0)),VLOOKUP($A13&I$2,'2004'!$A$2:$K$1621,10,0),VLOOKUP($A13&I$2,'2004'!$B$2:$K$1621,10,0)) -> RMO | ... U13: =IF(ISNA(VLOOKUP($A13&U$2,'2004'!$B$2:$K$1621,10,0)),VLOOKUP($A13&U$2,'2004'!$A$2:$K$1621,10,0),VLOOKUP($A13&U$2,'2004'!$B$2:$K$1621,10,0)) -> @CTW
A14: =A13+1 -> 38091 | B14: =IF(ISNA(VLOOKUP($A14&B$2,'2004'!$B$2:$K$1621,10,0)),VLOOKUP($A14&B$2,'2004'!$A$2:$K$1621,10,0),VLOOKUP($A14&B$2,'2004'!$B$2:$K$1621,10,0)) -> HAR | C14: =IF(ISNA(VLOOKUP($A14&C$2,'2004'!$B$2:$K$1621,10,0)),VLOOKUP($A14&C$2,'2004'!$A$2:$K$1621,10,0),VLOOKUP($A14&C$2,'2004'!$B$2:$K$1621,10,0)) -> CBB | D14: =IF(ISNA(VLOOKUP($A14&D$2,'2004'!$B$2:$K$1621,10,0)),VLOOKUP($A14&D$2,'2004'!$A$2:$K$1621,10,0),VLOOKUP($A14&D$2,'2004'!$B$2:$K$1621,10,0)) -> PHI | E14: =IF(ISNA(VLOOKUP($A14&E$2,'2004'!$B$2:$K$1621,10,0)),VLOOKUP($A14&E$2,'2004'!$A$2:$K$1621,10,0),VLOOKUP($A14&E$2,'2004'!$B$2:$K$1621,10,0)) -> BRK | F14: =IF(ISNA(VLOOKUP($A14&F$2,'2004'!$B$2:$K$1621,10,0)),VLOOKUP($A14&F$2,'2004'!$A$2:$K$1621,10,0),VLOOKUP($A14&F$2,'2004'!$B$2:$K$1621,10,0)) -> NYD | G14: =IF(ISNA(VLOOKUP($A14&G$2,'2004'!$B$2:$K$1621,10,0)),VLOOKUP($A14&G$2,'2004'!$A$2:$K$1621,10,0),VLOOKUP($A14&G$2,'2004'!$B$2:$K$1621,10,0)) -> OKO | H14: =IF(ISNA(VLOOKUP($A14&H$2,'2004'!$B$2:$K$1621,10,0)),VLOOKUP($A14&H$2,'2004'!$A$2:$K$1621,10,0),VLOOKUP($A14&H$2,'2004'!$B$2:$K$1621,10,0)) -> DIG | I14: =IF(ISNA(VLOOKUP($A14&I$2,'2004'!$B$2:$K$1621,10,0)),VLOOKUP($A14&I$2,'2004'!$A$2:$K$1621,10,0),VLOOKUP($A14&I$2,'2004'!$B$2:$K$1621,10,0)) -> RMO | ... U14: =IF(ISNA(VLOOKUP($A14&U$2,'2004'!$B$2:$K$1621,10,0)),VLOOKUP($A14&U$2,'2004'!$A$2:$K$1621,10,0),VLOOKUP($A14&U$2,'2004'!$B$2:$K$1621,10,0)) -> @CTW
A15: =A14+1 -> 38092 | B15: =IF(ISNA(VLOOKUP($A15&B$2,'2004'!$B$2:$K$1621,10,0)),VLOOKUP($A15&B$2,'2004'!$A$2:$K$1621,10,0),VLOOKUP($A15&B$2,'2004'!$B$2:$K$1621,10,0)) -> HAR | C15: =IF(ISNA(VLOOKUP($A15&C$2,'2004'!$B$2:$K$1621,10,0)),VLOOKUP($A15&C$2,'2004'!$A$2:$K$1621,10,0),VLOOKUP($A15&C$2,'2004'!$B$2:$K$1621,10,0)) -> CBB | D15: =IF(ISNA(VLOOKUP($A15&D$2,'2004'!$B$2:$K$1621,10,0)),VLOOKUP($A15&D$2,'2004'!$A$2:$K$1621,10,0),VLOOKUP($A15&D$2,'2004'!$B$2:$K$1621,10,0)) -> PHI | E15: =IF(ISNA(VLOOKUP($A15&E$2,'2004'!$B$2:$K$1621,10,0)),VLOOKUP($A15&E$2,'2004'!$A$2:$K$1621,10,0),VLOOKUP($A15&E$2,'2004'!$B$2:$K$1621,10,0)) -> BRK | F15: =IF(ISNA(VLOOKUP($A15&F$2,'2004'!$B$2:$K$1621,10,0)),VLOOKUP($A15&F$2,'2004'!$A$2:$K$1621,10,0),VLOOKUP($A15&F$2,'2004'!$B$2:$K$1621,10,0)) -> NYD | G15: =IF(ISNA(VLOOKUP($A15&G$2,'2004'!$B$2:$K$1621,10,0)),VLOOKUP($A15&G$2,'2004'!$A$2:$K$1621,10,0),VLOOKUP($A15&G$2,'2004'!$B$2:$K$1621,10,0)) -> OKO | H15: =IF(ISNA(VLOOKUP($A15&H$2,'2004'!$B$2:$K$1621,10,0)),VLOOKUP($A15&H$2,'2004'!$A$2:$K$1621,10,0),VLOOKUP($A15&H$2,'2004'!$B$2:$K$1621,10,0)) -> DIG | I15: =IF(ISNA(VLOOKUP($A15&I$2,'2004'!$B$2:$K$1621,10,0)),VLOOKUP($A15&I$2,'2004'!$A$2:$K$1621,10,0),VLOOKUP($A15&I$2,'2004'!$B$2:$K$1621,10,0)) -> RMO | ... U15: =IF(ISNA(VLOOKUP($A15&U$2,'2004'!$B$2:$K$1621,10,0)),VLOOKUP($A15&U$2,'2004'!$A$2:$K$1621,10,0),VLOOKUP($A15&U$2,'2004'!$B$2:$K$1621,10,0)) -> @CTW
A16: =A15+1 -> 38093 | B16: =IF(ISNA(VLOOKUP($A16&B$2,'2004'!$B$2:$K$1621,10,0)),VLOOKUP($A16&B$2,'2004'!$A$2:$K$1621,10,0),VLOOKUP($A16&B$2,'2004'!$B$2:$K$1621,10,0)) -> HAR | C16: =IF(ISNA(VLOOKUP($A16&C$2,'2004'!$B$2:$K$1621,10,0)),VLOOKUP($A16&C$2,'2004'!$A$2:$K$1621,10,0),VLOOKUP($A16&C$2,'2004'!$B$2:$K$1621,10,0)) -> CBB | D16: =IF(ISNA(VLOOKUP($A16&D$2,'2004'!$B$2:$K$1621,10,0)),VLOOKUP($A16&D$2,'2004'!$A$2:$K$1621,10,0),VLOOKUP($A16&D$2,'2004'!$B$2:$K$1621,10,0)) -> PHI | E16: =IF(ISNA(VLOOKUP($A16&E$2,'2004'!$B$2:$K$1621,10,0)),VLOOKUP($A16&E$2,'2004'!$A$2:$K$1621,10,0),VLOOKUP($A16&E$2,'2004'!$B$2:$K$1621,10,0)) -> BRK | F16: =IF(ISNA(VLOOKUP($A16&F$2,'2004'!$B$2:$K$1621,10,0)),VLOOKUP($A16&F$2,'2004'!$A$2:$K$1621,10,0),VLOOKUP($A16&F$2,'2004'!$B$2:$K$1621,10,0)) -> NYD | G16: =IF(ISNA(VLOOKUP($A16&G$2,'2004'!$B$2:$K$1621,10,0)),VLOOKUP($A16&G$2,'2004'!$A$2:$K$1621,10,0),VLOOKUP($A16&G$2,'2004'!$B$2:$K$1621,10,0)) -> OKO | H16: =IF(ISNA(VLOOKUP($A16&H$2,'2004'!$B$2:$K$1621,10,0)),VLOOKUP($A16&H$2,'2004'!$A$2:$K$1621,10,0),VLOOKUP($A16&H$2,'2004'!$B$2:$K$1621,10,0)) -> DIG | I16: =IF(ISNA(VLOOKUP($A16&I$2,'2004'!$B$2:$K$1621,10,0)),VLOOKUP($A16&I$2,'2004'!$A$2:$K$1621,10,0),VLOOKUP($A16&I$2,'2004'!$B$2:$K$1621,10,0)) -> RMO | ... U16: =IF(ISNA(VLOOKUP($A16&U$2,'2004'!$B$2:$K$1621,10,0)),VLOOKUP($A16&U$2,'2004'!$A$2:$K$1621,10,0),VLOOKUP($A16&U$2,'2004'!$B$2:$K$1621,10,0)) -> @CTW
A17: =A16+1 -> 38094 | B17: =IF(ISNA(VLOOKUP($A17&B$2,'2004'!$B$2:$K$1621,10,0)),VLOOKUP($A17&B$2,'2004'!$A$2:$K$1621,10,0),VLOOKUP($A17&B$2,'2004'!$B$2:$K$1621,10,0)) -> FDH | C17: =IF(ISNA(VLOOKUP($A17&C$2,'2004'!$B$2:$K$1621,10,0)),VLOOKUP($A17&C$2,'2004'!$A$2:$K$1621,10,0),VLOOKUP($A17&C$2,'2004'!$B$2:$K$1621,10,0)) -> TEW | D17: =IF(ISNA(VLOOKUP($A17&D$2,'2004'!$B$2:$K$1621,10,0)),VLOOKUP($A17&D$2,'2004'!$A$2:$K$1621,10,0),VLOOKUP($A17&D$2,'2004'!$B$2:$K$1621,10,0)) -> CEN | E17: =IF(ISNA(VLOOKUP($A17&E$2,'2004'!$B$2:$K$1621,10,0)),VLOOKUP($A17&E$2,'2004'!$A$2:$K$1621,10,0),VLOOKUP($A17&E$2,'2004'!$B$2:$K$1621,10,0)) -> REN | F17: =IF(ISNA(VLOOKUP($A17&F$2,'2004'!$B$2:$K$1621,10,0)),VLOOKUP($A17&F$2,'2004'!$A$2:$K$1621,10,0),VLOOKUP($A17&F$2,'2004'!$B$2:$K$1621,10,0)) -> NEP | G17: =IF(ISNA(VLOOKUP($A17&G$2,'2004'!$B$2:$K$1621,10,0)),VLOOKUP($A17&G$2,'2004'!$A$2:$K$1621,10,0),VLOOKUP($A17&G$2,'2004'!$B$2:$K$1621,10,0)) -> @CTW | H17: =IF(ISNA(VLOOKUP($A17&H$2,'2004'!$B$2:$K$1621,10,0)),VLOOKUP($A17&H$2,'2004'!$A$2:$K$1621,10,0),VLOOKUP($A17&H$2,'2004'!$B$2:$K$1621,10,0)) -> @BBG | I17: =IF(ISNA(VLOOKUP($A17&I$2,'2004'!$B$2:$K$1621,10,0)),VLOOKUP($A17&I$2,'2004'!$A$2:$K$1621,10,0),VLOOKUP($A17&I$2,'2004'!$B$2:$K$1621,10,0)) -> @GAR | ... U17: =IF(ISNA(VLOOKUP($A17&U$2,'2004'!$B$2:$K$1621,10,0)),VLOOKUP($A17&U$2,'2004'!$A$2:$K$1621,10,0),VLOOKUP($A17&U$2,'2004'!$B$2:$K$1621,10,0)) -> @NNN
... A186: =A185+1 -> 38263 | B186: =IF(ISNA(VLOOKUP($A186&B$2,'2004'!$B$2:$K$1621,10,0)),VLOOKUP($A186&B$2,'2004'!$A$2:$K$1621,10,0),VLOOKUP($A186&B$2,'2004'!$B$2:$K$1621,10,0)) -> #N/A | C186: =IF(ISNA(VLOOKUP($A186&C$2,'2004'!$B$2:$K$1621,10,0)),VLOOKUP($A186&C$2,'2004'!$A$2:$K$1621,10,0),VLOOKUP($A186&C$2,'2004'!$B$2:$K$1621,10,0)) -> #N/A | D186: =IF(ISNA(VLOOKUP($A186&D$2,'2004'!$B$2:$K$1621,10,0)),VLOOKUP($A186&D$2,'2004'!$A$2:$K$1621,10,0),VLOOKUP($A186&D$2,'2004'!$B$2:$K$1621,10,0)) -> #N/A | E186: =IF(ISNA(VLOOKUP($A186&E$2,'2004'!$B$2:$K$1621,10,0)),VLOOKUP($A186&E$2,'2004'!$A$2:$K$1621,10,0),VLOOKUP($A186&E$2,'2004'!$B$2:$K$1621,10,0)) -> #N/A | F186: =IF(ISNA(VLOOKUP($A186&F$2,'2004'!$B$2:$K$1621,10,0)),VLOOKUP($A186&F$2,'2004'!$A$2:$K$1621,10,0),VLOOKUP($A186&F$2,'2004'!$B$2:$K$1621,10,0)) -> #N/A | G186: =IF(ISNA(VLOOKUP($A186&G$2,'2004'!$B$2:$K$1621,10,0)),VLOOKUP($A186&G$2,'2004'!$A$2:$K$1621,10,0),VLOOKUP($A186&G$2,'2004'!$B$2:$K$1621,10,0)) -> #N/A | H186: =IF(ISNA(VLOOKUP($A186&H$2,'2004'!$B$2:$K$1621,10,0)),VLOOKUP($A186&H$2,'2004'!$A$2:$K$1621,10,0),VLOOKUP($A186&H$2,'2004'!$B$2:$K$1621,10,0)) -> #N/A | I186: =IF(ISNA(VLOOKUP($A186&I$2,'2004'!$B$2:$K$1621,10,0)),VLOOKUP($A186&I$2,'2004'!$A$2:$K$1621,10,0),VLOOKUP($A186&I$2,'2004'!$B$2:$K$1621,10,0)) -> #N/A | ... U186: =IF(ISNA(VLOOKUP($A186&U$2,'2004'!$B$2:$K$1621,10,0)),VLOOKUP($A186&U$2,'2004'!$A$2:$K$1621,10,0),VLOOKUP($A186&U$2,'2004'!$B$2:$K$1621,10,0)) -> #N/A
A188: DIAGNOSTICS
A189: home | B189: =SUM(B191:B210) -> 81 | C189: =SUM(C191:C210) -> 81 | D189: =SUM(D191:D210) -> 81 | E189: =SUM(E191:E210) -> 81 | F189: =SUM(F191:F210) -> 81 | G189: =SUM(G191:G210) -> 81 | H189: =SUM(H191:H210) -> 81 | I189: =SUM(I191:I210) -> 81 | ... U189: =SUM(U191:U210) -> 81
A190: away | B190: =SUM(B211:B230) -> 81 | C190: =SUM(C211:C230) -> 81 | D190: =SUM(D211:D230) -> 81 | E190: =SUM(E211:E230) -> 81 | F190: =SUM(F211:F230) -> 81 | G190: =SUM(G211:G230) -> 81 | H190: =SUM(H211:H230) -> 81 | I190: =SUM(I211:I230) -> 81 | ... U190: =SUM(U211:U230) -> 81
A191: BBG | B191: =COUNTIF(B$5:B$187,$A191) -> 0 | C191: =COUNTIF(C$5:C$187,$A191) -> 6 | D191: =COUNTIF(D$5:D$187,$A191) -> 5 | E191: =COUNTIF(E$5:E$187,$A191) -> 5 | F191: =COUNTIF(F$5:F$187,$A191) -> 5 | G191: =COUNTIF(G$5:G$187,$A191) -> 4 | H191: =COUNTIF(H$5:H$187,$A191) -> 4 | I191: =COUNTIF(I$5:I$187,$A191) -> 4 | ... U191: =COUNTIF(U$5:U$187,$A191) -> 4
A192: BAR | B192: =COUNTIF(B$5:B$187,$A192) -> 5 | C192: =COUNTIF(C$5:C$187,$A192) -> 0 | D192: =COUNTIF(D$5:D$187,$A192) -> 6 | E192: =COUNTIF(E$5:E$187,$A192) -> 5 | F192: =COUNTIF(F$5:F$187,$A192) -> 5 | G192: =COUNTIF(G$5:G$187,$A192) -> 4 | H192: =COUNTIF(H$5:H$187,$A192) -> 4 | I192: =COUNTIF(I$5:I$187,$A192) -> 4 | ... U192: =COUNTIF(U$5:U$187,$A192) -> 4
A193: CTW | B193: =COUNTIF(B$5:B$187,$A193) -> 5 | C193: =COUNTIF(C$5:C$187,$A193) -> 5 | D193: =COUNTIF(D$5:D$187,$A193) -> 0 | E193: =COUNTIF(E$5:E$187,$A193) -> 6 | F193: =COUNTIF(F$5:F$187,$A193) -> 5 | G193: =COUNTIF(G$5:G$187,$A193) -> 4 | H193: =COUNTIF(H$5:H$187,$A193) -> 4 | I193: =COUNTIF(I$5:I$187,$A193) -> 4 | ... U193: =COUNTIF(U$5:U$187,$A193) -> 4
A194: CIN | B194: =COUNTIF(B$5:B$187,$A194) -> 5 | C194: =COUNTIF(C$5:C$187,$A194) -> 5 | D194: =COUNTIF(D$5:D$187,$A194) -> 5 | E194: =COUNTIF(E$5:E$187,$A194) -> 0 | F194: =COUNTIF(F$5:F$187,$A194) -> 6 | G194: =COUNTIF(G$5:G$187,$A194) -> 4 | H194: =COUNTIF(H$5:H$187,$A194) -> 4 | I194: =COUNTIF(I$5:I$187,$A194) -> 4 | ... U194: =COUNTIF(U$5:U$187,$A194) -> 4
A195: GAR | B195: =COUNTIF(B$5:B$187,$A195) -> 6 | C195: =COUNTIF(C$5:C$187,$A195) -> 5 | D195: =COUNTIF(D$5:D$187,$A195) -> 5 | E195: =COUNTIF(E$5:E$187,$A195) -> 5 | F195: =COUNTIF(F$5:F$187,$A195) -> 0 | G195: =COUNTIF(G$5:G$187,$A195) -> 4 | H195: =COUNTIF(H$5:H$187,$A195) -> 4 | I195: =COUNTIF(I$5:I$187,$A195) -> 4 | ... U195: =COUNTIF(U$5:U$187,$A195) -> 4
A196: CEN | B196: =COUNTIF(B$5:B$187,$A196) -> 4 | C196: =COUNTIF(C$5:C$187,$A196) -> 4 | D196: =COUNTIF(D$5:D$187,$A196) -> 4 | E196: =COUNTIF(E$5:E$187,$A196) -> 4 | F196: =COUNTIF(F$5:F$187,$A196) -> 4 | G196: =COUNTIF(G$5:G$187,$A196) -> 0 | H196: =COUNTIF(H$5:H$187,$A196) -> 6 | I196: =COUNTIF(I$5:I$187,$A196) -> 5 | ... U196: =COUNTIF(U$5:U$187,$A196) -> 4
A197: FDH | B197: =COUNTIF(B$5:B$187,$A197) -> 4 | C197: =COUNTIF(C$5:C$187,$A197) -> 4 | D197: =COUNTIF(D$5:D$187,$A197) -> 4 | E197: =COUNTIF(E$5:E$187,$A197) -> 4 | F197: =COUNTIF(F$5:F$187,$A197) -> 4 | G197: =COUNTIF(G$5:G$187,$A197) -> 6 | H197: =COUNTIF(H$5:H$187,$A197) -> 0 | I197: =COUNTIF(I$5:I$187,$A197) -> 5 | ... U197: =COUNTIF(U$5:U$187,$A197) -> 4
A198: NEP | B198: =COUNTIF(B$5:B$187,$A198) -> 4 | C198: =COUNTIF(C$5:C$187,$A198) -> 4 | D198: =COUNTIF(D$5:D$187,$A198) -> 4 | E198: =COUNTIF(E$5:E$187,$A198) -> 4 | F198: =COUNTIF(F$5:F$187,$A198) -> 4 | G198: =COUNTIF(G$5:G$187,$A198) -> 5 | H198: =COUNTIF(H$5:H$187,$A198) -> 5 | I198: =COUNTIF(I$5:I$187,$A198) -> 0 | ... U198: =COUNTIF(U$5:U$187,$A198) -> 4
A199: REN | B199: =COUNTIF(B$5:B$187,$A199) -> 4 | C199: =COUNTIF(C$5:C$187,$A199) -> 4 | D199: =COUNTIF(D$5:D$187,$A199) -> 4 | E199: =COUNTIF(E$5:E$187,$A199) -> 4 | F199: =COUNTIF(F$5:F$187,$A199) -> 4 | G199: =COUNTIF(G$5:G$187,$A199) -> 5 | H199: =COUNTIF(H$5:H$187,$A199) -> 5 | I199: =COUNTIF(I$5:I$187,$A199) -> 5 | ... U199: =COUNTIF(U$5:U$187,$A199) -> 4
A200: TEW | B200: =COUNTIF(B$5:B$187,$A200) -> 4 | C200: =COUNTIF(C$5:C$187,$A200) -> 4 | D200: =COUNTIF(D$5:D$187,$A200) -> 4 | E200: =COUNTIF(E$5:E$187,$A200) -> 4 | F200: =COUNTIF(F$5:F$187,$A200) -> 4 | G200: =COUNTIF(G$5:G$187,$A200) -> 5 | H200: =COUNTIF(H$5:H$187,$A200) -> 5 | I200: =COUNTIF(I$5:I$187,$A200) -> 6 | ... U200: =COUNTIF(U$5:U$187,$A200) -> 4
A201: DIG | B201: =COUNTIF(B$5:B$187,$A201) -> 4 | C201: =COUNTIF(C$5:C$187,$A201) -> 4 | D201: =COUNTIF(D$5:D$187,$A201) -> 4 | E201: =COUNTIF(E$5:E$187,$A201) -> 4 | F201: =COUNTIF(F$5:F$187,$A201) -> 4 | G201: =COUNTIF(G$5:G$187,$A201) -> 4 | H201: =COUNTIF(H$5:H$187,$A201) -> 4 | I201: =COUNTIF(I$5:I$187,$A201) -> 4 | ... U201: =COUNTIF(U$5:U$187,$A201) -> 4
A202: FFR | B202: =COUNTIF(B$5:B$187,$A202) -> 4 | C202: =COUNTIF(C$5:C$187,$A202) -> 4 | D202: =COUNTIF(D$5:D$187,$A202) -> 4 | E202: =COUNTIF(E$5:E$187,$A202) -> 4 | F202: =COUNTIF(F$5:F$187,$A202) -> 4 | G202: =COUNTIF(G$5:G$187,$A202) -> 4 | H202: =COUNTIF(H$5:H$187,$A202) -> 4 | I202: =COUNTIF(I$5:I$187,$A202) -> 4 | ... U202: =COUNTIF(U$5:U$187,$A202) -> 4
... A210: PHI | B210: =COUNTIF(B$5:B$187,$A210) -> 4 | C210: =COUNTIF(C$5:C$187,$A210) -> 4 | D210: =COUNTIF(D$5:D$187,$A210) -> 4 | E210: =COUNTIF(E$5:E$187,$A210) -> 4 | F210: =COUNTIF(F$5:F$187,$A210) -> 4 | G210: =COUNTIF(G$5:G$187,$A210) -> 4 | H210: =COUNTIF(H$5:H$187,$A210) -> 4 | I210: =COUNTIF(I$5:I$187,$A210) -> 4 | ... U210: =COUNTIF(U$5:U$187,$A210) -> 0
A211: ="@"&A191 -> @BBG | B211: =COUNTIF(B$5:B$187,$A211) -> 0 | C211: =COUNTIF(C$5:C$187,$A211) -> 5 | D211: =COUNTIF(D$5:D$187,$A211) -> 5 | E211: =COUNTIF(E$5:E$187,$A211) -> 5 | F211: =COUNTIF(F$5:F$187,$A211) -> 6 | G211: =COUNTIF(G$5:G$187,$A211) -> 4 | H211: =COUNTIF(H$5:H$187,$A211) -> 4 | I211: =COUNTIF(I$5:I$187,$A211) -> 4 | ... U211: =COUNTIF(U$5:U$187,$A211) -> 4
A212: ="@"&A192 -> @BAR | B212: =COUNTIF(B$5:B$187,$A212) -> 6 | C212: =COUNTIF(C$5:C$187,$A212) -> 0 | D212: =COUNTIF(D$5:D$187,$A212) -> 5 | E212: =COUNTIF(E$5:E$187,$A212) -> 5 | F212: =COUNTIF(F$5:F$187,$A212) -> 5 | G212: =COUNTIF(G$5:G$187,$A212) -> 4 | H212: =COUNTIF(H$5:H$187,$A212) -> 4 | I212: =COUNTIF(I$5:I$187,$A212) -> 4 | ... U212: =COUNTIF(U$5:U$187,$A212) -> 4
A213: ="@"&A193 -> @CTW | B213: =COUNTIF(B$5:B$187,$A213) -> 5 | C213: =COUNTIF(C$5:C$187,$A213) -> 6 | D213: =COUNTIF(D$5:D$187,$A213) -> 0 | E213: =COUNTIF(E$5:E$187,$A213) -> 5 | F213: =COUNTIF(F$5:F$187,$A213) -> 5 | G213: =COUNTIF(G$5:G$187,$A213) -> 4 | H213: =COUNTIF(H$5:H$187,$A213) -> 4 | I213: =COUNTIF(I$5:I$187,$A213) -> 4 | ... U213: =COUNTIF(U$5:U$187,$A213) -> 4
A214: ="@"&A194 -> @CIN | B214: =COUNTIF(B$5:B$187,$A214) -> 5 | C214: =COUNTIF(C$5:C$187,$A214) -> 5 | D214: =COUNTIF(D$5:D$187,$A214) -> 6 | E214: =COUNTIF(E$5:E$187,$A214) -> 0 | F214: =COUNTIF(F$5:F$187,$A214) -> 5 | G214: =COUNTIF(G$5:G$187,$A214) -> 4 | H214: =COUNTIF(H$5:H$187,$A214) -> 4 | I214: =COUNTIF(I$5:I$187,$A214) -> 4 | ... U214: =COUNTIF(U$5:U$187,$A214) -> 4
A215: ="@"&A195 -> @GAR | B215: =COUNTIF(B$5:B$187,$A215) -> 5 | C215: =COUNTIF(C$5:C$187,$A215) -> 5 | D215: =COUNTIF(D$5:D$187,$A215) -> 5 | E215: =COUNTIF(E$5:E$187,$A215) -> 6 | F215: =COUNTIF(F$5:F$187,$A215) -> 0 | G215: =COUNTIF(G$5:G$187,$A215) -> 4 | H215: =COUNTIF(H$5:H$187,$A215) -> 4 | I215: =COUNTIF(I$5:I$187,$A215) -> 4 | ... U215: =COUNTIF(U$5:U$187,$A215) -> 4
A216: ="@"&A196 -> @CEN | B216: =COUNTIF(B$5:B$187,$A216) -> 4 | C216: =COUNTIF(C$5:C$187,$A216) -> 4 | D216: =COUNTIF(D$5:D$187,$A216) -> 4 | E216: =COUNTIF(E$5:E$187,$A216) -> 4 | F216: =COUNTIF(F$5:F$187,$A216) -> 4 | G216: =COUNTIF(G$5:G$187,$A216) -> 0 | H216: =COUNTIF(H$5:H$187,$A216) -> 6 | I216: =COUNTIF(I$5:I$187,$A216) -> 5 | ... U216: =COUNTIF(U$5:U$187,$A216) -> 4
...

Sheet 2004
A1: Combo Home | B1: Combo Away | C1: Seq | D1: Game Date | E1: god | F1: Vis | G1: Home | H1: Type | I1: Status | J1: Vis | K1: Home | L1: Paste as text for import | M1: ID | N1: Team | O1: Div
A2: =D2&G2 -> 380822 | B2: =D2&F2 -> 380824 | C2: 1 | D2: 38082 | E2: 0 | F2: 4 | G2: 2 | H2: 2 | I2: 0 | J2: =VLOOKUP(F2,$M$2:$N$21,2,0) -> NNN | K2: ="@"&VLOOKUP(G2,$M$2:$N$21,2,0) -> @NEP | L2: =C2&","&MONTH(D2)&"/"&DAY(D2)&"/"&YEAR(D2)&","&E2&","&F2&","&G2&","&H2&","&I2 -> 1,4/5/2004,0,4,2,2,0 | M2: 13 | N2: BBG | O2: 1
A3: =D3&G3 -> 380823 | B3: =D3&F3 -> 380825 | C3: 2 | D3: 38082 | E3: 0 | F3: 5 | G3: 3 | H3: 2 | I3: 0 | J3: =VLOOKUP(F3,$M$2:$N$21,2,0) -> OKO | K3: ="@"&VLOOKUP(G3,$M$2:$N$21,2,0) -> @TEW | L3: =C3&","&MONTH(D3)&"/"&DAY(D3)&"/"&YEAR(D3)&","&E3&","&F3&","&G3&","&H3&","&I3 -> 2,4/5/2004,0,5,3,2,0 | M3: 7 | N3: BAR | O3: 1
A4: =D4&G4 -> 380827 | B4: =D4&F4 -> 3808224 | C4: 3 | D4: 38082 | E4: 0 | F4: 24 | G4: 7 | H4: 2 | I4: 0 | J4: =VLOOKUP(F4,$M$2:$N$21,2,0) -> PHI | K4: ="@"&VLOOKUP(G4,$M$2:$N$21,2,0) -> @BAR | L4: =C4&","&MONTH(D4)&"/"&DAY(D4)&"/"&YEAR(D4)&","&E4&","&F4&","&G4&","&H4&","&I4 -> 3,4/5/2004,0,24,7,2,0 | M4: 8 | N4: CTW | O4: 1
A5: =D5&G5 -> 380828 | B5: =D5&F5 -> 3808221 | C5: 4 | D5: 38082 | E5: 0 | F5: 21 | G5: 8 | H5: 2 | I5: 0 | J5: =VLOOKUP(F5,$M$2:$N$21,2,0) -> NYD | K5: ="@"&VLOOKUP(G5,$M$2:$N$21,2,0) -> @CTW | L5: =C5&","&MONTH(D5)&"/"&DAY(D5)&"/"&YEAR(D5)&","&E5&","&F5&","&G5&","&H5&","&I5 -> 4,4/5/2004,0,21,8,2,0 | M5: 9 | N5: CIN | O5: 1
A6: =D6&G6 -> 380829 | B6: =D6&F6 -> 3808211 | C6: 5 | D6: 38082 | E6: 0 | F6: 11 | G6: 9 | H6: 2 | I6: 0 | J6: =VLOOKUP(F6,$M$2:$N$21,2,0) -> HAR | K6: ="@"&VLOOKUP(G6,$M$2:$N$21,2,0) -> @CIN | L6: =C6&","&MONTH(D6)&"/"&DAY(D6)&"/"&YEAR(D6)&","&E6&","&F6&","&G6&","&H6&","&I6 -> 5,4/5/2004,0,11,9,2,0 | M6: 17 | N6: GAR | O6: 1
A7: =D7&G7 -> 3808210 | B7: =D7&F7 -> 3808216 | C7: 6 | D7: 38082 | E7: 0 | F7: 16 | G7: 10 | H7: 2 | I7: 0 | J7: =VLOOKUP(F7,$M$2:$N$21,2,0) -> DIG | K7: ="@"&VLOOKUP(G7,$M$2:$N$21,2,0) -> @REN | L7: =C7&","&MONTH(D7)&"/"&DAY(D7)&"/"&YEAR(D7)&","&E7&","&F7&","&G7&","&H7&","&I7 -> 6,4/5/2004,0,16,10,2,0 | M7: 14 | N7: CEN | O7: 2
A8: =D8&G8 -> 3808213 | B8: =D8&F8 -> 3808222 | C8: 7 | D8: 38082 | E8: 0 | F8: 22 | G8: 13 | H8: 2 | I8: 0 | J8: =VLOOKUP(F8,$M$2:$N$21,2,0) -> CBB | K8: ="@"&VLOOKUP(G8,$M$2:$N$21,2,0) -> @BBG | L8: =C8&","&MONTH(D8)&"/"&DAY(D8)&"/"&YEAR(D8)&","&E8&","&F8&","&G8&","&H8&","&I8 -> 7,4/5/2004,0,22,13,2,0 | M8: 20 | N8: FDH | O8: 2
A9: =D9&G9 -> 3808214 | B9: =D9&F9 -> 3808212 | C9: 8 | D9: 38082 | E9: 0 | F9: 12 | G9: 14 | H9: 2 | I9: 0 | J9: =VLOOKUP(F9,$M$2:$N$21,2,0) -> RMO | K9: ="@"&VLOOKUP(G9,$M$2:$N$21,2,0) -> @CEN | L9: =C9&","&MONTH(D9)&"/"&DAY(D9)&"/"&YEAR(D9)&","&E9&","&F9&","&G9&","&H9&","&I9 -> 8,4/5/2004,0,12,14,2,0 | M9: 2 | N9: NEP | O9: 2
A10: =D10&G10 -> 3808217 | B10: =D10&F10 -> 3808223 | C10: 9 | D10: 38082 | E10: 0 | F10: 23 | G10: 17 | H10: 2 | I10: 0 | J10: =VLOOKUP(F10,$M$2:$N$21,2,0) -> BRK | K10: ="@"&VLOOKUP(G10,$M$2:$N$21,2,0) -> @GAR | L10: =C10&","&MONTH(D10)&"/"&DAY(D10)&"/"&YEAR(D10)&","&E10&","&F10&","&G10&","&H10&","&I10 -> 9,4/5/2004,0,23,17,2,0 | M10: 10 | N10: REN | O10: 2
A11: =D11&G11 -> 3808220 | B11: =D11&F11 -> 380821 | C11: 10 | D11: 38082 | E11: 0 | F11: 1 | G11: 20 | H11: 2 | I11: 0 | J11: =VLOOKUP(F11,$M$2:$N$21,2,0) -> FFR | K11: ="@"&VLOOKUP(G11,$M$2:$N$21,2,0) -> @FDH | L11: =C11&","&MONTH(D11)&"/"&DAY(D11)&"/"&YEAR(D11)&","&E11&","&F11&","&G11&","&H11&","&I11 -> 10,4/5/2004,0,1,20,2,0 | M11: 3 | N11: TEW | O11: 2
A12: =D12&G12 -> 380832 | B12: =D12&F12 -> 380834 | C12: 11 | D12: 38083 | E12: 0 | F12: 4 | G12: 2 | H12: 2 | I12: 0 | J12: =VLOOKUP(F12,$M$2:$N$21,2,0) -> NNN | K12: ="@"&VLOOKUP(G12,$M$2:$N$21,2,0) -> @NEP | L12: =C12&","&MONTH(D12)&"/"&DAY(D12)&"/"&YEAR(D12)&","&E12&","&F12&","&G12&","&H12&","&I12 -> 11,4/6/2004,0,4,2,2,0 | M12: 16 | N12: DIG | O12: 3
A13: =D13&G13 -> 380833 | B13: =D13&F13 -> 380835 | C13: 12 | D13: 38083 | E13: 0 | F13: 5 | G13: 3 | H13: 2 | I13: 0 | J13: =VLOOKUP(F13,$M$2:$N$21,2,0) -> OKO | K13: ="@"&VLOOKUP(G13,$M$2:$N$21,2,0) -> @TEW | L13: =C13&","&MONTH(D13)&"/"&DAY(D13)&"/"&YEAR(D13)&","&E13&","&F13&","&G13&","&H13&","&I13 -> 12,4/6/2004,0,5,3,2,0 | M13: 1 | N13: FFR | O13: 3
... A21: =D21&G21 -> 3808320 | B21: =D21&F21 -> 380831 | C21: 20 | D21: 38083 | E21: 0 | F21: 1 | G21: 20 | H21: 2 | I21: 0 | J21: =VLOOKUP(F21,$M$2:$N$21,2,0) -> FFR | K21: ="@"&VLOOKUP(G21,$M$2:$N$21,2,0) -> @FDH | L21: =C21&","&MONTH(D21)&"/"&DAY(D21)&"/"&YEAR(D21)&","&E21&","&F21&","&G21&","&H21&","&I21 -> 20,4/6/2004,0,1,20,2,0 | M21: 24 | N21: PHI | O21: 4
A22: =D22&G22 -> 380842 | B22: =D22&F22 -> 380844 | C22: 21 | D22: 38084 | E22: 0 | F22: 4 | G22: 2 | H22: 2 | I22: 0 | J22: =VLOOKUP(F22,$M$2:$N$21,2,0) -> NNN | K22: ="@"&VLOOKUP(G22,$M$2:$N$21,2,0) -> @NEP | L22: =C22&","&MONTH(D22)&"/"&DAY(D22)&"/"&YEAR(D22)&","&E22&","&F22&","&G22&","&H22&","&I22 -> 21,4/7/2004,0,4,2,2,0
A23: =D23&G23 -> 380843 | B23: =D23&F23 -> 380845 | C23: 22 | D23: 38084 | E23: 0 | F23: 5 | G23: 3 | H23: 2 | I23: 0 | J23: =VLOOKUP(F23,$M$2:$N$21,2,0) -> OKO | K23: ="@"&VLOOKUP(G23,$M$2:$N$21,2,0) -> @TEW | L23: =C23&","&MONTH(D23)&"/"&DAY(D23)&"/"&YEAR(D23)&","&E23&","&F23&","&G23&","&H23&","&I23 -> 22,4/7/2004,0,5,3,2,0
A24: =D24&G24 -> 380847 | B24: =D24&F24 -> 3808424 | C24: 23 | D24: 38084 | E24: 0 | F24: 24 | G24: 7 | H24: 2 | I24: 0 | J24: =VLOOKUP(F24,$M$2:$N$21,2,0) -> PHI | K24: ="@"&VLOOKUP(G24,$M$2:$N$21,2,0) -> @BAR | L24: =C24&","&MONTH(D24)&"/"&DAY(D24)&"/"&YEAR(D24)&","&E24&","&F24&","&G24&","&H24&","&I24 -> 23,4/7/2004,0,24,7,2,0
A25: =D25&G25 -> 380848 | B25: =D25&F25 -> 3808421 | C25: 24 | D25: 38084 | E25: 0 | F25: 21 | G25: 8 | H25: 2 | I25: 0 | J25: =VLOOKUP(F25,$M$2:$N$21,2,0) -> NYD | K25: ="@"&VLOOKUP(G25,$M$2:$N$21,2,0) -> @CTW | L25: =C25&","&MONTH(D25)&"/"&DAY(D25)&"/"&YEAR(D25)&","&E25&","&F25&","&G25&","&H25&","&I25 -> 24,4/7/2004,0,21,8,2,0
A26: =D26&G26 -> 380849 | B26: =D26&F26 -> 3808411 | C26: 25 | D26: 38084 | E26: 0 | F26: 11 | G26: 9 | H26: 2 | I26: 0 | J26: =VLOOKUP(F26,$M$2:$N$21,2,0) -> HAR | K26: ="@"&VLOOKUP(G26,$M$2:$N$21,2,0) -> @CIN | L26: =C26&","&MONTH(D26)&"/"&DAY(D26)&"/"&YEAR(D26)&","&E26&","&F26&","&G26&","&H26&","&I26 -> 25,4/7/2004,0,11,9,2,0
A27: =D27&G27 -> 3808410 | B27: =D27&F27 -> 3808416 | C27: 26 | D27: 38084 | E27: 0 | F27: 16 | G27: 10 | H27: 2 | I27: 0 | J27: =VLOOKUP(F27,$M$2:$N$21,2,0) -> DIG | K27: ="@"&VLOOKUP(G27,$M$2:$N$21,2,0) -> @REN | L27: =C27&","&MONTH(D27)&"/"&DAY(D27)&"/"&YEAR(D27)&","&E27&","&F27&","&G27&","&H27&","&I27 -> 26,4/7/2004,0,16,10,2,0
A28: =D28&G28 -> 3808413 | B28: =D28&F28 -> 3808422 | C28: 27 | D28: 38084 | E28: 0 | F28: 22 | G28: 13 | H28: 2 | I28: 0 | J28: =VLOOKUP(F28,$M$2:$N$21,2,0) -> CBB | K28: ="@"&VLOOKUP(G28,$M$2:$N$21,2,0) -> @BBG | L28: =C28&","&MONTH(D28)&"/"&DAY(D28)&"/"&YEAR(D28)&","&E28&","&F28&","&G28&","&H28&","&I28 -> 27,4/7/2004,0,22,13,2,0
A29: =D29&G29 -> 3808414 | B29: =D29&F29 -> 3808412 | C29: 28 | D29: 38084 | E29: 0 | F29: 12 | G29: 14 | H29: 2 | I29: 0 | J29: =VLOOKUP(F29,$M$2:$N$21,2,0) -> RMO | K29: ="@"&VLOOKUP(G29,$M$2:$N$21,2,0) -> @CEN | L29: =C29&","&MONTH(D29)&"/"&DAY(D29)&"/"&YEAR(D29)&","&E29&","&F29&","&G29&","&H29&","&I29 -> 28,4/7/2004,0,12,14,2,0
A30: =D30&G30 -> 3808417 | B30: =D30&F30 -> 3808423 | C30: 29 | D30: 38084 | E30: 0 | F30: 23 | G30: 17 | H30: 2 | I30: 0 | J30: =VLOOKUP(F30,$M$2:$N$21,2,0) -> BRK | K30: ="@"&VLOOKUP(G30,$M$2:$N$21,2,0) -> @GAR | L30: =C30&","&MONTH(D30)&"/"&DAY(D30)&"/"&YEAR(D30)&","&E30&","&F30&","&G30&","&H30&","&I30 -> 29,4/7/2004,0,23,17,2,0
A31: =D31&G31 -> 3808420 | B31: =D31&F31 -> 380841 | C31: 30 | D31: 38084 | E31: 0 | F31: 1 | G31: 20 | H31: 2 | I31: 0 | J31: =VLOOKUP(F31,$M$2:$N$21,2,0) -> FFR | K31: ="@"&VLOOKUP(G31,$M$2:$N$21,2,0) -> @FDH | L31: =C31&","&MONTH(D31)&"/"&DAY(D31)&"/"&YEAR(D31)&","&E31&","&F31&","&G31&","&H31&","&I31 -> 30,4/7/2004,0,1,20,2,0
A32: =D32&G32 -> 380852 | B32: =D32&F32 -> 380854 | C32: 31 | D32: 38085 | E32: 0 | F32: 4 | G32: 2 | H32: 2 | I32: 0 | J32: =VLOOKUP(F32,$M$2:$N$21,2,0) -> NNN | K32: ="@"&VLOOKUP(G32,$M$2:$N$21,2,0) -> @NEP | L32: =C32&","&MONTH(D32)&"/"&DAY(D32)&"/"&YEAR(D32)&","&E32&","&F32&","&G32&","&H32&","&I32 -> 31,4/8/2004,0,4,2,2,0 | M32: 25
A33: =D33&G33 -> 380853 | B33: =D33&F33 -> 380855 | C33: 32 | D33: 38085 | E33: 0 | F33: 5 | G33: 3 | H33: 2 | I33: 0 | J33: =VLOOKUP(F33,$M$2:$N$21,2,0) -> OKO | K33: ="@"&VLOOKUP(G33,$M$2:$N$21,2,0) -> @TEW | L33: =C33&","&MONTH(D33)&"/"&DAY(D33)&"/"&YEAR(D33)&","&E33&","&F33&","&G33&","&H33&","&I33 -> 32,4/8/2004,0,5,3,2,0
A34: =D34&G34 -> 380857 | B34: =D34&F34 -> 3808524 | C34: 33 | D34: 38085 | E34: 0 | F34: 24 | G34: 7 | H34: 2 | I34: 0 | J34: =VLOOKUP(F34,$M$2:$N$21,2,0) -> PHI | K34: ="@"&VLOOKUP(G34,$M$2:$N$21,2,0) -> @BAR | L34: =C34&","&MONTH(D34)&"/"&DAY(D34)&"/"&YEAR(D34)&","&E34&","&F34&","&G34&","&H34&","&I34 -> 33,4/8/2004,0,24,7,2,0
A35: =D35&G35 -> 380858 | B35: =D35&F35 -> 3808521 | C35: 34 | D35: 38085 | E35: 0 | F35: 21 | G35: 8 | H35: 2 | I35: 0 | J35: =VLOOKUP(F35,$M$2:$N$21,2,0) -> NYD | K35: ="@"&VLOOKUP(G35,$M$2:$N$21,2,0) -> @CTW | L35: =C35&","&MONTH(D35)&"/"&DAY(D35)&"/"&YEAR(D35)&","&E35&","&F35&","&G35&","&H35&","&I35 -> 34,4/8/2004,0,21,8,2,0
A36: =D36&G36 -> 380859 | B36: =D36&F36 -> 3808511 | C36: 35 | D36: 38085 | E36: 0 | F36: 11 | G36: 9 | H36: 2 | I36: 0 | J36: =VLOOKUP(F36,$M$2:$N$21,2,0) -> HAR | K36: ="@"&VLOOKUP(G36,$M$2:$N$21,2,0) -> @CIN | L36: =C36&","&MONTH(D36)&"/"&DAY(D36)&"/"&YEAR(D36)&","&E36&","&F36&","&G36&","&H36&","&I36 -> 35,4/8/2004,0,11,9,2,0
A37: =D37&G37 -> 3808510 | B37: =D37&F37 -> 3808516 | C37: 36 | D37: 38085 | E37: 0 | F37: 16 | G37: 10 | H37: 2 | I37: 0 | J37: =VLOOKUP(F37,$M$2:$N$21,2,0) -> DIG | K37: ="@"&VLOOKUP(G37,$M$2:$N$21,2,0) -> @REN | L37: =C37&","&MONTH(D37)&"/"&DAY(D37)&"/"&YEAR(D37)&","&E37&","&F37&","&G37&","&H37&","&I37 -> 36,4/8/2004,0,16,10,2,0
A38: =D38&G38 -> 3808513 | B38: =D38&F38 -> 3808522 | C38: 37 | D38: 38085 | E38: 0 | F38: 22 | G38: 13 | H38: 2 | I38: 0 | J38: =VLOOKUP(F38,$M$2:$N$21,2,0) -> CBB | K38: ="@"&VLOOKUP(G38,$M$2:$N$21,2,0) -> @BBG | L38: =C38&","&MONTH(D38)&"/"&DAY(D38)&"/"&YEAR(D38)&","&E38&","&F38&","&G38&","&H38&","&I38 -> 37,4/8/2004,0,22,13,2,0
A39: =D39&G39 -> 3808514 | B39: =D39&F39 -> 3808512 | C39: 38 | D39: 38085 | E39: 0 | F39: 12 | G39: 14 | H39: 2 | I39: 0 | J39: =VLOOKUP(F39,$M$2:$N$21,2,0) -> RMO | K39: ="@"&VLOOKUP(G39,$M$2:$N$21,2,0) -> @CEN | L39: =C39&","&MONTH(D39)&"/"&DAY(D39)&"/"&YEAR(D39)&","&E39&","&F39&","&G39&","&H39&","&I39 -> 38,4/8/2004,0,12,14,2,0
A40: =D40&G40 -> 3808517 | B40: =D40&F40 -> 3808523 | C40: 39 | D40: 38085 | E40: 0 | F40: 23 | G40: 17 | H40: 2 | I40: 0 | J40: =VLOOKUP(F40,$M$2:$N$21,2,0) -> BRK | K40: ="@"&VLOOKUP(G40,$M$2:$N$21,2,0) -> @GAR | L40: =C40&","&MONTH(D40)&"/"&DAY(D40)&"/"&YEAR(D40)&","&E40&","&F40&","&G40&","&H40&","&I40 -> 39,4/8/2004,0,23,17,2,0
A41: =D41&G41 -> 3808520 | B41: =D41&F41 -> 380851 | C41: 40 | D41: 38085 | E41: 0 | F41: 1 | G41: 20 | H41: 2 | I41: 0 | J41: =VLOOKUP(F41,$M$2:$N$21,2,0) -> FFR | K41: ="@"&VLOOKUP(G41,$M$2:$N$21,2,0) -> @FDH | L41: =C41&","&MONTH(D41)&"/"&DAY(D41)&"/"&YEAR(D41)&","&E41&","&F41&","&G41&","&H41&","&I41 -> 40,4/8/2004,0,1,20,2,0
A42: =D42&G42 -> 3808622 | B42: =D42&F42 -> 3808624 | C42: 41 | D42: 38086 | E42: 0 | F42: 24 | G42: 22 | H42: 2 | I42: 0 | J42: =VLOOKUP(F42,$M$2:$N$21,2,0) -> PHI | K42: ="@"&VLOOKUP(G42,$M$2:$N$21,2,0) -> @CBB | L42: =C42&","&MONTH(D42)&"/"&DAY(D42)&"/"&YEAR(D42)&","&E42&","&F42&","&G42&","&H42&","&I42 -> 41,4/9/2004,0,24,22,2,0
A43: =D43&G43 -> 380863 | B43: =D43&F43 -> 3808613 | C43: 42 | D43: 38086 | E43: 0 | F43: 13 | G43: 3 | H43: 2 | I43: 0 | J43: =VLOOKUP(F43,$M$2:$N$21,2,0) -> BBG | K43: ="@"&VLOOKUP(G43,$M$2:$N$21,2,0) -> @TEW | L43: =C43&","&MONTH(D43)&"/"&DAY(D43)&"/"&YEAR(D43)&","&E43&","&F43&","&G43&","&H43&","&I43 -> 42,4/9/2004,0,13,3,2,0
A44: =D44&G44 -> 380865 | B44: =D44&F44 -> 3808612 | C44: 43 | D44: 38086 | E44: 0 | F44: 12 | G44: 5 | H44: 2 | I44: 0 | J44: =VLOOKUP(F44,$M$2:$N$21,2,0) -> RMO | K44: ="@"&VLOOKUP(G44,$M$2:$N$21,2,0) -> @OKO | L44: =C44&","&MONTH(D44)&"/"&DAY(D44)&"/"&YEAR(D44)&","&E44&","&F44&","&G44&","&H44&","&I44 -> 43,4/9/2004,0,12,5,2,0
... A439: =D439&G439 -> 381298 | B439: =D439&F439 -> 3812920 | C439: 438 | D439: 38129 | E439: 0 | F439: 20 | G439: 8 | H439: 2 | I439: 0 | J439: =VLOOKUP(F439,$M$2:$N$21,2,0) -> FDH | K439: ="@"&VLOOKUP(G439,$M$2:$N$21,2,0) -> @CTW | L439: =C439&","&MONTH(D439)&"/"&DAY(D439)&"/"&YEAR(D439)&","&E439&","&F439&","&G439&","&H439&","&I439 -> 438,5/22/2004,0,20,8,2,0
A440: =D440&G440 -> 381299 | B440: =D440&F440 -> 3812914 | C440: 439 | D440: 38129 | E440: 0 | F440: 14 | G440: 9 | H440: 2 | I440: 0 | J440: =VLOOKUP(F440,$M$2:$N$21,2,0) -> CEN | K440: ="@"&VLOOKUP(G440,$M$2:$N$21,2,0) -> @CIN | L440: =C440&","&MONTH(D440)&"/"&DAY(D440)&"/"&YEAR(D440)&","&E440&","&F440&","&G440&","&H440&","&I440 -> 439,5/22/2004,0,14,9,2,0 | N440: 1
A441: =D441&G441 -> 3812912 | B441: =D441&F441 -> 3812923 | C441: 440 | D441: 38129 | E441: 0 | F441: 23 | G441: 12 | H441: 2 | I441: 0 | J441: =VLOOKUP(F441,$M$2:$N$21,2,0) -> BRK | K441: ="@"&VLOOKUP(G441,$M$2:$N$21,2,0) -> @RMO | L441: =C441&","&MONTH(D441)&"/"&DAY(D441)&"/"&YEAR(D441)&","&E441&","&F441&","&G441&","&H441&","&I441 -> 440,5/22/2004,0,23,12,2,0
...

Sheet colorpalette
D1: RGB Color Palette
B2: Bright | F2: Dull
D3: Hex
A4: 1 | B4: 21 | C4: 10 | E4: 0e | F4: 1a | G4: 13
A5: 24 | B5: 79 | C5: 35 | E5: 3f | F5: 60 | G5: 45
A6: 55 | B6: b4 | C6: 3a | E6: 6a | F6: 90 | G6: 5f
A7: e1 | B7: ff | C7: dd | E7: c7 | F7: db | G7: c6
A8: 95 | B8: cd | C8: 43 | E8: 8e | F8: a4 | G8: 6d
D9: Decimal
A10: =HEX2DEC(A4) -> 1 | B10: =HEX2DEC(B4) -> 33 | C10: =HEX2DEC(C4) -> 16 | E10: =HEX2DEC(E4) -> 14 | F10: =HEX2DEC(F4) -> 26 | G10: =HEX2DEC(G4) -> 19
A11: =HEX2DEC(A5) -> 36 | B11: =HEX2DEC(B5) -> 121 | C11: =HEX2DEC(C5) -> 53 | E11: =HEX2DEC(E5) -> 63 | F11: =HEX2DEC(F5) -> 96 | G11: =HEX2DEC(G5) -> 69
A12: =HEX2DEC(A6) -> 85 | B12: =HEX2DEC(B6) -> 180 | C12: =HEX2DEC(C6) -> 58 | E12: =HEX2DEC(E6) -> 106 | F12: =HEX2DEC(F6) -> 144 | G12: =HEX2DEC(G6) -> 95
A13: =HEX2DEC(A7) -> 225 | B13: =HEX2DEC(B7) -> 255 | C13: =HEX2DEC(C7) -> 221 | E13: =HEX2DEC(E7) -> 199 | F13: =HEX2DEC(F7) -> 219 | G13: =HEX2DEC(G7) -> 198
A14: =HEX2DEC(A8) -> 149 | B14: =HEX2DEC(B8) -> 205 | C14: =HEX2DEC(C8) -> 67 | E14: =HEX2DEC(E8) -> 142 | F14: =HEX2DEC(F8) -> 164 | G14: =HEX2DEC(G8) -> 109
