Workbook

Sheet 1999 Draft
C1: Pick | D1: Team | F1: <-- Enter team code to highlight that team's picks!
A2: Pick | B2: Rnd | C2: in Rnd | D2: Prev | E2: Curr | F2: Player Selected | G2: Comment | H2: For pasting into email
A3: 1 | B3: 1 | C3: 1 | E3: OKO | F3: Lance Berkman, lf | H3: =IF(B3<10," ","")&B3&"."&IF(C3<10,"0","")&C3&" "&E3&" "&VLOOKUP(E3,Teams!$A$2:$C$21,2,0)&REPT(" ",Teams!C$1+1-VLOOKUP(E3,Teams!$A$2:$C$21,3,0))&"- "&F3&IF(ISBLANK(D3),""," (from "&D3&")") -> 1.01 OKO Smith - Lance Berkman, lf
A4: 2 | B4: 1 | C4: 2 | E4: BBG | F4: Tim Hudson, rsp | H4: =IF(B4<10," ","")&B4&"."&IF(C4<10,"0","")&C4&" "&E4&" "&VLOOKUP(E4,Teams!$A$2:$C$21,2,0)&REPT(" ",Teams!C$1+1-VLOOKUP(E4,Teams!$A$2:$C$21,3,0))&"- "&F4&IF(ISBLANK(D4),""," (from "&D4&")") -> 1.02 BBG Canter - Tim Hudson, rsp
A5: 3 | B5: 1 | C5: 3 | E5: ZZY | F5: Alfonso Soriano, ss | H5: =IF(B5<10," ","")&B5&"."&IF(C5<10,"0","")&C5&" "&E5&" "&VLOOKUP(E5,Teams!$A$2:$C$21,2,0)&REPT(" ",Teams!C$1+1-VLOOKUP(E5,Teams!$A$2:$C$21,3,0))&"- "&F5&IF(ISBLANK(D5),""," (from "&D5&")") -> 1.03 ZZY Poole - Alfonso Soriano, ss
A6: 4 | B6: 1 | C6: 4 | D6: FFR | E6: RMO | F6: Freddy Garcia, rsp | G6: for 1.09, RMO00-02 | H6: =IF(B6<10," ","")&B6&"."&IF(C6<10,"0","")&C6&" "&E6&" "&VLOOKUP(E6,Teams!$A$2:$C$21,2,0)&REPT(" ",Teams!C$1+1-VLOOKUP(E6,Teams!$A$2:$C$21,3,0))&"- "&F6&IF(ISBLANK(D6),""," (from "&D6&")") -> 1.04 RMO Haverty/Mojo - Freddy Garcia, rsp (from FFR)
A7: 5 | B7: 1 | C7: 5 | E7: GAR | F7: A.J. Burnett, rsp | H7: =IF(B7<10," ","")&B7&"."&IF(C7<10,"0","")&C7&" "&E7&" "&VLOOKUP(E7,Teams!$A$2:$C$21,2,0)&REPT(" ",Teams!C$1+1-VLOOKUP(E7,Teams!$A$2:$C$21,3,0))&"- "&F7&IF(ISBLANK(D7),""," (from "&D7&")") -> 1.05 GAR Bernstein - A.J. Burnett, rsp
A8: 6 | B8: 1 | C8: 6 | E8: FDH | F8: Joe Mays, rmr | H8: =IF(B8<10," ","")&B8&"."&IF(C8<10,"0","")&C8&" "&E8&" "&VLOOKUP(E8,Teams!$A$2:$C$21,2,0)&REPT(" ",Teams!C$1+1-VLOOKUP(E8,Teams!$A$2:$C$21,3,0))&"- "&F8&IF(ISBLANK(D8),""," (from "&D8&")") -> 1.06 FDH English - Joe Mays, rmr
A9: 7 | B9: 1 | C9: 7 | E9: FHK | F9: Joe Nathan, rsp | H9: =IF(B9<10," ","")&B9&"."&IF(C9<10,"0","")&C9&" "&E9&" "&VLOOKUP(E9,Teams!$A$2:$C$21,2,0)&REPT(" ",Teams!C$1+1-VLOOKUP(E9,Teams!$A$2:$C$21,3,0))&"- "&F9&IF(ISBLANK(D9),""," (from "&D9&")") -> 1.07 FHK Chernow - Joe Nathan, rsp
A10: 8 | B10: 1 | C10: 8 | E10: FER | F10: Steve Finley, cf | H10: =IF(B10<10," ","")&B10&"."&IF(C10<10,"0","")&C10&" "&E10&" "&VLOOKUP(E10,Teams!$A$2:$C$21,2,0)&REPT(" ",Teams!C$1+1-VLOOKUP(E10,Teams!$A$2:$C$21,3,0))&"- "&F10&IF(ISBLANK(D10),""," (from "&D10&")") -> 1.08 FER Olkin - Steve Finley, cf
A11: 9 | B11: 1 | C11: 9 | D11: MCL,RMO | E11: FFR | F11: Ted Lilly, lsp | G11: from MCL for Mike Mussina, Mike Redmond, RMO99-11, from RMO for 1.04 FFR00-03 | H11: =IF(B11<10," ","")&B11&"."&IF(C11<10,"0","")&C11&" "&E11&" "&VLOOKUP(E11,Teams!$A$2:$C$21,2,0)&REPT(" ",Teams!C$1+1-VLOOKUP(E11,Teams!$A$2:$C$21,3,0))&"- "&F11&IF(ISBLANK(D11),""," (from "&D11&")") -> 1.09 FFR Scott - Ted Lilly, lsp (from MCL,RMO)
A12: 10 | B12: 1 | C12: 10 | D12: RMO | E12: FLL | F12: Carlos Lee, lf | H12: =IF(B12<10," ","")&B12&"."&IF(C12<10,"0","")&C12&" "&E12&" "&VLOOKUP(E12,Teams!$A$2:$C$21,2,0)&REPT(" ",Teams!C$1+1-VLOOKUP(E12,Teams!$A$2:$C$21,3,0))&"- "&F12&IF(ISBLANK(D12),""," (from "&D12&")") -> 1.10 FLL Carroll/Kleine - Carlos Lee, lf (from RMO)
A13: 11 | B13: 1 | C13: 11 | E13: CIN | F13: Vernon Wells, cf | H13: =IF(B13<10," ","")&B13&"."&IF(C13<10,"0","")&C13&" "&E13&" "&VLOOKUP(E13,Teams!$A$2:$C$21,2,0)&REPT(" ",Teams!C$1+1-VLOOKUP(E13,Teams!$A$2:$C$21,3,0))&"- "&F13&IF(ISBLANK(D13),""," (from "&D13&")") -> 1.11 CIN CMiller - Vernon Wells, cf
A14: 12 | B14: 1 | C14: 12 | D14: CTW | E14: FFR | F14: Randy Wolf, lsp | H14: =IF(B14<10," ","")&B14&"."&IF(C14<10,"0","")&C14&" "&E14&" "&VLOOKUP(E14,Teams!$A$2:$C$21,2,0)&REPT(" ",Teams!C$1+1-VLOOKUP(E14,Teams!$A$2:$C$21,3,0))&"- "&F14&IF(ISBLANK(D14),""," (from "&D14&")") -> 1.12 FFR Scott - Randy Wolf, lsp (from CTW)
A15: 13 | B15: 1 | C15: 13 | E15: FLL | F15: Francisco Cordero, rmr | H15: =IF(B15<10," ","")&B15&"."&IF(C15<10,"0","")&C15&" "&E15&" "&VLOOKUP(E15,Teams!$A$2:$C$21,2,0)&REPT(" ",Teams!C$1+1-VLOOKUP(E15,Teams!$A$2:$C$21,3,0))&"- "&F15&IF(ISBLANK(D15),""," (from "&D15&")") -> 1.13 FLL Carroll/Kleine - Francisco Cordero, rmr
A16: 14 | B16: 1 | C16: 14 | D16: BAR | E16: CIN | F16: Eric Gagne, rsp | H16: =IF(B16<10," ","")&B16&"."&IF(C16<10,"0","")&C16&" "&E16&" "&VLOOKUP(E16,Teams!$A$2:$C$21,2,0)&REPT(" ",Teams!C$1+1-VLOOKUP(E16,Teams!$A$2:$C$21,3,0))&"- "&F16&IF(ISBLANK(D16),""," (from "&D16&")") -> 1.14 CIN CMiller - Eric Gagne, rsp (from BAR)
A17: 15 | B17: 1 | C17: 15 | D17: CEN,CIN | E17: OKO | F17: Melvin Mora, 3b | H17: =IF(B17<10," ","")&B17&"."&IF(C17<10,"0","")&C17&" "&E17&" "&VLOOKUP(E17,Teams!$A$2:$C$21,2,0)&REPT(" ",Teams!C$1+1-VLOOKUP(E17,Teams!$A$2:$C$21,3,0))&"- "&F17&IF(ISBLANK(D17),""," (from "&D17&")") -> 1.15 OKO Smith - Melvin Mora, 3b (from CEN,CIN)
A18: 16 | B18: 1 | C18: 16 | E18: TAR | F18: Ramon Hernandez, c | H18: =IF(B18<10," ","")&B18&"."&IF(C18<10,"0","")&C18&" "&E18&" "&VLOOKUP(E18,Teams!$A$2:$C$21,2,0)&REPT(" ",Teams!C$1+1-VLOOKUP(E18,Teams!$A$2:$C$21,3,0))&"- "&F18&IF(ISBLANK(D18),""," (from "&D18&")") -> 1.16 TAR Lingo - Ramon Hernandez, c
A19: 17 | B19: 1 | C19: 17 | D19: EVN,FFR | E19: OKO | F19: Byung-Hyun Kim, rmr | G19: with FFR00-02 for 2.04, 2.05, 9.07 | H19: =IF(B19<10," ","")&B19&"."&IF(C19<10,"0","")&C19&" "&E19&" "&VLOOKUP(E19,Teams!$A$2:$C$21,2,0)&REPT(" ",Teams!C$1+1-VLOOKUP(E19,Teams!$A$2:$C$21,3,0))&"- "&F19&IF(ISBLANK(D19),""," (from "&D19&")") -> 1.17 OKO Smith - Byung-Hyun Kim, rmr (from EVN,FFR)
A20: 18 | B20: 1 | C20: 18 | D20: TEW | E20: RMO | F20: Billy Koch, rmr | G20: from TEW for RMO00-01 | H20: =IF(B20<10," ","")&B20&"."&IF(C20<10,"0","")&C20&" "&E20&" "&VLOOKUP(E20,Teams!$A$2:$C$21,2,0)&REPT(" ",Teams!C$1+1-VLOOKUP(E20,Teams!$A$2:$C$21,3,0))&"- "&F20&IF(ISBLANK(D20),""," (from "&D20&")") -> 1.18 RMO Haverty/Mojo - Billy Koch, rmr (from TEW)
A21: 19 | B21: 1 | C21: 19 | D21: DLM,FFR | E21: CTW | F21: Esteban Loaiza, rsp | G21: from FFR for FFR2.01 and CTW00-04 | H21: =IF(B21<10," ","")&B21&"."&IF(C21<10,"0","")&C21&" "&E21&" "&VLOOKUP(E21,Teams!$A$2:$C$21,2,0)&REPT(" ",Teams!C$1+1-VLOOKUP(E21,Teams!$A$2:$C$21,3,0))&"- "&F21&IF(ISBLANK(D21),""," (from "&D21&")") -> 1.19 CTW RMiller - Esteban Loaiza, rsp (from DLM,FFR)
A22: 20 | B22: 1 | C22: 20 | D22: NEP | E22: RMO | F22: Scott Williamson, rcl | G22: from NEP for RMO 3.09, FFR 00-3, RMO 00-5 | H22: =IF(B22<10," ","")&B22&"."&IF(C22<10,"0","")&C22&" "&E22&" "&VLOOKUP(E22,Teams!$A$2:$C$21,2,0)&REPT(" ",Teams!C$1+1-VLOOKUP(E22,Teams!$A$2:$C$21,3,0))&"- "&F22&IF(ISBLANK(D22),""," (from "&D22&")") -> 1.20 RMO Haverty/Mojo - Scott Williamson, rcl (from NEP)
A23: 21 | B23: 2 | C23: 1 | D23: FFR,CTW | E23: FFR | F23: Octavio Dotel, rsp | G23: from CTW w/CTW00-04 for DLM1.19 | H23: =IF(B23<10," ","")&B23&"."&IF(C23<10,"0","")&C23&" "&E23&" "&VLOOKUP(E23,Teams!$A$2:$C$21,2,0)&REPT(" ",Teams!C$1+1-VLOOKUP(E23,Teams!$A$2:$C$21,3,0))&"- "&F23&IF(ISBLANK(D23),""," (from "&D23&")") -> 2.01 FFR Scott - Octavio Dotel, rsp (from FFR,CTW)
A24: 22 | B24: 2 | C24: 2 | E24: GAR | F24: Wade Miller, rmr | H24: =IF(B24<10," ","")&B24&"."&IF(C24<10,"0","")&C24&" "&E24&" "&VLOOKUP(E24,Teams!$A$2:$C$21,2,0)&REPT(" ",Teams!C$1+1-VLOOKUP(E24,Teams!$A$2:$C$21,3,0))&"- "&F24&IF(ISBLANK(D24),""," (from "&D24&")") -> 2.02 GAR Bernstein - Wade Miller, rmr
A25: 23 | B25: 2 | C25: 3 | D25: BBG | E25: CIN | F25: B.J. Ryan, lmr | G25: from BBG w/BBG00-05 for Ray Lankford | H25: =IF(B25<10," ","")&B25&"."&IF(C25<10,"0","")&C25&" "&E25&" "&VLOOKUP(E25,Teams!$A$2:$C$21,2,0)&REPT(" ",Teams!C$1+1-VLOOKUP(E25,Teams!$A$2:$C$21,3,0))&"- "&F25&IF(ISBLANK(D25),""," (from "&D25&")") -> 2.03 CIN CMiller - B.J. Ryan, lmr (from BBG)
A26: 24 | B26: 2 | C26: 4 | D26: FDH,OKO | E26: FFR | F26: Adam Kennedy, 2b | G26: w/2.05,9.07 for 1.17, FFR00-02 | H26: =IF(B26<10," ","")&B26&"."&IF(C26<10,"0","")&C26&" "&E26&" "&VLOOKUP(E26,Teams!$A$2:$C$21,2,0)&REPT(" ",Teams!C$1+1-VLOOKUP(E26,Teams!$A$2:$C$21,3,0))&"- "&F26&IF(ISBLANK(D26),""," (from "&D26&")") -> 2.04 FFR Scott - Adam Kennedy, 2b (from FDH,OKO)
A27: 25 | B27: 2 | C27: 5 | D27: OKO | E27: FFR | F27: Kyle Farnsworth, rsp | G27: w/2.04,9.07 for 1.17, FFR00-02 | H27: =IF(B27<10," ","")&B27&"."&IF(C27<10,"0","")&C27&" "&E27&" "&VLOOKUP(E27,Teams!$A$2:$C$21,2,0)&REPT(" ",Teams!C$1+1-VLOOKUP(E27,Teams!$A$2:$C$21,3,0))&"- "&F27&IF(ISBLANK(D27),""," (from "&D27&")") -> 2.05 FFR Scott - Kyle Farnsworth, rsp (from OKO)
A28: 26 | B28: 2 | C28: 6 | E28: FER | F28: Kris Benson, rsp | H28: =IF(B28<10," ","")&B28&"."&IF(C28<10,"0","")&C28&" "&E28&" "&VLOOKUP(E28,Teams!$A$2:$C$21,2,0)&REPT(" ",Teams!C$1+1-VLOOKUP(E28,Teams!$A$2:$C$21,3,0))&"- "&F28&IF(ISBLANK(D28),""," (from "&D28&")") -> 2.06 FER Olkin - Kris Benson, rsp
A29: 27 | B29: 2 | C29: 7 | E29: FHK | F29: Brian Anderson, lsp | H29: =IF(B29<10," ","")&B29&"."&IF(C29<10,"0","")&C29&" "&E29&" "&VLOOKUP(E29,Teams!$A$2:$C$21,2,0)&REPT(" ",Teams!C$1+1-VLOOKUP(E29,Teams!$A$2:$C$21,3,0))&"- "&F29&IF(ISBLANK(D29),""," (from "&D29&")") -> 2.07 FHK Chernow - Brian Anderson, lsp
A30: 28 | B30: 2 | C30: 8 | E30: MCL | F30: Jeff Zimmerman, rmr | H30: =IF(B30<10," ","")&B30&"."&IF(C30<10,"0","")&C30&" "&E30&" "&VLOOKUP(E30,Teams!$A$2:$C$21,2,0)&REPT(" ",Teams!C$1+1-VLOOKUP(E30,Teams!$A$2:$C$21,3,0))&"- "&F30&IF(ISBLANK(D30),""," (from "&D30&")") -> 2.08 MCL Manuel - Jeff Zimmerman, rmr
A31: 29 | B31: 2 | C31: 9 | D31: RMO | E31: EVN | F31: Kent Bottenfield, rsp | H31: =IF(B31<10," ","")&B31&"."&IF(C31<10,"0","")&C31&" "&E31&" "&VLOOKUP(E31,Teams!$A$2:$C$21,2,0)&REPT(" ",Teams!C$1+1-VLOOKUP(E31,Teams!$A$2:$C$21,3,0))&"- "&F31&IF(ISBLANK(D31),""," (from "&D31&")") -> 2.09 EVN Henninger - Kent Bottenfield, rsp (from RMO)
A32: 30 | B32: 2 | C32: 10 | E32: ZZY | F32: John Flaherty, c | H32: =IF(B32<10," ","")&B32&"."&IF(C32<10,"0","")&C32&" "&E32&" "&VLOOKUP(E32,Teams!$A$2:$C$21,2,0)&REPT(" ",Teams!C$1+1-VLOOKUP(E32,Teams!$A$2:$C$21,3,0))&"- "&F32&IF(ISBLANK(D32),""," (from "&D32&")") -> 2.10 ZZY Poole - John Flaherty, c
A33: 31 | B33: 2 | C33: 11 | D33: CIN | E33: BAR | F33: Rick Ankiel, lsp | H33: =IF(B33<10," ","")&B33&"."&IF(C33<10,"0","")&C33&" "&E33&" "&VLOOKUP(E33,Teams!$A$2:$C$21,2,0)&REPT(" ",Teams!C$1+1-VLOOKUP(E33,Teams!$A$2:$C$21,3,0))&"- "&F33&IF(ISBLANK(D33),""," (from "&D33&")") -> 2.11 BAR Marshall - Rick Ankiel, lsp (from CIN)
A34: 32 | B34: 2 | C34: 12 | E34: CTW | F34: Jason LaRue, c | H34: =IF(B34<10," ","")&B34&"."&IF(C34<10,"0","")&C34&" "&E34&" "&VLOOKUP(E34,Teams!$A$2:$C$21,2,0)&REPT(" ",Teams!C$1+1-VLOOKUP(E34,Teams!$A$2:$C$21,3,0))&"- "&F34&IF(ISBLANK(D34),""," (from "&D34&")") -> 2.12 CTW RMiller - Jason LaRue, c
A35: 33 | B35: 2 | C35: 13 | E35: FLL | F35: Ray King, lmr | H35: =IF(B35<10," ","")&B35&"."&IF(C35<10,"0","")&C35&" "&E35&" "&VLOOKUP(E35,Teams!$A$2:$C$21,2,0)&REPT(" ",Teams!C$1+1-VLOOKUP(E35,Teams!$A$2:$C$21,3,0))&"- "&F35&IF(ISBLANK(D35),""," (from "&D35&")") -> 2.13 FLL Carroll/Kleine - Ray King, lmr
A36: 34 | B36: 2 | C36: 14 | E36: BAR | F36: Jacque Jones, cf | H36: =IF(B36<10," ","")&B36&"."&IF(C36<10,"0","")&C36&" "&E36&" "&VLOOKUP(E36,Teams!$A$2:$C$21,2,0)&REPT(" ",Teams!C$1+1-VLOOKUP(E36,Teams!$A$2:$C$21,3,0))&"- "&F36&IF(ISBLANK(D36),""," (from "&D36&")") -> 2.14 BAR Marshall - Jacque Jones, cf
A37: 35 | B37: 2 | C37: 15 | E37: TAR | F37: Todd Zeile, 3b | H37: =IF(B37<10," ","")&B37&"."&IF(C37<10,"0","")&C37&" "&E37&" "&VLOOKUP(E37,Teams!$A$2:$C$21,2,0)&REPT(" ",Teams!C$1+1-VLOOKUP(E37,Teams!$A$2:$C$21,3,0))&"- "&F37&IF(ISBLANK(D37),""," (from "&D37&")") -> 2.15 TAR Lingo - Todd Zeile, 3b
A38: 36 | B38: 2 | C38: 16 | D38: CEN | E38: FLL | F38: Damaso Marte, lmr | H38: =IF(B38<10," ","")&B38&"."&IF(C38<10,"0","")&C38&" "&E38&" "&VLOOKUP(E38,Teams!$A$2:$C$21,2,0)&REPT(" ",Teams!C$1+1-VLOOKUP(E38,Teams!$A$2:$C$21,3,0))&"- "&F38&IF(ISBLANK(D38),""," (from "&D38&")") -> 2.16 FLL Carroll/Kleine - Damaso Marte, lmr (from CEN)
A39: 37 | B39: 2 | C39: 17 | E39: EVN | F39: Royce Clayton, ss | H39: =IF(B39<10," ","")&B39&"."&IF(C39<10,"0","")&C39&" "&E39&" "&VLOOKUP(E39,Teams!$A$2:$C$21,2,0)&REPT(" ",Teams!C$1+1-VLOOKUP(E39,Teams!$A$2:$C$21,3,0))&"- "&F39&IF(ISBLANK(D39),""," (from "&D39&")") -> 2.17 EVN Henninger - Royce Clayton, ss
A40: 38 | B40: 2 | C40: 18 | E40: TEW | F40: Joe Randa, 3b | H40: =IF(B40<10," ","")&B40&"."&IF(C40<10,"0","")&C40&" "&E40&" "&VLOOKUP(E40,Teams!$A$2:$C$21,2,0)&REPT(" ",Teams!C$1+1-VLOOKUP(E40,Teams!$A$2:$C$21,3,0))&"- "&F40&IF(ISBLANK(D40),""," (from "&D40&")") -> 2.18 TEW Bailey - Joe Randa, 3b
...

Sheet 1999 Trades
A1: Date | B1: Team1 | C1: Trades away | D1: Team2 | E1: Trades away | F1: 2000 Picks | G1: BBG | H1: Tm | I1: 2000 PICKS RECEIVED
A2: 40180 | B2: MCL | C2: MCL1.09, MCL9.08, Chris Carpenter, Aaron Sele, Mark Loretta | D2: RMO | E2: RMO11.08, Mike Mussina, Mike Redmond | F2: 0 | H2: BAR | K2: NNN-03
A3: 40182 | B3: FFR | C3: FFR1.04, FFR00-03 | D3: RMO | E3: MCL1.09, RMO00-02 | F3: 2 | H3: BBG | M3: FFR-05 | R3: FHK-15
A4: 40182 | B4: CIN | C4: CIN1.15 | D4: OKO | E4: Russ Ortiz | F4: 0 | H4: CEN | M4: CIN-05 | N4: NNN-06 | O4: DLM-06 | P4: DLM-07 | R4: DLM-12
A5: 40183 | B5: BAR | C5: Mike DeJean | D5: OKO | E5: Shawon Dunston | F5: 0 | H5: CIN | K5: TAR-03 | L5: BBG-05 | M5: DLM-05 | N5: TEW-05 | O5: CTW-06 | R5: TAR-12
A6: 40183 | B6: RMO | C6: RMO00-01 | D6: TEW | E6: TEW1.18 | F6: 1 | H6: CTW | Q6: FLL-08
A7: 40183 | B7: FFR | C7: 1.17, 4.01, FFR00-02 | D7: OKO | E7: FDH2.04, OKO2.05, OKO9.07 | F7: 1 | H7: DLM | M7: GAR-05 | Q7: CTW-09
A8: 40183 | B8: BBG | C8: BBG2.03, BBG00-05 | D8: CIN | E8: Ray Lankford | F8: 1 | H8: EVN | J8: CEN-02
A9: 40183 | B9: CTW | C9: FFR2.01, CTW00-04 | D9: FFR | E9: DLM1.19 | F9: 1 | H9: FDH
A10: 40183 | B10: NEP | C10: NEP1.20 | D10: RMO | E10: RMO 3.09, FFR 00-3, RMO 00-5 | F10: 1 | H10: FER
A11: 40184 | B11: OKO | C11: Kevin Young | D11: TAR | E11: TAR 3.16 | F11: 0 | H11: FFR | J11: RMO-02 | L11: CTW-04
A12: 40184 | B12: FLL | C12: Steve Parris | D12: GAR | E12: GAR 00-3 | F12: 1 | H12: FHK
A13: 40184 | B13: DLM | C13: Mike Williams, DLM00-08 | D13: FLL | E13: Rick Aguilera, FLL5.12 | F13: 1 | H13: FLL | I13: TEW-01 | J13: CIN-02 | K13: GAR-03 | O13: BAR-07 | P13: DLM-08 | Q13: OKO-08 | R13: TAR-11
A14: 40184 | B14: FFR | C14: Kyle Farnsworth | D14: FDH | E14: FDH 3.04, DLM 4.19, FDH 5.04 | F14: 0 | H14: GAR | J14: CTW-02 | L14: DLM-04 | Q14: DLM-10 | R14: DLM-14
A15: 40185 | B15: BAR | C15: BAR00-06 | D15: NEP | E15: Graeme Lloyd | F15: 1 | H15: MCL | P15: EVN-08 | R15: CIN-12
A16: 40185 | B16: CEN | C16: CEN 5.14 | D16: NEP | E16: Brian Moehler | F16: 0 | H16: NEP | K16: FFR-03 | M16: RMO-05 | N16: BAR-06 | P16: CIN-08
A17: 40186 | B17: CIN | C17: Scott Sullivan | D17: FHK | E17: Vicente Padilla | F17: 0 | H17: NNN | I17: BAR-01 | K17: CTW-03
A18: 40186 | B18: BAR | C18: 3.14, 14.09 | D18: FFR | E18: 5.01, 5.04, Bobby Ayala | F18: 0 | H18: OKO | J18: FFR-02 | R18: FLL-13
A19: 40186 | B19: CTW | C19: CTW00-03 | D19: GAR | E19: GAR4.02 | F19: 1 | H19: RMO | M19: BAR-05 | P19: BAR-08
A20: 40186 | B20: BBG | C20: BBG 4.03 | D20: FFR | E20: FFR00-05, Roger Cedeno | F20: 1 | H20: TAR | M20: MCL-05 | O20: CEN-07
A21: 40186 | B21: CEN | C21: CEN 4.16, Chad Kreuter | D21: FDH | E21: Tony Eusebio, Darren Oliver | F21: 0 | H21: TEW | I21: RMO-01 | O21: FLL-07
A22: 40187 | B22: BAR | C22: BAR00-07 | D22: FLL | E22: 15.06, 15.07, 16.05, 17.05, 18.05, 19.03 | F22: 1 | R22: =COUNTA(I2:R21) -> 47
A23: 40187 | B23: FLL | C23: Armando Reynoso | D23: NNN | E23: ZZY8.10 | F23: 0
A24: 40187 | B24: CEN | C24: Damian Jackson | D24: CIN | E24: CIN00-05 | F24: 1
A25: 40187 | B25: CEN | C25: 7.15, 8.15, 9.15, 10.15 | D25: DLM | E25: DLM00-06, DLM00-07, DLM00-12 | F25: 3 | H25: Tm | I25: 2000 PICKS TRADED
A26: 40188 | B26: BAR | C26: BAR00-01 | D26: NNN | E26: Tim Wakefield, ZZY00-03 | F26: 2 | H26: BAR | I26: BAR-01 | M26: BAR-05 | N26: BAR-06 | O26: BAR-07 | P26: BAR-08
A27: 40189 | B27: CIN | C27: CIN00-08 | D27: NEP | E27: NEP12.17, NEP13.15, NEP14.14 | F27: 1 | H27: BBG | M27: BBG-05
A28: 40189 | B28: CIN | C28: Ismael Valdes, CIN10.10 | D28: DLM | E28: DLM00-05 | F28: 1 | H28: CEN | J28: CEN-02 | O28: CEN-07 | P28: CEN-08
A29: 40189 | B29: DLM | C29: Tom Glavine | D29: FLL | E29: Larry Walker | F29: 0 | H29: CIN | J29: CIN-02 | M29: CIN-05 | P29: CIN-08 | R29: CIN-12
A30: 40189 | B30: CIN | C30: Ben Grieve, Damian Jackson | D30: TAR | E30: TAR9.16, TAR00-03, TAR00-12 | F30: 2 | H30: CTW | J30: CTW-02 | K30: CTW-03 | L30: CTW-04 | N30: CTW-06 | Q30: CTW-09
A31: 40190 | B31: BBG | C31: BBG8.03 | D31: FHK | E31: FHK8.07, FHK00-15 | F31: 1 | H31: DLM | K31: DLM-04 | L31: DLM-05 | M31: DLM-06 | N31: DLM-07 | O31: DLM-08 | P31: DLM-10 | Q31: DLM-12 | R31: DLM-14
A32: 40190 | B32: DLM | C32: DLM00-04, DLM00-05 | D32: GAR | E32: GAR00-05, Rey Ordonez | F32: 3 | H32: EVN | P32: EVN-08
A33: 40191 | B33: FFR | C33: Al Martin | D33: TAR | E33: TAR00-11 | F33: 1 | H33: FDH
A34: 40191 | B34: FFR | C34: TAR00-11, Donnels, Larkin, Ojala | D34: FLL | E34: FLL14.08 | F34: 0 | H34: FER
A35: 40192 | B35: CIN | C35: CIN00-12 | D35: MCL | E35: 15.03, 16.02, 17.02, 18.02 | F35: 1 | H35: FFR | J35: FFR-02 | K35: FFR-03 | M35: FFR-05
A36: 40211 | B36: CEN | C36: Chris Gomez | D36: NNN | E36: ZZY00-06 | F36: 1 | G36: =0.75*75 -> 56.25 | H36: FHK | R36: FHK-15
A37: 40222 | B37: EVN | C37: BJ Surhoff, EVN00-08 | D37: MCL | E37: Matt Lawton | F37: 1 | H37: FLL | O37: FLL-07 | P37: FLL-08 | R37: FLL-13
A38: 40231 | B38: CEN | C38: David Wells, CEN00-02 | D38: EVN | E38: Daal, Elarton, Hernandez, Mahomes | F38: 1 | H38: GAR | K38: GAR-03 | M38: GAR-05
A39: 40238 | B39: DLM | C39: Angel Pena, Pete Schourek, JD Smart | D39: EVN | E39: Robinson Cancel, Doug Glanville | F39: 0 | H39: MCL | M39: MCL-05
A40: 40239 | B40: BAR | C40: BAR00-05, BAR00-08, Scott Pose | D40: RMO | E40: Al Reyes, Dennys Reyes | F40: 2 | H40: NEP
...

Sheet 1999 PreDraft Trades
A1: Date | B1: Team1 | C1: Trades away | D1: Team2 | E1: Trades away | F1: 1999 Picks | G1: CTW | H1: Tm | I1: 1999 PICKS RECEIVED
A2: 39790 | B2: OKO | C2: Hampton, DeShields, Telemaco | D2: TAR | E2: Mike Sweeney | F2: 0 | H2: BAR | I2: CIN9902 | J2: CTW9903 | K2: ZZY9906 | L2: ZZY9907 | M2: CIN9912
A3: 39790 | B3: DLM | C3: 2.01 | D3: OKO | E3: Andy Ashby | F3: 0 | H3: BBG | I3: FFR9903 | J3: CIN9904 | K3: OKO9905 | L3: TAR9905 | M3: FFR9906 | N3: RMO9907 | O3: CIN9909
A4: 39792 | B4: DLM | C4: 1.04, 3.01, DLM9901, Vanderwal | D4: FFR | E4: Greg Maddux, FFR9903 | F4: 2 | H4: CEN
A5: 39793 | B5: DLM | C5: DLM9904 | D5: FDH | E5: Jeff Reed | F5: 1 | H5: CIN | I5: CEN9901 | J5: BAR9901 | K5: EVN9904 | L5: BAR9905 | M5: RMO9906
A6: 39794 | B6: DLM | C6: Kevin Millwood | D6: MCL | E6: Pete Harnisch, Eddie Perez | F6: 0 | H6: CTW | I6: FFR9902 | J6: DLM9902 | K6: TAR9906 | L6: DLM9906 | M6: BAR9908
A7: 39796 | B7: CTW | C7: Shigetoshi Hasegawa, Paul O'Neill | D7: DLM | E7: DLM9902, Paul Shuey | F7: 1 | H7: DLM | I7: GAR9906 | J7: CTW9918
A8: 39796 | B8: FFR | C8: Jose Panigua, John Vander Wal | D8: OKO | E8: Jose Hernandez | F8: 0 | H8: EVN | I8: RMO9902
A9: 39796 | B9: CTW | C9: Kevin Appier | D9: FDH | E9: Jose Lima, S Montgomery | F9: 0 | H9: FDH | I9: DLM9904
A10: 39797 | B10: FFR | C10: Roger Clemens | D10: RMO | E10: Torii Hunter, RMO9902, 2.03 | F10: 1 | H10: FER | I10: TEW9903 | J10: CEN9903
A11: 39798 | B11: CTW | C11: Mickey Morandini, Roberto Kelly | D11: TEW | E11: 11.17, Reggie Sanders | F11: 0 | H11: FFR | I11: CTW9901 | J11: DLM9901 | K11: EVN9901 | L11: TAR9904 | M11: CTW9908 | N11: BAR9916
A12: 39799 | B12: FDH | C12: Javier, Mike Maddux, Radinsky | D12: MCL | E12: Craig Counsell, Mark Kotsay | F12: 0 | H12: FHK
A13: 39799 | B13: CTW | C13: Bobby Estalella | D13: OKO | E13: 4.08 | F13: 0 | H13: GAR | I13: DLM9903 | J13: OKO9904 | K13: CTW9904 | L13: TEW9904 | M13: CTW9906 | N13: DLM9907 | O13: RMO9908
A14: 39799 | B14: BBG | C14: Shawn Estes | D14: OKO | E14: 2.08 | F14: 0 | H14: MCL | I14: ZZY9905 | J14: TEW9906
A15: 39799 | B15: CTW | C15: Andy Pettitte, CTW9901 | D15: FFR | E15: John Smoltz | F15: 1 | H15: NEP | I15: BBG9903 | J15: BBG9905 | K15: DLM9905 | L15: CTW9912
A16: 39800 | B16: FDH | C16: Chris Stynes, David Weathers | D16: OKO | E16: Danny Bautista, R Rincon | F16: 0 | H16: OKO | I16: FDH9902
A17: 39801 | B17: MCL | C17: Ricky Gutierrez, Tim Worrell | D17: OKO | E17: Tony Batista, 11.09 | F17: 0 | H17: RMO | I17: CTW9910 | J17: BAR9910 | K17: EVN9909 | L17: END99XX
A18: 39812 | B18: GAR | C18: Shannon Stewart | D18: RMO | E18: Jeff D'Amico, Sean Lowe | F18: 0 | H18: TAR | I18: END99XX
A19: 39814 | B19: CTW | C19: Chuck Knoblauch | D19: WIN | E19: Mike Bordick, Pokey Reese | F19: 0 | H19: TEW
A20: 39818 | B20: RMO | C20: RMO9901, RMO98-5.03 | D20: WIN | E20: 98-1.11 | F20: 1 | H20: WIN | I20: RMO9901 | J20: CEN9902 | K20: CIN9908 | L20: BAR9915
A21: 39818 | B21: CTW | C21: Jason Giambi, Will Clark | D21: FFR | E21: Mark McGwire, 1.12, 3.01 | F21: 0 | H21: ZZY | I21: BAR9904 | J21: BAR9906 | K21: CEN9906 | L21: BAR9907
A22: 39819 | B22: FDH | C22: FDH9902, Mark Kotsay, DLM9904 | D22: OKO | E22: 1.15 | F22: 1 | Q22: =COUNTA(I2:Q21) -> 61
A23: 39819 | B23: FFR | C23: Juan Gonzalez, Steinbach, 98-2.11 | D23: TAR | E23: 98-1.14, TAR9904, G Anderson | F23: 1
A24: 39819 | B24: DLM | C24: Chris Hammond | D24: FFR | E24: Chuck McElroy | F24: 0 | H24: Tm | I24: 1999 PICKS TRADED
A25: 39820 | B25: FDH | C25: 4.12 | D25: OKO | E25: DLM9904 | F25: 0 | H25: BAR | I25: BAR9901 | J25: BAR9904 | K25: BAR9905 | L25: BAR9906 | M25: BAR9907 | N25: BAR9908 | O25: BAR9910 | P25: BAR9915 | Q25: BAR9916
A26: 39820 | B26: EVN | C26: EVN9901, Tyler Green | D26: FFR | E26: Omar Daal, RMO9902 | F26: 1 | H26: BBG | I26: BBG9903 | J26: BBG9905
A27: 39820 | B27: FFR | C27: 6.11 | D27: WIN | E27: Eli Marrero | F27: 0 | H27: CEN | I27: CEN9901 | J27: CEN9902 | K27: CEN9903 | L27: CEN9906
A28: 39821 | B28: FDH | C28: Brian Bohanon | D28: TAR | E28: 2.11 | F28: 0 | H28: CIN | I28: CIN9902 | J28: CIN9904 | K28: CIN9908 | L28: CIN9909 | M28: CIN9912
A29: 39821 | B29: CIN | C29: Brett Tomko | D29: TAR | E29: 2.13 | F29: 0 | H29: CTW | I29: CTW9901 | J29: CTW9903 | K29: CTW9904 | L29: CTW9906 | M29: CTW9908 | N29: CTW9910 | O29: CTW9912 | P29: CTW9918
A30: 39821 | B30: DLM | C30: 3.15, 8.17 | D30: FDH | E30: Willie Greene | F30: 0 | H30: DLM | I30: DLM9901 | J30: DLM9902 | K30: DLM9903 | L30: DLM9904 | M30: DLM9905 | N30: DLM9906 | O30: DLM9907
A31: 39822 | B31: NEP | C31: Woody Williams | D31: RMO | E31: 2.14 | F31: 0 | H31: EVN | I31: EVN9901 | J31: EVN9904 | K31: EVN9909
A32: 39822 | B32: BBG | C32: 3.20 | D32: RMO | E32: Ron Villone | F32: 0 | H32: FDH | I32: FDH9902
A33: 39822 | B33: CEN | C33: 2.18, 5.18 | D33: FFR | E33: Matt Williams, 4.11, 7.10 | F33: 0 | H33: FER
A34: 39822 | B34: OKO | C34: 3.08, Devon White | D34: ZZY | E34: 2.19 | F34: 0 | H34: FFR | I34: FFR9902 | J34: FFR9903 | K34: FFR9906
A35: 39823 | B35: BAR | C35: Russ Davis, Orlando Merced | D35: FDH | E35: David Segui | F35: 0 | H35: FHK
A36: 39824 | B36: RMO | C36: 3.16, 4.03 | D36: WIN | E36: 3.10, 7.09 | F36: 0 | H36: GAR | I36: GAR9906
A37: 39824 | B37: FFR | C37: 3.11 | D37: RMO | E37: Jason Johnson, 7.03, 8.14 | F37: 0 | H37: MCL
A38: 39824 | B38: BBG | C38: Justin Thompson, BBG9903, BBG9905 | D38: NEP | E38: Jose Rosado | F38: 2 | H38: NEP
A39: 39825 | B39: RMO | C39: Alan Levine, Armando Reynoso | D39: WIN | E39: 7.16, 10.08 | F39: 0 | H39: OKO | I39: OKO9904 | J39: OKO9905
A40: 39825 | B40: TEW | C40: John Wetteland | D40: WIN | E40: 4.03, Dante Bichette | F40: 0 | H40: RMO | I40: RMO9901 | J40: RMO9902 | K40: RMO9905 | L40: RMO9906 | M40: RMO9907 | N40: RMO9908
...

Sheet Teams
A1: Code | B1: 1 | C1: =MAX(C2:C21) -> 14 | D1: 14 | E1: 22 | F1: 17 | G1: 14 | H1: # of Picks
A2: BBG | B2: =VLOOKUP(A2,A$2:G$21,3+B$1,0) -> Canter | C2: =LEN(B2) -> 6 | D2: Canter | E2: Baraboo | F2: Goitermen | G2: Yard | H2: =COUNTIF('1999 Draft'!$E$3:$E$324,Teams!A2) -> 21
A3: BAR | B3: =VLOOKUP(A3,A$2:G$21,3+B$1,0) -> Marshall | C3: =LEN(B3) -> 8 | D3: Marshall | E3: Barcelona | F3: Brewers | G3: Marcia ^3 | H3: =COUNTIF('1999 Draft'!$E$3:$E$324,Teams!A3) -> 18
A4: CEN | B4: =VLOOKUP(A4,A$2:G$21,3+B$1,0) -> Stearns | C4: =LEN(B4) -> 7 | D4: Stearns | E4: Century | F4: Atoms | G4: Stearns | H4: =COUNTIF('1999 Draft'!$E$3:$E$324,Teams!A4) -> 0
A5: CTW | B5: =VLOOKUP(A5,A$2:G$21,3+B$1,0) -> RMiller | C5: =LEN(B5) -> 7 | D5: RMiller | E5: Chinatrust | F5: Whales | G5: West Coast | H5: =COUNTIF('1999 Draft'!$E$3:$E$324,Teams!A5) -> 20
A6: CIN | B6: =VLOOKUP(A6,A$2:G$21,3+B$1,0) -> CMiller | C6: =LEN(B6) -> 7 | D6: CMiller | E6: Cincinnati | F6: Reds | G6: Midwest | H6: =COUNTIF('1999 Draft'!$E$3:$E$324,Teams!A6) -> 21
A7: DLM | B7: =VLOOKUP(A7,A$2:G$21,3+B$1,0) -> Potter | C7: =LEN(B7) -> 6 | D7: Potter | E7: Dún Laoghaire | F7: Messiahs | G7: Potsy | H7: =COUNTIF('1999 Draft'!$E$3:$E$324,Teams!A7) -> 25
A8: EVN | B8: =VLOOKUP(A8,A$2:G$21,3+B$1,0) -> Henninger | C8: =LEN(B8) -> 9 | D8: Henninger | E8: Evanston | F8: Endorphins | G8: Henninger | H8: =COUNTIF('1999 Draft'!$E$3:$E$324,Teams!A8) -> 21
A9: FFR | B9: =VLOOKUP(A9,A$2:G$21,3+B$1,0) -> Scott | C9: =LEN(B9) -> 5 | D9: Scott | E9: Fallkirk | F9: Frightened Rabbit | G9: Snorkles | H9: =COUNTIF('1999 Draft'!$E$3:$E$324,Teams!A9) -> 21
A10: FDH | B10: =VLOOKUP(A10,A$2:G$21,3+B$1,0) -> English | C10: =LEN(B10) -> 7 | D10: English | E10: Felldownhead | F10: Firsts | G10: Engrish | H10: =COUNTIF('1999 Draft'!$E$3:$E$324,Teams!A10) -> 7
A11: FER | B11: =VLOOKUP(A11,A$2:G$21,3+B$1,0) -> Olkin | C11: =LEN(B11) -> 5 | D11: Olkin | E11: Ferdinand | F11: Magellans | G11: Olkin | H11: =COUNTIF('1999 Draft'!$E$3:$E$324,Teams!A11) -> 16
A12: FHK | B12: =VLOOKUP(A12,A$2:G$21,3+B$1,0) -> Chernow | C12: =LEN(B12) -> 7 | D12: Chernow | E12: Ferlin | F12: Huskies | G12: Trogdor | H12: =COUNTIF('1999 Draft'!$E$3:$E$324,Teams!A12) -> 15
A13: FLL | B13: =VLOOKUP(A13,A$2:G$21,3+B$1,0) -> Carroll/Kleine | C13: =LEN(B13) -> 14 | D13: Carroll/Kleine | E13: French Lick | F13: Linguists | G13: die kleinen Carroll | H13: =COUNTIF('1999 Draft'!$E$3:$E$324,Teams!A20) -> 10
A14: GAR | B14: =VLOOKUP(A14,A$2:G$21,3+B$1,0) -> Bernstein | C14: =LEN(B14) -> 9 | D14: Bernstein | E14: Garmisch-Partenkirchen | F14: Shebazzle! | G14: DrewBFrog | H14: =COUNTIF('1999 Draft'!$E$3:$E$324,Teams!A13) -> 16
A15: MCL | B15: =VLOOKUP(A15,A$2:G$21,3+B$1,0) -> Manuel | C15: =LEN(B15) -> 6 | D15: Manuel | E15: McCullers | F15: Lancers | G15: Manny | H15: =COUNTIF('1999 Draft'!$E$3:$E$324,Teams!A14) -> 17
A16: NEP | B16: =VLOOKUP(A16,A$2:G$21,3+B$1,0) -> Sasman | C16: =LEN(B16) -> 6 | D16: Sasman | E16: Newfoundland | F16: Perfectos | G16: Foxy | H16: =COUNTIF('1999 Draft'!$E$3:$E$324,Teams!A15) -> 15
A17: OKO | B17: =VLOOKUP(A17,A$2:G$21,3+B$1,0) -> Smith | C17: =LEN(B17) -> 5 | D17: Smith | E17: Okoboji | F17: Farmers | G17: Smith | H17: =COUNTIF('1999 Draft'!$E$3:$E$324,Teams!A16) -> 16
A18: RMO | B18: =VLOOKUP(A18,A$2:G$21,3+B$1,0) -> Haverty/Mojo | C18: =LEN(B18) -> 12 | D18: Haverty/Mojo | E18: Rocky Mountain | F18: Oysters | G18: Haverty/Mojo | H18: =COUNTIF('1999 Draft'!$E$3:$E$324,Teams!A17) -> 13
A19: TAR | B19: =VLOOKUP(A19,A$2:G$21,3+B$1,0) -> Lingo | C19: =LEN(B19) -> 5 | D19: Lingo | E19: Tarboro | F19: Goobers | G19: Lingoba | H19: =COUNTIF('1999 Draft'!$E$3:$E$324,Teams!A18) -> 11
A20: TEW | B20: =VLOOKUP(A20,A$2:G$21,3+B$1,0) -> Bailey | C20: =LEN(B20) -> 6 | D20: Bailey | E20: Tewksbury | F20: Bobs | G20: Shecky | H20: =COUNTIF('1999 Draft'!$E$3:$E$324,Teams!A19) -> 19
A21: ZZY | B21: =VLOOKUP(A21,A$2:G$21,3+B$1,0) -> Poole | C21: =LEN(B21) -> 5 | D21: Poole | E21: Zzyzx | F21: Loadies | G21: Poole | H21: =COUNTIF('1999 Draft'!$E$3:$E$324,Teams!A21) -> 20
