Workbook

Sheet dump
A1: Manager Profile for 1999 Chinatrust Whales | B1: =TRIM(A1) -> Manager Profile for 1999 Chinatrust Whales
A2: 12345678901234567890123456789012345678901234567890123456789012345678901234567890123456789012345678901234567890
A3: Pitching Chart | B3: =TRIM(A3) -> Pitching Chart
A5: Usage mode: Strict | B5: Usage Mode: | C5: =TRIM(MID(A5,16,6)) -> Strict
A6: Rotation size: 4 | B6: Rotation Size: | C6: =1*MID(A6,16,1) -> 4
A7: Next starter: 1 | B7: Next Starter: | C7: =1*MID(A7,16,1) -> 1 | D7: =VLOOKUP(C7,$B$10:$C$14,2,0) -> Johnson,Ra
A9: Starting Rotation Johnson,Ra Boehringer Lima Burba | C9: Rotation | D9: Spot Starters | E9: % | F9: Mopup | G9: Long | H9: Setup Vs LHB | I9: Setup vs RHB | J9: Closers vs LHB | K9: Closers vs RHB
A10: Spot Starters | B10: 1 | C10: =TRIM(MID(A$9,21,18)) -> Johnson,Ra | D10: =TRIM(MID(A$10,21,18)) | E10: =IF(D10="","",1*TRIM(MID(A$11,21,18))) | F10: =TRIM(MID(A$13,21,18)) -> Loaiza | G10: =TRIM(MID(A$14,21,18)) -> Trombley | H10: =TRIM(MID(A$15,21,18)) -> Quantrill | I10: =TRIM(MID(A$16,21,18)) -> Perisho | J10: =TRIM(MID(A$17,21,18)) -> Rivera,M | K10: =TRIM(MID(A$18,21,18)) -> Rivera,M
A11: Spot Pct | B11: 2 | C11: =TRIM(MID(A$9,39,18)) -> Boehringer | D11: =TRIM(MID(A$10,39,18)) | E11: =IF(D11="","",1*TRIM(MID(A$11,39,18))) | F11: =TRIM(MID(A$13,39,18)) -> Boehringer | G11: =TRIM(MID(A$14,39,18)) -> Shuey | H11: =TRIM(MID(A$15,39,18)) -> Montgomery,S | I11: =TRIM(MID(A$16,39,18)) -> Quantrill | J11: =TRIM(MID(A$17,39,18)) -> Montgomery,S | K11: =TRIM(MID(A$18,39,18)) -> Quantrill
B12: 3 | C12: =TRIM(MID(A$9,57,18)) -> Lima | D12: =TRIM(MID(A$10,57,18)) | E12: =IF(D12="","",1*TRIM(MID(A$11,57,18))) | F12: =TRIM(MID(A$13,57,18)) | G12: =TRIM(MID(A$14,57,18)) -> Montgomery,S | H12: =TRIM(MID(A$15,57,18)) -> Trombley | I12: =TRIM(MID(A$16,57,18)) -> Shuey | J12: =TRIM(MID(A$17,57,18)) | K12: =TRIM(MID(A$18,57,18))
A13: Mopup situations Loaiza Boehringer | B13: 4 | C13: =TRIM(MID(A$9,75,18)) -> Burba | D13: =TRIM(MID(A$10,75,18)) | E13: =IF(D13="","",1*TRIM(MID(A$11,75,18))) | F13: =TRIM(MID(A$13,75,18)) | G13: =TRIM(MID(A$14,75,18)) -> Quantrill | H13: =TRIM(MID(A$15,75,18)) -> Perisho | I13: =TRIM(MID(A$16,75,18)) -> Montgomery,S | J13: =TRIM(MID(A$17,75,18)) | K13: =TRIM(MID(A$18,75,18))
A14: Long relievers Trombley Shuey Montgomery,S Quantrill Perisho | B14: 5 | C14: =TRIM(MID(A$9,93,18)) | D14: =TRIM(MID(A$10,93,18)) | E14: =IF(D14="","",1*TRIM(MID(A$11,93,18))) | F14: =TRIM(MID(A$13,93,18)) | G14: =TRIM(MID(A$14,93,18)) -> Perisho | H14: =TRIM(MID(A$15,93,18)) -> Shuey | I14: =TRIM(MID(A$16,93,18)) -> Trombley | J14: =TRIM(MID(A$17,93,18)) | K14: =TRIM(MID(A$18,93,18))
A15: Setup vs LHB Quantrill Montgomery,S Trombley Perisho Shuey
A16: Setup vs RHB Perisho Quantrill Shuey Montgomery,S Trombley
A17: Closers vs LHB Rivera,M Montgomery,S | B17: =TRIM(A23) -> Depth Chart for 1999 Chinatrust Whales -- vs LHP
A18: Closers vs RHB Rivera,M Quantrill
B19: Usage: | C19: =TRIM(MID(A26,8,18)) -> Game by game
A20: .................................................................................................... | B20: Versus: | C20: =TRIM(MID(A26,36,5)) -> Left
A21: Manager Profile for 1999 Chinatrust Whales | B21: DH: | C21: =TRIM(MID(A26,52,3)) -> No
A23: Depth Chart for 1999 Chinatrust Whales -- vs LHP | B23: Starting Lineup
B25: 1 | C25: =TRIM(MID(A30,4,16)) -> Henderson | D25: =TRIM(MID(A30,21,2)) -> lf
A26: Usage: Game by game Versus: Left DH: No | B26: 2 | C26: =TRIM(MID(A31,4,16)) -> Bordick | D26: =TRIM(MID(A31,21,2)) -> ss
B27: 3 | C27: =TRIM(MID(A32,4,16)) -> Sanders,R | D27: =TRIM(MID(A32,21,2)) -> cf
A28: Starting Lineup | B28: 4 | C28: =TRIM(MID(A33,4,16)) -> Jones,C | D28: =TRIM(MID(A33,21,2)) -> 3b
B29: 5 | C29: =TRIM(MID(A34,4,16)) -> McGwire | D29: =TRIM(MID(A34,21,2)) -> 1b
A30: 1: Henderson lf | B30: 6 | C30: =TRIM(MID(A35,4,16)) -> Howard,T | D30: =TRIM(MID(A35,21,2)) -> rf
A31: 2: Bordick ss | B31: 7 | C31: =TRIM(MID(A36,4,16)) -> Reese | D31: =TRIM(MID(A36,21,2)) -> 2b
A32: 3: Sanders,R cf | B32: 8 | C32: =TRIM(MID(A37,4,16)) -> Pratt | D32: =TRIM(MID(A37,21,2)) -> c
A33: 4: Jones,C 3b
A34: 5: McGwire 1b | C34: Catcher | E34: First Base | G34: Second Base | I34: Third Base | K34: Shortstop
A35: 6: Howard,T rf | B35: Start | C35: =TRIM(MID($A44,7,16)) -> Pratt | E35: =TRIM(MID($A44,28,16)) -> McGwire | G35: =TRIM(MID($A44,49,16)) -> Reese | I35: =TRIM(MID($A44,70,16)) -> Jones,C | K35: =TRIM(MID($A56,7,16)) -> Bordick
A36: 7: Reese 2b | B36: Plat | C36: =TRIM(MID($A45,7,16)) | E36: =TRIM(MID($A45,28,16)) | G36: =TRIM(MID($A45,49,16)) | I36: =TRIM(MID($A45,70,16)) | K36: =TRIM(MID($A57,7,16))
A37: 8: Pratt c | B37: Def | C37: =TRIM(MID($A46,7,16)) | E37: =TRIM(MID($A46,28,16)) -> Durazo | G37: =TRIM(MID($A46,49,16)) -> Reese | I37: =TRIM(MID($A46,70,16)) | K37: =TRIM(MID($A58,7,16))
A38: 0.375 | B38: Util1 | C38: =TRIM(MID($A47,7,16)) -> Kinkade | D38: =IF(C38="","",1*MID($A47,24,2)) -> 0 | E38: =TRIM(MID($A47,28,16)) -> Buhner | F38: =IF(E38="","",1*MID($A47,45,2)) -> 0 | G38: =TRIM(MID($A47,49,16)) | H38: =IF(G38="","",1*MID($A47,66,2)) | I38: =TRIM(MID($A47,70,16)) -> Battle | J38: =IF(I38="","",1*MID($A47,87,2)) -> 0 | K38: =TRIM(MID($A59,7,16)) | L38: =IF(K38="","",1*MID($A59,24,2))
B39: Util2 | C39: =TRIM(MID($A48,7,16)) -> Pratt | D39: =IF(C39="","",1*MID($A48,24,2)) -> 0 | E39: =TRIM(MID($A48,28,16)) | F39: =IF(E39="","",1*MID($A48,45,2)) | G39: =TRIM(MID($A48,49,16)) | H39: =IF(G39="","",1*MID($A48,66,2)) | I39: =TRIM(MID($A48,70,16)) | J39: =IF(I39="","",1*MID($A48,87,2)) | K39: =TRIM(MID($A60,7,16)) | L39: =IF(K39="","",1*MID($A60,24,2))
B40: Util3 | C40: =TRIM(MID($A49,7,16)) -> Johnson,B | D40: =IF(C40="","",1*MID($A49,24,2)) -> 0 | E40: =TRIM(MID($A49,28,16)) | F40: =IF(E40="","",1*MID($A49,45,2)) | G40: =TRIM(MID($A49,49,16)) | H40: =IF(G40="","",1*MID($A49,66,2)) | I40: =TRIM(MID($A49,70,16)) | J40: =IF(I40="","",1*MID($A49,87,2)) | K40: =TRIM(MID($A61,7,16)) | L40: =IF(K40="","",1*MID($A61,24,2))
B41: Util4 | C41: =TRIM(MID($A50,7,16)) | D41: =IF(C41="","",1*MID($A50,24,2)) | E41: =TRIM(MID($A50,28,16)) | F41: =IF(E41="","",1*MID($A50,45,2)) | G41: =TRIM(MID($A50,49,16)) | H41: =IF(G41="","",1*MID($A50,66,2)) | I41: =TRIM(MID($A50,70,16)) | J41: =IF(I41="","",1*MID($A50,87,2)) | K41: =TRIM(MID($A62,7,16)) | L41: =IF(K41="","",1*MID($A62,24,2))
A42: ----- Catcher ----- --- First Base ---- --- Second Base --- --- Third Base ---- | B42: Util5 | C42: =TRIM(MID($A51,7,16)) | D42: =IF(C42="","",1*MID($A51,24,2)) | E42: =TRIM(MID($A51,28,16)) | F42: =IF(E42="","",1*MID($A51,45,2)) | G42: =TRIM(MID($A51,49,16)) | H42: =IF(G42="","",1*MID($A51,66,2)) | I42: =TRIM(MID($A51,70,16)) | J42: =IF(I42="","",1*MID($A51,87,2)) | K42: =TRIM(MID($A63,7,16)) | L42: =IF(K42="","",1*MID($A63,24,2))
A44: Start Pratt McGwire Reese Jones,C | C44: Left Field | E44: Center Field | G44: Right Field | I44: Designated Hitter
A45: Plat | B45: Start | C45: =TRIM(MID($A56,28,16)) -> Henderson | E45: =TRIM(MID($A56,49,16)) -> Sanders,R | G45: =TRIM(MID($A56,70,16)) -> Howard,T | I45: =TRIM(MID($A68,7,16))
...

Sheet profile
A1: PITCHING CHART
B2: Usage Mode: | C2: =dump!$C$5 -> Strict | E2: Rotation Size: | F2: =dump!$C$6 -> 4 | H2: Next Starter: | I2: =dump!$C$7 -> 1
A3: Slot | B3: Starters | C3: Spot Starter | D3: Spot% | E3: Mopup | F3: Long | G3: Setup vs L | H3: Setup vs R | I3: Closer vs L | J3: Closer vs R
A4: 1 | B4: =dump!C10 -> Johnson,Ra | C4: =dump!D10 | D4: =dump!E10 | E4: =dump!F10 -> Loaiza | F4: =dump!G10 -> Trombley | G4: =dump!H10 -> Quantrill | H4: =dump!I10 -> Perisho | I4: =dump!J10 -> Rivera,M | J4: =dump!K10 -> Rivera,M
A5: 2 | B5: =dump!C11 -> Boehringer | C5: =dump!D11 | D5: =dump!E11 | E5: =dump!F11 -> Boehringer | F5: =dump!G11 -> Shuey | G5: =dump!H11 -> Montgomery,S | H5: =dump!I11 -> Quantrill | I5: =dump!J11 -> Montgomery,S | J5: =dump!K11 -> Quantrill
A6: 3 | B6: =dump!C12 -> Lima | C6: =dump!D12 | D6: =dump!E12 | E6: =dump!F12 | F6: =dump!G12 -> Montgomery,S | G6: =dump!H12 -> Trombley | H6: =dump!I12 -> Shuey | I6: =dump!J12 | J6: =dump!K12
A7: 4 | B7: =dump!C13 -> Burba | C7: =dump!D13 | D7: =dump!E13 | E7: =dump!F13 | F7: =dump!G13 -> Quantrill | G7: =dump!H13 -> Perisho | H7: =dump!I13 -> Montgomery,S | I7: =dump!J13 | J7: =dump!K13
A8: 5 | B8: =dump!C14 | C8: =dump!D14 | D8: =dump!E14 | E8: =dump!F14 | F8: =dump!G14 -> Perisho | G8: =dump!H14 -> Shuey | H8: =dump!I14 -> Trombley | I8: =dump!J14 | J8: =dump!K14
A9: DEPTH CHART VS LHP
B10: Usage: | C10: =dump!$C$19 -> Game by game | E10: Versus: | F10: =dump!$C$20 -> Left | G10: DH: | H10: =dump!$C$21 -> No
B11: Player | C11: Pos
A12: 1 | B12: =dump!C25 -> Henderson | C12: =dump!D25 -> lf
A13: 2 | B13: =dump!C26 -> Bordick | C13: =dump!D26 -> ss
A14: 3 | B14: =dump!C27 -> Sanders,R | C14: =dump!D27 -> cf
A15: 4 | B15: =dump!C28 -> Jones,C | C15: =dump!D28 -> 3b
A16: 5 | B16: =dump!C29 -> McGwire | C16: =dump!D29 -> 1b
A17: 6 | B17: =dump!C30 -> Howard,T | C17: =dump!D30 -> rf
A18: 7 | B18: =dump!C31 -> Reese | C18: =dump!D31 -> 2b
A19: 8 | B19: =dump!C32 -> Pratt | C19: =dump!D32 -> c
A20: 9 | B20: Pitcher | C20: p
E182: =INDEX($B$125:$B$179,MATCH(ROW()-181+10,$E$125:$E$179,0)) -> #N/A | F182: =INDEX($B$125:$B$179,MATCH(ROW()-181+20,$E$125:$E$179,0)) -> #N/A | G182: =INDEX($B$125:$B$179,MATCH(ROW()-181,$F$125:$F$179,0)) -> #N/A | H182: =INDEX($B$125:$B$179,MATCH(ROW()-181+10,$F$125:$F$179,0)) -> #N/A | J182: =INDEX($B$125:$B$179,MATCH(ROW()-181+10,$G$125:$G$179,0)) -> #N/A | K182: =INDEX($B$125:$B$179,MATCH(ROW()-181+20,$G$125:$G$179,0)) -> #N/A
E183: =INDEX($B$125:$B$179,MATCH(ROW()-181+10,$E$125:$E$179,0)) -> #N/A | F183: =INDEX($B$125:$B$179,MATCH(ROW()-181+20,$E$125:$E$179,0)) -> #N/A | G183: =INDEX($B$125:$B$179,MATCH(ROW()-181,$F$125:$F$179,0)) -> #N/A | H183: =INDEX($B$125:$B$179,MATCH(ROW()-181+10,$F$125:$F$179,0)) -> #N/A
E184: =INDEX($B$125:$B$179,MATCH(ROW()-181+10,$E$125:$E$179,0)) -> #N/A | F184: =INDEX($B$125:$B$179,MATCH(ROW()-181+20,$E$125:$E$179,0)) -> #N/A | G184: =INDEX($B$125:$B$179,MATCH(ROW()-181,$F$125:$F$179,0)) -> #N/A | H184: =INDEX($B$125:$B$179,MATCH(ROW()-181+10,$F$125:$F$179,0)) -> #N/A
E185: =INDEX($B$125:$B$179,MATCH(ROW()-181+10,$E$125:$E$179,0)) -> #N/A | F185: =INDEX($B$125:$B$179,MATCH(ROW()-181+20,$E$125:$E$179,0)) -> #N/A | G185: =INDEX($B$125:$B$179,MATCH(ROW()-181,$F$125:$F$179,0)) -> #N/A | H185: =INDEX($B$125:$B$179,MATCH(ROW()-181+10,$F$125:$F$179,0)) -> #N/A
E186: =INDEX($B$125:$B$179,MATCH(ROW()-181+10,$E$125:$E$179,0)) -> #N/A | F186: =INDEX($B$125:$B$179,MATCH(ROW()-181+20,$E$125:$E$179,0)) -> #N/A | G186: =INDEX($B$125:$B$179,MATCH(ROW()-181,$F$125:$F$179,0)) -> #N/A | H186: =INDEX($B$125:$B$179,MATCH(ROW()-181+10,$F$125:$F$179,0)) -> #N/A
E187: =INDEX($B$125:$B$179,MATCH(ROW()-181+10,$E$125:$E$179,0)) -> #N/A | F187: =INDEX($B$125:$B$179,MATCH(ROW()-181+20,$E$125:$E$179,0)) -> #N/A | G187: =INDEX($B$125:$B$179,MATCH(ROW()-181,$F$125:$F$179,0)) -> #N/A | H187: =INDEX($B$125:$B$179,MATCH(ROW()-181+10,$F$125:$F$179,0)) -> #N/A
E188: =INDEX($B$125:$B$179,MATCH(ROW()-181+10,$E$125:$E$179,0)) -> #N/A | F188: =INDEX($B$125:$B$179,MATCH(ROW()-181+20,$E$125:$E$179,0)) -> #N/A | G188: =INDEX($B$125:$B$179,MATCH(ROW()-181,$F$125:$F$179,0)) -> #N/A | H188: =INDEX($B$125:$B$179,MATCH(ROW()-181+10,$F$125:$F$179,0)) -> #N/A
E189: =INDEX($B$125:$B$179,MATCH(ROW()-181+10,$E$125:$E$179,0)) -> #N/A | F189: =INDEX($B$125:$B$179,MATCH(ROW()-181+20,$E$125:$E$179,0)) -> #N/A | G189: =INDEX($B$125:$B$179,MATCH(ROW()-181,$F$125:$F$179,0)) -> #N/A | H189: =INDEX($B$125:$B$179,MATCH(ROW()-181+10,$F$125:$F$179,0)) -> #N/A
E190: =INDEX($B$125:$B$179,MATCH(ROW()-181+10,$E$125:$E$179,0)) -> #N/A | F190: =INDEX($B$125:$B$179,MATCH(ROW()-181+20,$E$125:$E$179,0)) -> #N/A | G190: =INDEX($B$125:$B$179,MATCH(ROW()-181,$F$125:$F$179,0)) -> #N/A | H190: =INDEX($B$125:$B$179,MATCH(ROW()-181+10,$F$125:$F$179,0)) -> #N/A
E191: =INDEX($B$125:$B$179,MATCH(ROW()-181+10,$E$125:$E$179,0)) -> #N/A | F191: =INDEX($B$125:$B$179,MATCH(ROW()-181+20,$E$125:$E$179,0)) -> #N/A | G191: =INDEX($B$125:$B$179,MATCH(ROW()-181,$F$125:$F$179,0)) -> #N/A | H191: =INDEX($B$125:$B$179,MATCH(ROW()-181+10,$F$125:$F$179,0)) -> #N/A

Sheet Sheet3
